Workbook

Sheet Инструкция
D1: PVZ.FLOW — рабочий файл расчетов
D2: Источник фактов движения — только лист «Движение». Остальные листы расчетные.
A5: Шаг | B5: Раздел | C5: Что делать
A6: 1 | B6: Настройки периода | C6: На листе «Настройки» укажи дату начала недели. Дата окончания считается автоматически.
A7: 2 | B7: Ввод движения | C7: На листе «Движение» выбери оператора в строке дня и внеси по товарам только «Приход» и «Убытие». Остатки считаются автоматически.
A8: 3 | B8: Проверка | C8: Перед счетом открой лист «Контроль». Если критические проверки OK — можно выставлять счет и платить сотрудникам.
A9: 4 | B9: Счет селлеру | C9: Лист «Свод_селлер» содержит фулфилмент, хранение и общий итог к начислению.
A10: 5 | B10: Сотрудники | C10: Лист «Мотивация» — общая ведомость. Листы «Расчетный_Пузанов» и «Расчетный_Завалишин» — расчетные листки.
A11: 6 | B11: Важно | C11: Не сортируй строки листа «Движение». Можно фильтровать/искать по датам, но порядок дат должен оставаться хронологическим.

Sheet Настройки
D1: Настройки
D2: Тарифы, период расчета и справочники. Желтые поля можно менять.
A5: Дата начала недели | B5: 46279 | E5: Цвета бренда
A6: Дата окончания недели | B6: =B5+6 | E6: Винный | F6: #5A081E
A7: Бесплатных дней хранения | B7: 5 | E7: Золотой | F7: #BD995A
A10: Товар | B10: Категория | C10: Весовая группа | D10: Приемка селлеру | E10: Брендирование | F10: Упаковка | G10: Сборка | H10: Отправка селлеру | I10: Хранение / шт-день | J10: Приемка персоналу | K10: Отправка персоналу | L10: Начальный остаток | O10: Сотрудники
A11: АК-10 | B11: АК | C11: до 1 кг | D11: 10 | E11: 10 | F11: 20 | G11: 10 | H11: =E11+F11+G11 | I11: 0.35714286 | J11: 1 | K11: 12 | L11: 0 | O11: Пузанов Д.В.
A12: АК-15 | B12: АК | C12: до 1 кг | D12: 10 | E12: 10 | F12: 20 | G12: 10 | H12: =E12+F12+G12 | I12: 0.35714286 | J12: 1 | K12: 12 | L12: 0 | O12: Завалишин Д.Л.
A13: Г 1800 | B13: Г | C13: 1–5 кг | D13: 10 | E13: 10 | F13: 30 | G13: 15 | H13: =E13+F13+G13 | I13: 5 | J13: 2 | K13: 23 | L13: 0
A14: Г 3500 | B14: Г | C14: >5 кг | D14: 10 | E14: 15 | F14: 35 | G14: 25 | H14: =E14+F14+G14 | I14: 5 | J14: 3 | K14: 34 | L14: 0
A15: Г 800 | B15: Г | C15: 1–5 кг | D15: 10 | E15: 10 | F15: 30 | G15: 15 | H15: =E15+F15+G15 | I15: 5 | J15: 2 | K15: 23 | L15: 0
A16: Ми-К | B16: Ми | C16: до 1 кг | D16: 10 | E16: 0 | F16: 20 | G16: 10 | H16: =E16+F16+G16 | I16: 1.3636364 | J16: 1 | K16: 9 | L16: 0
A17: Ми-П | B17: Ми | C17: до 1 кг | D17: 10 | E17: 0 | F17: 20 | G17: 10 | H17: =E17+F17+G17 | I17: 0.16304348 | J17: 1 | K17: 9 | L17: 0

Sheet Движение
D1: Движение товара — источник данных
A5: Период расчета | B5: =Настройки!$B$5 | C5: =Настройки!$B$6
A6: Итоговая таблица недели
A7: Товар | B7: Остаток начало | C7: Приход | D7: Убытие | E7: Остаток конец | F7: Контроль | G7: Фулфилмент | H7: Хранение | I7: Мотивация
A8: АК-10 | B8: =SUMIFS(Тех_Движение!$E$2:$E$5111,Тех_Движение!$B$2:$B$5111,Настройки!$B$5,Тех_Движение!$D$2:$D$5111,$A8) | C8: =SUMIFS(Тех_Движение!$F$2:$F$5111,Тех_Движение!$B$2:$B$5111,">="&Настройки!$B$5,Тех_Движение!$B$2:$B$5111,"<="&Настройки!$B$6,Тех_Движение!$D$2:$D$5111,$A8) | D8: =SUMIFS(Тех_Движение!$G$2:$G$5111,Тех_Движение!$B$2:$B$5111,">="&Настройки!$B$5,Тех_Движение!$B$2:$B$5111,"<="&Настройки!$B$6,Тех_Движение!$D$2:$D$5111,$A8) | E8: =SUMIFS(Тех_Движение!$H$2:$H$5111,Тех_Движение!$B$2:$B$5111,Настройки!$B$6,Тех_Движение!$D$2:$D$5111,$A8) | F8: =IF(ABS($B8+$C8-$D8-$E8)<0.0001,"OK","ОШИБКА") | G8: =$C8*VLOOKUP($A8,Настройки!$A$11:$L$17,4,FALSE)+$D8*VLOOKUP($A8,Настройки!$A$11:$L$17,8,FALSE) | H8: =SUMIFS(Тех_Хранение!$T$5:$T$5114,Тех_Хранение!$C$5:$C$5114,$A8) | I8: =$C8*VLOOKUP($A8,Настройки!$A$11:$L$17,10,FALSE)+$D8*VLOOKUP($A8,Настройки!$A$11:$L$17,11,FALSE)
A9: АК-15 | B9: =SUMIFS(Тех_Движение!$E$2:$E$5111,Тех_Движение!$B$2:$B$5111,Настройки!$B$5,Тех_Движение!$D$2:$D$5111,$A9) | C9: =SUMIFS(Тех_Движение!$F$2:$F$5111,Тех_Движение!$B$2:$B$5111,">="&Настройки!$B$5,Тех_Движение!$B$2:$B$5111,"<="&Настройки!$B$6,Тех_Движение!$D$2:$D$5111,$A9) | D9: =SUMIFS(Тех_Движение!$G$2:$G$5111,Тех_Движение!$B$2:$B$5111,">="&Настройки!$B$5,Тех_Движение!$B$2:$B$5111,"<="&Настройки!$B$6,Тех_Движение!$D$2:$D$5111,$A9) | E9: =SUMIFS(Тех_Движение!$H$2:$H$5111,Тех_Движение!$B$2:$B$5111,Настройки!$B$6,Тех_Движение!$D$2:$D$5111,$A9) | F9: =IF(ABS($B9+$C9-$D9-$E9)<0.0001,"OK","ОШИБКА") | G9: =$C9*VLOOKUP($A9,Настройки!$A$11:$L$17,4,FALSE)+$D9*VLOOKUP($A9,Настройки!$A$11:$L$17,8,FALSE) | H9: =SUMIFS(Тех_Хранение!$T$5:$T$5114,Тех_Хранение!$C$5:$C$5114,$A9) | I9: =$C9*VLOOKUP($A9,Настройки!$A$11:$L$17,10,FALSE)+$D9*VLOOKUP($A9,Настройки!$A$11:$L$17,11,FALSE)
A10: Г 1800 | B10: =SUMIFS(Тех_Движение!$E$2:$E$5111,Тех_Движение!$B$2:$B$5111,Настройки!$B$5,Тех_Движение!$D$2:$D$5111,$A10) | C10: =SUMIFS(Тех_Движение!$F$2:$F$5111,Тех_Движение!$B$2:$B$5111,">="&Настройки!$B$5,Тех_Движение!$B$2:$B$5111,"<="&Настройки!$B$6,Тех_Движение!$D$2:$D$5111,$A10) | D10: =SUMIFS(Тех_Движение!$G$2:$G$5111,Тех_Движение!$B$2:$B$5111,">="&Настройки!$B$5,Тех_Движение!$B$2:$B$5111,"<="&Настройки!$B$6,Тех_Движение!$D$2:$D$5111,$A10) | E10: =SUMIFS(Тех_Движение!$H$2:$H$5111,Тех_Движение!$B$2:$B$5111,Настройки!$B$6,Тех_Движение!$D$2:$D$5111,$A10) | F10: =IF(ABS($B10+$C10-$D10-$E10)<0.0001,"OK","ОШИБКА") | G10: =$C10*VLOOKUP($A10,Настройки!$A$11:$L$17,4,FALSE)+$D10*VLOOKUP($A10,Настройки!$A$11:$L$17,8,FALSE) | H10: =SUMIFS(Тех_Хранение!$T$5:$T$5114,Тех_Хранение!$C$5:$C$5114,$A10) | I10: =$C10*VLOOKUP($A10,Настройки!$A$11:$L$17,10,FALSE)+$D10*VLOOKUP($A10,Настройки!$A$11:$L$17,11,FALSE)
A11: Г 3500 | B11: =SUMIFS(Тех_Движение!$E$2:$E$5111,Тех_Движение!$B$2:$B$5111,Настройки!$B$5,Тех_Движение!$D$2:$D$5111,$A11) | C11: =SUMIFS(Тех_Движение!$F$2:$F$5111,Тех_Движение!$B$2:$B$5111,">="&Настройки!$B$5,Тех_Движение!$B$2:$B$5111,"<="&Настройки!$B$6,Тех_Движение!$D$2:$D$5111,$A11) | D11: =SUMIFS(Тех_Движение!$G$2:$G$5111,Тех_Движение!$B$2:$B$5111,">="&Настройки!$B$5,Тех_Движение!$B$2:$B$5111,"<="&Настройки!$B$6,Тех_Движение!$D$2:$D$5111,$A11) | E11: =SUMIFS(Тех_Движение!$H$2:$H$5111,Тех_Движение!$B$2:$B$5111,Настройки!$B$6,Тех_Движение!$D$2:$D$5111,$A11) | F11: =IF(ABS($B11+$C11-$D11-$E11)<0.0001,"OK","ОШИБКА") | G11: =$C11*VLOOKUP($A11,Настройки!$A$11:$L$17,4,FALSE)+$D11*VLOOKUP($A11,Настройки!$A$11:$L$17,8,FALSE) | H11: =SUMIFS(Тех_Хранение!$T$5:$T$5114,Тех_Хранение!$C$5:$C$5114,$A11) | I11: =$C11*VLOOKUP($A11,Настройки!$A$11:$L$17,10,FALSE)+$D11*VLOOKUP($A11,Настройки!$A$11:$L$17,11,FALSE)
A12: Г 800 | B12: =SUMIFS(Тех_Движение!$E$2:$E$5111,Тех_Движение!$B$2:$B$5111,Настройки!$B$5,Тех_Движение!$D$2:$D$5111,$A12) | C12: =SUMIFS(Тех_Движение!$F$2:$F$5111,Тех_Движение!$B$2:$B$5111,">="&Настройки!$B$5,Тех_Движение!$B$2:$B$5111,"<="&Настройки!$B$6,Тех_Движение!$D$2:$D$5111,$A12) | D12: =SUMIFS(Тех_Движение!$G$2:$G$5111,Тех_Движение!$B$2:$B$5111,">="&Настройки!$B$5,Тех_Движение!$B$2:$B$5111,"<="&Настройки!$B$6,Тех_Движение!$D$2:$D$5111,$A12) | E12: =SUMIFS(Тех_Движение!$H$2:$H$5111,Тех_Движение!$B$2:$B$5111,Настройки!$B$6,Тех_Движение!$D$2:$D$5111,$A12) | F12: =IF(ABS($B12+$C12-$D12-$E12)<0.0001,"OK","ОШИБКА") | G12: =$C12*VLOOKUP($A12,Настройки!$A$11:$L$17,4,FALSE)+$D12*VLOOKUP($A12,Настройки!$A$11:$L$17,8,FALSE) | H12: =SUMIFS(Тех_Хранение!$T$5:$T$5114,Тех_Хранение!$C$5:$C$5114,$A12) | I12: =$C12*VLOOKUP($A12,Настройки!$A$11:$L$17,10,FALSE)+$D12*VLOOKUP($A12,Настройки!$A$11:$L$17,11,FALSE)
A13: Ми-К | B13: =SUMIFS(Тех_Движение!$E$2:$E$5111,Тех_Движение!$B$2:$B$5111,Настройки!$B$5,Тех_Движение!$D$2:$D$5111,$A13) | C13: =SUMIFS(Тех_Движение!$F$2:$F$5111,Тех_Движение!$B$2:$B$5111,">="&Настройки!$B$5,Тех_Движение!$B$2:$B$5111,"<="&Настройки!$B$6,Тех_Движение!$D$2:$D$5111,$A13) | D13: =SUMIFS(Тех_Движение!$G$2:$G$5111,Тех_Движение!$B$2:$B$5111,">="&Настройки!$B$5,Тех_Движение!$B$2:$B$5111,"<="&Настройки!$B$6,Тех_Движение!$D$2:$D$5111,$A13) | E13: =SUMIFS(Тех_Движение!$H$2:$H$5111,Тех_Движение!$B$2:$B$5111,Настройки!$B$6,Тех_Движение!$D$2:$D$5111,$A13) | F13: =IF(ABS($B13+$C13-$D13-$E13)<0.0001,"OK","ОШИБКА") | G13: =$C13*VLOOKUP($A13,Настройки!$A$11:$L$17,4,FALSE)+$D13*VLOOKUP($A13,Настройки!$A$11:$L$17,8,FALSE) | H13: =SUMIFS(Тех_Хранение!$T$5:$T$5114,Тех_Хранение!$C$5:$C$5114,$A13) | I13: =$C13*VLOOKUP($A13,Настройки!$A$11:$L$17,10,FALSE)+$D13*VLOOKUP($A13,Настройки!$A$11:$L$17,11,FALSE)
A14: Ми-П | B14: =SUMIFS(Тех_Движение!$E$2:$E$5111,Тех_Движение!$B$2:$B$5111,Настройки!$B$5,Тех_Движение!$D$2:$D$5111,$A14) | C14: =SUMIFS(Тех_Движение!$F$2:$F$5111,Тех_Движение!$B$2:$B$5111,">="&Настройки!$B$5,Тех_Движение!$B$2:$B$5111,"<="&Настройки!$B$6,Тех_Движение!$D$2:$D$5111,$A14) | D14: =SUMIFS(Тех_Движение!$G$2:$G$5111,Тех_Движение!$B$2:$B$5111,">="&Настройки!$B$5,Тех_Движение!$B$2:$B$5111,"<="&Настройки!$B$6,Тех_Движение!$D$2:$D$5111,$A14) | E14: =SUMIFS(Тех_Движение!$H$2:$H$5111,Тех_Движение!$B$2:$B$5111,Настройки!$B$6,Тех_Движение!$D$2:$D$5111,$A14) | F14: =IF(ABS($B14+$C14-$D14-$E14)<0.0001,"OK","ОШИБКА") | G14: =$C14*VLOOKUP($A14,Настройки!$A$11:$L$17,4,FALSE)+$D14*VLOOKUP($A14,Настройки!$A$11:$L$17,8,FALSE) | H14: =SUMIFS(Тех_Хранение!$T$5:$T$5114,Тех_Хранение!$C$5:$C$5114,$A14) | I14: =$C14*VLOOKUP($A14,Настройки!$A$11:$L$17,10,FALSE)+$D14*VLOOKUP($A14,Настройки!$A$11:$L$17,11,FALSE)
A15: ИТОГО | B15: =SUM(B8:B14) | C15: =SUM(C8:C14) | D15: =SUM(D8:D14) | E15: =SUM(E8:E14) | F15: =IF(COUNTIF(F8:F14,"ОШИБКА")=0,"OK","ОШИБКА") | G15: =SUM(G8:G14) | H15: =SUM(H8:H14) | I15: =SUM(I8:I14)
A17: Ввод данных
A18: Желтые поля: оператор, приход, убытие. Серые поля считаются автоматически. Не сортируй строки; используй фильтр или поиск по дате.
A20: Дата | B20: День | C20: Оператор | D20: АК-10 | H20: АК-15 | L20: Г 1800 | P20: Г 3500 | T20: Г 800 | X20: Ми-К | AB20: Ми-П | AF20: Контроль дня
D21: Остаток начало | E21: Приход | F21: Убытие | G21: Остаток конец | H21: Остаток начало | I21: Приход | J21: Убытие | K21: Остаток конец | L21: Остаток начало | M21: Приход | N21: Убытие | O21: Остаток конец | P21: Остаток начало | Q21: Приход | R21: Убытие | S21: Остаток конец | T21: Остаток начало | U21: Приход | V21: Убытие | W21: Остаток конец | X21: Остаток начало | Y21: Приход | Z21: Убытие | AA21: Остаток конец | AB21: Остаток начало | AC21: Приход | AD21: Убытие | AE21: Остаток конец
A22: 46241 | B22: ПТ | D22: =VLOOKUP("АК-10",Настройки!$A$11:$L$17,12,FALSE) | G22: =D22+N(E22)-N(F22) | H22: =VLOOKUP("АК-15",Настройки!$A$11:$L$17,12,FALSE) | K22: =H22+N(I22)-N(J22) | L22: =VLOOKUP("Г 1800",Настройки!$A$11:$L$17,12,FALSE) | O22: =L22+N(M22)-N(N22) | P22: =VLOOKUP("Г 3500",Настройки!$A$11:$L$17,12,FALSE) | S22: =P22+N(Q22)-N(R22) | T22: =VLOOKUP("Г 800",Настройки!$A$11:$L$17,12,FALSE) | W22: =T22+N(U22)-N(V22) | X22: =VLOOKUP("Ми-К",Настройки!$A$11:$L$17,12,FALSE) | Y22: 10 | AA22: =X22+N(Y22)-N(Z22) | AB22: =VLOOKUP("Ми-П",Настройки!$A$11:$L$17,12,FALSE) | AE22: =AB22+N(AC22)-N(AD22) | AF22: =IF(ABS((D22+H22+L22+P22+T22+X22+AB22)+(N(E22)+N(I22)+N(M22)+N(Q22)+N(U22)+N(Y22)+N(AC22))-(N(F22)+N(J22)+N(N22)+N(R22)+N(V22)+N(Z22)+N(AD22))-(G22+K22+O22+S22+W22+AA22+AE22))<0.0001,"OK","ОШИБКА")
A23: 46242 | B23: СБ | D23: =G22 | G23: =D23+N(E23)-N(F23) | H23: =K22 | K23: =H23+N(I23)-N(J23) | L23: =O22 | M23: 9 | O23: =L23+N(M23)-N(N23) | P23: =S22 | Q23: 2 | R23: 2 | S23: =P23+N(Q23)-N(R23) | T23: =W22 | W23: =T23+N(U23)-N(V23) | X23: =AA22 | Z23: 3 | AA23: =X23+N(Y23)-N(Z23) | AB23: =AE22 | AE23: =AB23+N(AC23)-N(AD23) | AF23: =IF(ABS((D23+H23+L23+P23+T23+X23+AB23)+(N(E23)+N(I23)+N(M23)+N(Q23)+N(U23)+N(Y23)+N(AC23))-(N(F23)+N(J23)+N(N23)+N(R23)+N(V23)+N(Z23)+N(AD23))-(G23+K23+O23+S23+W23+AA23+AE23))<0.0001,"OK","ОШИБКА")
A24: 46243 | B24: ВС | D24: =G23 | G24: =D24+N(E24)-N(F24) | H24: =K23 | K24: =H24+N(I24)-N(J24) | L24: =O23 | M24: 10 | O24: =L24+N(M24)-N(N24) | P24: =S23 | Q24: 2 | S24: =P24+N(Q24)-N(R24) | T24: =W23 | W24: =T24+N(U24)-N(V24) | X24: =AA23 | Y24: 10 | Z24: 5 | AA24: =X24+N(Y24)-N(Z24) | AB24: =AE23 | AE24: =AB24+N(AC24)-N(AD24) | AF24: =IF(ABS((D24+H24+L24+P24+T24+X24+AB24)+(N(E24)+N(I24)+N(M24)+N(Q24)+N(U24)+N(Y24)+N(AC24))-(N(F24)+N(J24)+N(N24)+N(R24)+N(V24)+N(Z24)+N(AD24))-(G24+K24+O24+S24+W24+AA24+AE24))<0.0001,"OK","ОШИБКА")
A25: 46244 | B25: ПН | D25: =G24 | G25: =D25+N(E25)-N(F25) | H25: =K24 | K25: =H25+N(I25)-N(J25) | L25: =O24 | N25: 6 | O25: =L25+N(M25)-N(N25) | P25: =S24 | R25: 2 | S25: =P25+N(Q25)-N(R25) | T25: =W24 | W25: =T25+N(U25)-N(V25) | X25: =AA24 | Z25: 2 | AA25: =X25+N(Y25)-N(Z25) | AB25: =AE24 | AE25: =AB25+N(AC25)-N(AD25) | AF25: =IF(ABS((D25+H25+L25+P25+T25+X25+AB25)+(N(E25)+N(I25)+N(M25)+N(Q25)+N(U25)+N(Y25)+N(AC25))-(N(F25)+N(J25)+N(N25)+N(R25)+N(V25)+N(Z25)+N(AD25))-(G25+K25+O25+S25+W25+AA25+AE25))<0.0001,"OK","ОШИБКА")
A26: 46245 | B26: ВТ | D26: =G25 | G26: =D26+N(E26)-N(F26) | H26: =K25 | K26: =H26+N(I26)-N(J26) | L26: =O25 | N26: 2 | O26: =L26+N(M26)-N(N26) | P26: =S25 | Q26: 10 | R26: 3 | S26: =P26+N(Q26)-N(R26) | T26: =W25 | W26: =T26+N(U26)-N(V26) | X26: =AA25 | Z26: 1 | AA26: =X26+N(Y26)-N(Z26) | AB26: =AE25 | AE26: =AB26+N(AC26)-N(AD26) | AF26: =IF(ABS((D26+H26+L26+P26+T26+X26+AB26)+(N(E26)+N(I26)+N(M26)+N(Q26)+N(U26)+N(Y26)+N(AC26))-(N(F26)+N(J26)+N(N26)+N(R26)+N(V26)+N(Z26)+N(AD26))-(G26+K26+O26+S26+W26+AA26+AE26))<0.0001,"OK","ОШИБКА")
A27: 46246 | B27: СР | D27: =G26 | G27: =D27+N(E27)-N(F27) | H27: =K26 | K27: =H27+N(I27)-N(J27) | L27: =O26 | N27: 4 | O27: =L27+N(M27)-N(N27) | P27: =S26 | R27: 1 | S27: =P27+N(Q27)-N(R27) | T27: =W26 | W27: =T27+N(U27)-N(V27) | X27: =AA26 | Z27: 2 | AA27: =X27+N(Y27)-N(Z27) | AB27: =AE26 | AE27: =AB27+N(AC27)-N(AD27) | AF27: =IF(ABS((D27+H27+L27+P27+T27+X27+AB27)+(N(E27)+N(I27)+N(M27)+N(Q27)+N(U27)+N(Y27)+N(AC27))-(N(F27)+N(J27)+N(N27)+N(R27)+N(V27)+N(Z27)+N(AD27))-(G27+K27+O27+S27+W27+AA27+AE27))<0.0001,"OK","ОШИБКА")
A28: 46247 | B28: ЧТ | D28: =G27 | G28: =D28+N(E28)-N(F28) | H28: =K27 | K28: =H28+N(I28)-N(J28) | L28: =O27 | M28: 10 | N28: 6 | O28: =L28+N(M28)-N(N28) | P28: =S27 | R28: 1 | S28: =P28+N(Q28)-N(R28) | T28: =W27 | W28: =T28+N(U28)-N(V28) | X28: =AA27 | Y28: 10 | Z28: 4 | AA28: =X28+N(Y28)-N(Z28) | AB28: =AE27 | AE28: =AB28+N(AC28)-N(AD28) | AF28: =IF(ABS((D28+H28+L28+P28+T28+X28+AB28)+(N(E28)+N(I28)+N(M28)+N(Q28)+N(U28)+N(Y28)+N(AC28))-(N(F28)+N(J28)+N(N28)+N(R28)+N(V28)+N(Z28)+N(AD28))-(G28+K28+O28+S28+W28+AA28+AE28))<0.0001,"OK","ОШИБКА")
A29: 46248 | B29: ПТ | D29: =G28 | G29: =D29+N(E29)-N(F29) | H29: =K28 | K29: =H29+N(I29)-N(J29) | L29: =O28 | N29: 9 | O29: =L29+N(M29)-N(N29) | P29: =S28 | R29: 3 | S29: =P29+N(Q29)-N(R29) | T29: =W28 | W29: =T29+N(U29)-N(V29) | X29: =AA28 | Z29: 1 | AA29: =X29+N(Y29)-N(Z29) | AB29: =AE28 | AE29: =AB29+N(AC29)-N(AD29) | AF29: =IF(ABS((D29+H29+L29+P29+T29+X29+AB29)+(N(E29)+N(I29)+N(M29)+N(Q29)+N(U29)+N(Y29)+N(AC29))-(N(F29)+N(J29)+N(N29)+N(R29)+N(V29)+N(Z29)+N(AD29))-(G29+K29+O29+S29+W29+AA29+AE29))<0.0001,"OK","ОШИБКА")
A30: 46249 | B30: СБ | D30: =G29 | G30: =D30+N(E30)-N(F30) | H30: =K29 | K30: =H30+N(I30)-N(J30) | L30: =O29 | M30: 10 | N30: 6 | O30: =L30+N(M30)-N(N30) | P30: =S29 | Q30: 10 | S30: =P30+N(Q30)-N(R30) | T30: =W29 | W30: =T30+N(U30)-N(V30) | X30: =AA29 | Y30: 5 | Z30: 8 | AA30: =X30+N(Y30)-N(Z30) | AB30: =AE29 | AE30: =AB30+N(AC30)-N(AD30) | AF30: =IF(ABS((D30+H30+L30+P30+T30+X30+AB30)+(N(E30)+N(I30)+N(M30)+N(Q30)+N(U30)+N(Y30)+N(AC30))-(N(F30)+N(J30)+N(N30)+N(R30)+N(V30)+N(Z30)+N(AD30))-(G30+K30+O30+S30+W30+AA30+AE30))<0.0001,"OK","ОШИБКА")
A31: 46250 | B31: ВС | D31: =G30 | G31: =D31+N(E31)-N(F31) | H31: =K30 | K31: =H31+N(I31)-N(J31) | L31: =O30 | M31: 10 | N31: 5 | O31: =L31+N(M31)-N(N31) | P31: =S30 | S31: =P31+N(Q31)-N(R31) | T31: =W30 | W31: =T31+N(U31)-N(V31) | X31: =AA30 | Z31: 4 | AA31: =X31+N(Y31)-N(Z31) | AB31: =AE30 | AE31: =AB31+N(AC31)-N(AD31) | AF31: =IF(ABS((D31+H31+L31+P31+T31+X31+AB31)+(N(E31)+N(I31)+N(M31)+N(Q31)+N(U31)+N(Y31)+N(AC31))-(N(F31)+N(J31)+N(N31)+N(R31)+N(V31)+N(Z31)+N(AD31))-(G31+K31+O31+S31+W31+AA31+AE31))<0.0001,"OK","ОШИБКА")
A32: 46251 | B32: ПН | D32: =G31 | G32: =D32+N(E32)-N(F32) | H32: =K31 | K32: =H32+N(I32)-N(J32) | L32: =O31 | N32: 4 | O32: =L32+N(M32)-N(N32) | P32: =S31 | S32: =P32+N(Q32)-N(R32) | T32: =W31 | W32: =T32+N(U32)-N(V32) | X32: =AA31 | Z32: 4 | AA32: =X32+N(Y32)-N(Z32) | AB32: =AE31 | AE32: =AB32+N(AC32)-N(AD32) | AF32: =IF(ABS((D32+H32+L32+P32+T32+X32+AB32)+(N(E32)+N(I32)+N(M32)+N(Q32)+N(U32)+N(Y32)+N(AC32))-(N(F32)+N(J32)+N(N32)+N(R32)+N(V32)+N(Z32)+N(AD32))-(G32+K32+O32+S32+W32+AA32+AE32))<0.0001,"OK","ОШИБКА")
A33: 46252 | B33: ВТ | D33: =G32 | G33: =D33+N(E33)-N(F33) | H33: =K32 | K33: =H33+N(I33)-N(J33) | L33: =O32 | M33: 5 | N33: 2 | O33: =L33+N(M33)-N(N33) | P33: =S32 | R33: 1 | S33: =P33+N(Q33)-N(R33) | T33: =W32 | U33: 10 | W33: =T33+N(U33)-N(V33) | X33: =AA32 | Y33: 10 | Z33: 4 | AA33: =X33+N(Y33)-N(Z33) | AB33: =AE32 | AE33: =AB33+N(AC33)-N(AD33) | AF33: =IF(ABS((D33+H33+L33+P33+T33+X33+AB33)+(N(E33)+N(I33)+N(M33)+N(Q33)+N(U33)+N(Y33)+N(AC33))-(N(F33)+N(J33)+N(N33)+N(R33)+N(V33)+N(Z33)+N(AD33))-(G33+K33+O33+S33+W33+AA33+AE33))<0.0001,"OK","ОШИБКА")
A34: 46253 | B34: СР | D34: =G33 | G34: =D34+N(E34)-N(F34) | H34: =K33 | K34: =H34+N(I34)-N(J34) | L34: =O33 | M34: 15 | N34: 11 | O34: =L34+N(M34)-N(N34) | P34: =S33 | R34: 1 | S34: =P34+N(Q34)-N(R34) | T34: =W33 | V34: 2 | W34: =T34+N(U34)-N(V34) | X34: =AA33 | Y34: 10 | Z34: 1 | AA34: =X34+N(Y34)-N(Z34) | AB34: =AE33 | AE34: =AB34+N(AC34)-N(AD34) | AF34: =IF(ABS((D34+H34+L34+P34+T34+X34+AB34)+(N(E34)+N(I34)+N(M34)+N(Q34)+N(U34)+N(Y34)+N(AC34))-(N(F34)+N(J34)+N(N34)+N(R34)+N(V34)+N(Z34)+N(AD34))-(G34+K34+O34+S34+W34+AA34+AE34))<0.0001,"OK","ОШИБКА")
A35: 46254 | B35: ЧТ | D35: =G34 | E35: 5 | G35: =D35+N(E35)-N(F35) | H35: =K34 | I35: 28 | K35: =H35+N(I35)-N(J35) | L35: =O34 | N35: 6 | O35: =L35+N(M35)-N(N35) | P35: =S34 | S35: =P35+N(Q35)-N(R35) | T35: =W34 | V35: 2 | W35: =T35+N(U35)-N(V35) | X35: =AA34 | Z35: 1 | AA35: =X35+N(Y35)-N(Z35) | AB35: =AE34 | AE35: =AB35+N(AC35)-N(AD35) | AF35: =IF(ABS((D35+H35+L35+P35+T35+X35+AB35)+(N(E35)+N(I35)+N(M35)+N(Q35)+N(U35)+N(Y35)+N(AC35))-(N(F35)+N(J35)+N(N35)+N(R35)+N(V35)+N(Z35)+N(AD35))-(G35+K35+O35+S35+W35+AA35+AE35))<0.0001,"OK","ОШИБКА")
A36: 46255 | B36: ПТ | D36: =G35 | G36: =D36+N(E36)-N(F36) | H36: =K35 | J36: 1 | K36: =H36+N(I36)-N(J36) | L36: =O35 | N36: 2 | O36: =L36+N(M36)-N(N36) | P36: =S35 | S36: =P36+N(Q36)-N(R36) | T36: =W35 | V36: 1 | W36: =T36+N(U36)-N(V36) | X36: =AA35 | AA36: =X36+N(Y36)-N(Z36) | AB36: =AE35 | AE36: =AB36+N(AC36)-N(AD36) | AF36: =IF(ABS((D36+H36+L36+P36+T36+X36+AB36)+(N(E36)+N(I36)+N(M36)+N(Q36)+N(U36)+N(Y36)+N(AC36))-(N(F36)+N(J36)+N(N36)+N(R36)+N(V36)+N(Z36)+N(AD36))-(G36+K36+O36+S36+W36+AA36+AE36))<0.0001,"OK","ОШИБКА")
A37: 46256 | B37: СБ | D37: =G36 | G37: =D37+N(E37)-N(F37) | H37: =K36 | J37: 7 | K37: =H37+N(I37)-N(J37) | L37: =O36 | M37: 15 | N37: 6 | O37: =L37+N(M37)-N(N37) | P37: =S36 | S37: =P37+N(Q37)-N(R37) | T37: =W36 | U37: 10 | V37: 5 | W37: =T37+N(U37)-N(V37) | X37: =AA36 | Z37: 1 | AA37: =X37+N(Y37)-N(Z37) | AB37: =AE36 | AE37: =AB37+N(AC37)-N(AD37) | AF37: =IF(ABS((D37+H37+L37+P37+T37+X37+AB37)+(N(E37)+N(I37)+N(M37)+N(Q37)+N(U37)+N(Y37)+N(AC37))-(N(F37)+N(J37)+N(N37)+N(R37)+N(V37)+N(Z37)+N(AD37))-(G37+K37+O37+S37+W37+AA37+AE37))<0.0001,"OK","ОШИБКА")
A38: 46257 | B38: ВС | D38: =G37 | F38: 1 | G38: =D38+N(E38)-N(F38) | H38: =K37 | J38: 1 | K38: =H38+N(I38)-N(J38) | L38: =O37 | N38: 7 | O38: =L38+N(M38)-N(N38) | P38: =S37 | S38: =P38+N(Q38)-N(R38) | T38: =W37 | V38: 4 | W38: =T38+N(U38)-N(V38) | X38: =AA37 | Z38: 2 | AA38: =X38+N(Y38)-N(Z38) | AB38: =AE37 | AE38: =AB38+N(AC38)-N(AD38) | AF38: =IF(ABS((D38+H38+L38+P38+T38+X38+AB38)+(N(E38)+N(I38)+N(M38)+N(Q38)+N(U38)+N(Y38)+N(AC38))-(N(F38)+N(J38)+N(N38)+N(R38)+N(V38)+N(Z38)+N(AD38))-(G38+K38+O38+S38+W38+AA38+AE38))<0.0001,"OK","ОШИБКА")
A39: 46258 | B39: ПН | D39: =G38 | F39: 3 | G39: =D39+N(E39)-N(F39) | H39: =K38 | J39: 2 | K39: =H39+N(I39)-N(J39) | L39: =O38 | M39: 21 | N39: 8 | O39: =L39+N(M39)-N(N39) | P39: =S38 | R39: 1 | S39: =P39+N(Q39)-N(R39) | T39: =W38 | U39: 5 | V39: 5 | W39: =T39+N(U39)-N(V39) | X39: =AA38 | Z39: 3 | AA39: =X39+N(Y39)-N(Z39) | AB39: =AE38 | AE39: =AB39+N(AC39)-N(AD39) | AF39: =IF(ABS((D39+H39+L39+P39+T39+X39+AB39)+(N(E39)+N(I39)+N(M39)+N(Q39)+N(U39)+N(Y39)+N(AC39))-(N(F39)+N(J39)+N(N39)+N(R39)+N(V39)+N(Z39)+N(AD39))-(G39+K39+O39+S39+W39+AA39+AE39))<0.0001,"OK","ОШИБКА")
A40: 46259 | B40: ВТ | D40: =G39 | F40: 1 | G40: =D40+N(E40)-N(F40) | H40: =K39 | K40: =H40+N(I40)-N(J40) | L40: =O39 | N40: 5 | O40: =L40+N(M40)-N(N40) | P40: =S39 | R40: 2 | S40: =P40+N(Q40)-N(R40) | T40: =W39 | V40: 1 | W40: =T40+N(U40)-N(V40) | X40: =AA39 | Z40: 4 | AA40: =X40+N(Y40)-N(Z40) | AB40: =AE39 | AE40: =AB40+N(AC40)-N(AD40) | AF40: =IF(ABS((D40+H40+L40+P40+T40+X40+AB40)+(N(E40)+N(I40)+N(M40)+N(Q40)+N(U40)+N(Y40)+N(AC40))-(N(F40)+N(J40)+N(N40)+N(R40)+N(V40)+N(Z40)+N(AD40))-(G40+K40+O40+S40+W40+AA40+AE40))<0.0001,"OK","ОШИБКА")
A41: 46260 | B41: СР | D41: =G40 | E41: 5 | G41: =D41+N(E41)-N(F41) | H41: =K40 | J41: 6 | K41: =H41+N(I41)-N(J41) | L41: =O40 | M41: 20 | N41: 11 | O41: =L41+N(M41)-N(N41) | P41: =S40 | S41: =P41+N(Q41)-N(R41) | T41: =W40 | V41: 4 | W41: =T41+N(U41)-N(V41) | X41: =AA40 | Y41: 10 | Z41: 3 | AA41: =X41+N(Y41)-N(Z41) | AB41: =AE40 | AE41: =AB41+N(AC41)-N(AD41) | AF41: =IF(ABS((D41+H41+L41+P41+T41+X41+AB41)+(N(E41)+N(I41)+N(M41)+N(Q41)+N(U41)+N(Y41)+N(AC41))-(N(F41)+N(J41)+N(N41)+N(R41)+N(V41)+N(Z41)+N(AD41))-(G41+K41+O41+S41+W41+AA41+AE41))<0.0001,"OK","ОШИБКА")
A42: 46261 | B42: ЧТ | D42: =G41 | F42: 3 | G42: =D42+N(E42)-N(F42) | H42: =K41 | K42: =H42+N(I42)-N(J42) | L42: =O41 | N42: 9 | O42: =L42+N(M42)-N(N42) | P42: =S41 | S42: =P42+N(Q42)-N(R42) | T42: =W41 | V42: 1 | W42: =T42+N(U42)-N(V42) | X42: =AA41 | Z42: 4 | AA42: =X42+N(Y42)-N(Z42) | AB42: =AE41 | AE42: =AB42+N(AC42)-N(AD42) | AF42: =IF(ABS((D42+H42+L42+P42+T42+X42+AB42)+(N(E42)+N(I42)+N(M42)+N(Q42)+N(U42)+N(Y42)+N(AC42))-(N(F42)+N(J42)+N(N42)+N(R42)+N(V42)+N(Z42)+N(AD42))-(G42+K42+O42+S42+W42+AA42+AE42))<0.0001,"OK","ОШИБКА")
A43: 46262 | B43: ПТ | D43: =G42 | E43: 10 | G43: =D43+N(E43)-N(F43) | H43: =K42 | I43: 1 | J43: 1 | K43: =H43+N(I43)-N(J43) | L43: =O42 | M43: 20 | N43: 9 | O43: =L43+N(M43)-N(N43) | P43: =S42 | S43: =P43+N(Q43)-N(R43) | T43: =W42 | W43: =T43+N(U43)-N(V43) | X43: =AA42 | Y43: 11 | Z43: 4 | AA43: =X43+N(Y43)-N(Z43) | AB43: =AE42 | AE43: =AB43+N(AC43)-N(AD43) | AF43: =IF(ABS((D43+H43+L43+P43+T43+X43+AB43)+(N(E43)+N(I43)+N(M43)+N(Q43)+N(U43)+N(Y43)+N(AC43))-(N(F43)+N(J43)+N(N43)+N(R43)+N(V43)+N(Z43)+N(AD43))-(G43+K43+O43+S43+W43+AA43+AE43))<0.0001,"OK","ОШИБКА")
A44: 46263 | B44: СБ | D44: =G43 | G44: =D44+N(E44)-N(F44) | H44: =K43 | J44: 2 | K44: =H44+N(I44)-N(J44) | L44: =O43 | N44: 14 | O44: =L44+N(M44)-N(N44) | P44: =S43 | S44: =P44+N(Q44)-N(R44) | T44: =W43 | W44: =T44+N(U44)-N(V44) | X44: =AA43 | Y44: 10 | Z44: 2 | AA44: =X44+N(Y44)-N(Z44) | AB44: =AE43 | AE44: =AB44+N(AC44)-N(AD44) | AF44: =IF(ABS((D44+H44+L44+P44+T44+X44+AB44)+(N(E44)+N(I44)+N(M44)+N(Q44)+N(U44)+N(Y44)+N(AC44))-(N(F44)+N(J44)+N(N44)+N(R44)+N(V44)+N(Z44)+N(AD44))-(G44+K44+O44+S44+W44+AA44+AE44))<0.0001,"OK","ОШИБКА")
A45: 46264 | B45: ВС | D45: =G44 | F45: 1 | G45: =D45+N(E45)-N(F45) | H45: =K44 | I45: 28 | J45: 2 | K45: =H45+N(I45)-N(J45) | L45: =O44 | M45: 17 | N45: 9 | O45: =L45+N(M45)-N(N45) | P45: =S44 | R45: 2 | S45: =P45+N(Q45)-N(R45) | T45: =W44 | W45: =T45+N(U45)-N(V45) | X45: =AA44 | Z45: 4 | AA45: =X45+N(Y45)-N(Z45) | AB45: =AE44 | AE45: =AB45+N(AC45)-N(AD45) | AF45: =IF(ABS((D45+H45+L45+P45+T45+X45+AB45)+(N(E45)+N(I45)+N(M45)+N(Q45)+N(U45)+N(Y45)+N(AC45))-(N(F45)+N(J45)+N(N45)+N(R45)+N(V45)+N(Z45)+N(AD45))-(G45+K45+O45+S45+W45+AA45+AE45))<0.0001,"OK","ОШИБКА")
...

Sheet Тех_Движение
A1: ID | B1: Дата | C1: Оператор | D1: Товар | E1: Остаток начало | F1: Приход | G1: Убытие | H1: Остаток конец | I1: Капсула
A2: 1 | B2: =Движение!$A$22 | C2: =Движение!$C$22 | D2: АК-10 | E2: =Движение!$D$22 | F2: =N(Движение!$E$22) | G2: =N(Движение!$F$22) | H2: =Движение!$G$22 | I2: =IF($F2>0,TEXT($B2,"dd.mm")&"_"&$D2,"")
A3: 2 | B3: =Движение!$A$22 | C3: =Движение!$C$22 | D3: АК-15 | E3: =Движение!$H$22 | F3: =N(Движение!$I$22) | G3: =N(Движение!$J$22) | H3: =Движение!$K$22 | I3: =IF($F3>0,TEXT($B3,"dd.mm")&"_"&$D3,"")
A4: 3 | B4: =Движение!$A$22 | C4: =Движение!$C$22 | D4: Г 1800 | E4: =Движение!$L$22 | F4: =N(Движение!$M$22) | G4: =N(Движение!$N$22) | H4: =Движение!$O$22 | I4: =IF($F4>0,TEXT($B4,"dd.mm")&"_"&$D4,"")
A5: 4 | B5: =Движение!$A$22 | C5: =Движение!$C$22 | D5: Г 3500 | E5: =Движение!$P$22 | F5: =N(Движение!$Q$22) | G5: =N(Движение!$R$22) | H5: =Движение!$S$22 | I5: =IF($F5>0,TEXT($B5,"dd.mm")&"_"&$D5,"")
A6: 5 | B6: =Движение!$A$22 | C6: =Движение!$C$22 | D6: Г 800 | E6: =Движение!$T$22 | F6: =N(Движение!$U$22) | G6: =N(Движение!$V$22) | H6: =Движение!$W$22 | I6: =IF($F6>0,TEXT($B6,"dd.mm")&"_"&$D6,"")
A7: 6 | B7: =Движение!$A$22 | C7: =Движение!$C$22 | D7: Ми-К | E7: =Движение!$X$22 | F7: =N(Движение!$Y$22) | G7: =N(Движение!$Z$22) | H7: =Движение!$AA$22 | I7: =IF($F7>0,TEXT($B7,"dd.mm")&"_"&$D7,"")
A8: 7 | B8: =Движение!$A$22 | C8: =Движение!$C$22 | D8: Ми-П | E8: =Движение!$AB$22 | F8: =N(Движение!$AC$22) | G8: =N(Движение!$AD$22) | H8: =Движение!$AE$22 | I8: =IF($F8>0,TEXT($B8,"dd.mm")&"_"&$D8,"")
A9: 8 | B9: =Движение!$A$23 | C9: =Движение!$C$23 | D9: АК-10 | E9: =Движение!$D$23 | F9: =N(Движение!$E$23) | G9: =N(Движение!$F$23) | H9: =Движение!$G$23 | I9: =IF($F9>0,TEXT($B9,"dd.mm")&"_"&$D9,"")
A10: 9 | B10: =Движение!$A$23 | C10: =Движение!$C$23 | D10: АК-15 | E10: =Движение!$H$23 | F10: =N(Движение!$I$23) | G10: =N(Движение!$J$23) | H10: =Движение!$K$23 | I10: =IF($F10>0,TEXT($B10,"dd.mm")&"_"&$D10,"")
A11: 10 | B11: =Движение!$A$23 | C11: =Движение!$C$23 | D11: Г 1800 | E11: =Движение!$L$23 | F11: =N(Движение!$M$23) | G11: =N(Движение!$N$23) | H11: =Движение!$O$23 | I11: =IF($F11>0,TEXT($B11,"dd.mm")&"_"&$D11,"")
A12: 11 | B12: =Движение!$A$23 | C12: =Движение!$C$23 | D12: Г 3500 | E12: =Движение!$P$23 | F12: =N(Движение!$Q$23) | G12: =N(Движение!$R$23) | H12: =Движение!$S$23 | I12: =IF($F12>0,TEXT($B12,"dd.mm")&"_"&$D12,"")
A13: 12 | B13: =Движение!$A$23 | C13: =Движение!$C$23 | D13: Г 800 | E13: =Движение!$T$23 | F13: =N(Движение!$U$23) | G13: =N(Движение!$V$23) | H13: =Движение!$W$23 | I13: =IF($F13>0,TEXT($B13,"dd.mm")&"_"&$D13,"")
A14: 13 | B14: =Движение!$A$23 | C14: =Движение!$C$23 | D14: Ми-К | E14: =Движение!$X$23 | F14: =N(Движение!$Y$23) | G14: =N(Движение!$Z$23) | H14: =Движение!$AA$23 | I14: =IF($F14>0,TEXT($B14,"dd.mm")&"_"&$D14,"")
A15: 14 | B15: =Движение!$A$23 | C15: =Движение!$C$23 | D15: Ми-П | E15: =Движение!$AB$23 | F15: =N(Движение!$AC$23) | G15: =N(Движение!$AD$23) | H15: =Движение!$AE$23 | I15: =IF($F15>0,TEXT($B15,"dd.mm")&"_"&$D15,"")
A16: 15 | B16: =Движение!$A$24 | C16: =Движение!$C$24 | D16: АК-10 | E16: =Движение!$D$24 | F16: =N(Движение!$E$24) | G16: =N(Движение!$F$24) | H16: =Движение!$G$24 | I16: =IF($F16>0,TEXT($B16,"dd.mm")&"_"&$D16,"")
A17: 16 | B17: =Движение!$A$24 | C17: =Движение!$C$24 | D17: АК-15 | E17: =Движение!$H$24 | F17: =N(Движение!$I$24) | G17: =N(Движение!$J$24) | H17: =Движение!$K$24 | I17: =IF($F17>0,TEXT($B17,"dd.mm")&"_"&$D17,"")
A18: 17 | B18: =Движение!$A$24 | C18: =Движение!$C$24 | D18: Г 1800 | E18: =Движение!$L$24 | F18: =N(Движение!$M$24) | G18: =N(Движение!$N$24) | H18: =Движение!$O$24 | I18: =IF($F18>0,TEXT($B18,"dd.mm")&"_"&$D18,"")
A19: 18 | B19: =Движение!$A$24 | C19: =Движение!$C$24 | D19: Г 3500 | E19: =Движение!$P$24 | F19: =N(Движение!$Q$24) | G19: =N(Движение!$R$24) | H19: =Движение!$S$24 | I19: =IF($F19>0,TEXT($B19,"dd.mm")&"_"&$D19,"")
A20: 19 | B20: =Движение!$A$24 | C20: =Движение!$C$24 | D20: Г 800 | E20: =Движение!$T$24 | F20: =N(Движение!$U$24) | G20: =N(Движение!$V$24) | H20: =Движение!$W$24 | I20: =IF($F20>0,TEXT($B20,"dd.mm")&"_"&$D20,"")
A21: 20 | B21: =Движение!$A$24 | C21: =Движение!$C$24 | D21: Ми-К | E21: =Движение!$X$24 | F21: =N(Движение!$Y$24) | G21: =N(Движение!$Z$24) | H21: =Движение!$AA$24 | I21: =IF($F21>0,TEXT($B21,"dd.mm")&"_"&$D21,"")
A22: 21 | B22: =Движение!$A$24 | C22: =Движение!$C$24 | D22: Ми-П | E22: =Движение!$AB$24 | F22: =N(Движение!$AC$24) | G22: =N(Движение!$AD$24) | H22: =Движение!$AE$24 | I22: =IF($F22>0,TEXT($B22,"dd.mm")&"_"&$D22,"")
A23: 22 | B23: =Движение!$A$25 | C23: =Движение!$C$25 | D23: АК-10 | E23: =Движение!$D$25 | F23: =N(Движение!$E$25) | G23: =N(Движение!$F$25) | H23: =Движение!$G$25 | I23: =IF($F23>0,TEXT($B23,"dd.mm")&"_"&$D23,"")
A24: 23 | B24: =Движение!$A$25 | C24: =Движение!$C$25 | D24: АК-15 | E24: =Движение!$H$25 | F24: =N(Движение!$I$25) | G24: =N(Движение!$J$25) | H24: =Движение!$K$25 | I24: =IF($F24>0,TEXT($B24,"dd.mm")&"_"&$D24,"")
A25: 24 | B25: =Движение!$A$25 | C25: =Движение!$C$25 | D25: Г 1800 | E25: =Движение!$L$25 | F25: =N(Движение!$M$25) | G25: =N(Движение!$N$25) | H25: =Движение!$O$25 | I25: =IF($F25>0,TEXT($B25,"dd.mm")&"_"&$D25,"")
A26: 25 | B26: =Движение!$A$25 | C26: =Движение!$C$25 | D26: Г 3500 | E26: =Движение!$P$25 | F26: =N(Движение!$Q$25) | G26: =N(Движение!$R$25) | H26: =Движение!$S$25 | I26: =IF($F26>0,TEXT($B26,"dd.mm")&"_"&$D26,"")
A27: 26 | B27: =Движение!$A$25 | C27: =Движение!$C$25 | D27: Г 800 | E27: =Движение!$T$25 | F27: =N(Движение!$U$25) | G27: =N(Движение!$V$25) | H27: =Движение!$W$25 | I27: =IF($F27>0,TEXT($B27,"dd.mm")&"_"&$D27,"")
A28: 27 | B28: =Движение!$A$25 | C28: =Движение!$C$25 | D28: Ми-К | E28: =Движение!$X$25 | F28: =N(Движение!$Y$25) | G28: =N(Движение!$Z$25) | H28: =Движение!$AA$25 | I28: =IF($F28>0,TEXT($B28,"dd.mm")&"_"&$D28,"")
A29: 28 | B29: =Движение!$A$25 | C29: =Движение!$C$25 | D29: Ми-П | E29: =Движение!$AB$25 | F29: =N(Движение!$AC$25) | G29: =N(Движение!$AD$25) | H29: =Движение!$AE$25 | I29: =IF($F29>0,TEXT($B29,"dd.mm")&"_"&$D29,"")
A30: 29 | B30: =Движение!$A$26 | C30: =Движение!$C$26 | D30: АК-10 | E30: =Движение!$D$26 | F30: =N(Движение!$E$26) | G30: =N(Движение!$F$26) | H30: =Движение!$G$26 | I30: =IF($F30>0,TEXT($B30,"dd.mm")&"_"&$D30,"")
A31: 30 | B31: =Движение!$A$26 | C31: =Движение!$C$26 | D31: АК-15 | E31: =Движение!$H$26 | F31: =N(Движение!$I$26) | G31: =N(Движение!$J$26) | H31: =Движение!$K$26 | I31: =IF($F31>0,TEXT($B31,"dd.mm")&"_"&$D31,"")
A32: 31 | B32: =Движение!$A$26 | C32: =Движение!$C$26 | D32: Г 1800 | E32: =Движение!$L$26 | F32: =N(Движение!$M$26) | G32: =N(Движение!$N$26) | H32: =Движение!$O$26 | I32: =IF($F32>0,TEXT($B32,"dd.mm")&"_"&$D32,"")
A33: 32 | B33: =Движение!$A$26 | C33: =Движение!$C$26 | D33: Г 3500 | E33: =Движение!$P$26 | F33: =N(Движение!$Q$26) | G33: =N(Движение!$R$26) | H33: =Движение!$S$26 | I33: =IF($F33>0,TEXT($B33,"dd.mm")&"_"&$D33,"")
A34: 33 | B34: =Движение!$A$26 | C34: =Движение!$C$26 | D34: Г 800 | E34: =Движение!$T$26 | F34: =N(Движение!$U$26) | G34: =N(Движение!$V$26) | H34: =Движение!$W$26 | I34: =IF($F34>0,TEXT($B34,"dd.mm")&"_"&$D34,"")
A35: 34 | B35: =Движение!$A$26 | C35: =Движение!$C$26 | D35: Ми-К | E35: =Движение!$X$26 | F35: =N(Движение!$Y$26) | G35: =N(Движение!$Z$26) | H35: =Движение!$AA$26 | I35: =IF($F35>0,TEXT($B35,"dd.mm")&"_"&$D35,"")
A36: 35 | B36: =Движение!$A$26 | C36: =Движение!$C$26 | D36: Ми-П | E36: =Движение!$AB$26 | F36: =N(Движение!$AC$26) | G36: =N(Движение!$AD$26) | H36: =Движение!$AE$26 | I36: =IF($F36>0,TEXT($B36,"dd.mm")&"_"&$D36,"")
A37: 36 | B37: =Движение!$A$27 | C37: =Движение!$C$27 | D37: АК-10 | E37: =Движение!$D$27 | F37: =N(Движение!$E$27) | G37: =N(Движение!$F$27) | H37: =Движение!$G$27 | I37: =IF($F37>0,TEXT($B37,"dd.mm")&"_"&$D37,"")
A38: 37 | B38: =Движение!$A$27 | C38: =Движение!$C$27 | D38: АК-15 | E38: =Движение!$H$27 | F38: =N(Движение!$I$27) | G38: =N(Движение!$J$27) | H38: =Движение!$K$27 | I38: =IF($F38>0,TEXT($B38,"dd.mm")&"_"&$D38,"")
A39: 38 | B39: =Движение!$A$27 | C39: =Движение!$C$27 | D39: Г 1800 | E39: =Движение!$L$27 | F39: =N(Движение!$M$27) | G39: =N(Движение!$N$27) | H39: =Движение!$O$27 | I39: =IF($F39>0,TEXT($B39,"dd.mm")&"_"&$D39,"")
A40: 39 | B40: =Движение!$A$27 | C40: =Движение!$C$27 | D40: Г 3500 | E40: =Движение!$P$27 | F40: =N(Движение!$Q$27) | G40: =N(Движение!$R$27) | H40: =Движение!$S$27 | I40: =IF($F40>0,TEXT($B40,"dd.mm")&"_"&$D40,"")
...

Sheet Тех_Хранение
D1: Хранение по капсулам FIFO
D2: Расчетный лист. Капсулы создаются из приходов на листе «Движение».
K3: =Настройки!$B$5+0 | L3: =Настройки!$B$5+1 | M3: =Настройки!$B$5+2 | N3: =Настройки!$B$5+3 | O3: =Настройки!$B$5+4 | P3: =Настройки!$B$5+5 | Q3: =Настройки!$B$5+6
A4: ID движения | B4: Капсула | C4: Товар | D4: Дата прихода | E4: Кол-во капсулы | F4: Предыдущие капсулы FIFO | G4: Остаток на начало периода | H4: Приход в периоде | I4: Списано FIFO в периоде | J4: Остаток на конец периода | K4: Платный остаток 1 | L4: Платный остаток 2 | M4: Платный остаток 3 | N4: Платный остаток 4 | O4: Платный остаток 5 | P4: Платный остаток 6 | Q4: Платный остаток 7 | R4: Платные шт-дни | S4: Тариф | T4: Сумма хранения
A5: =Тех_Движение!$A$2 | B5: =IF(Тех_Движение!$F$2>0,Тех_Движение!$I$2,"") | C5: =IF($B5="","",Тех_Движение!$D$2) | D5: =IF($B5="","",Тех_Движение!$B$2) | E5: =IF($B5="","",Тех_Движение!$F$2) | F5: =IF($B5="","",0) | G5: =IF($B5="","",MAX(0,$E5-MAX(0,SUMIFS(Тех_Движение!$G$2:$G$5111,Тех_Движение!$D$2:$D$5111,$C5,Тех_Движение!$B$2:$B$5111,"<="&Настройки!$B$5-1)-$F5))) | H5: =IF($B5="","",IF(AND($D5>=Настройки!$B$5,$D5<=Настройки!$B$6),$E5,0)) | I5: =IF($B5="","",$G5+$H5-$J5) | J5: =IF($B5="","",MAX(0,$E5-MAX(0,SUMIFS(Тех_Движение!$G$2:$G$5111,Тех_Движение!$D$2:$D$5111,$C5,Тех_Движение!$B$2:$B$5111,"<="&Настройки!$B$6)-$F5))) | K5: =IF(OR($B5="",K$3<$D5+Настройки!$B$7),0,MAX(0,$E5-MAX(0,SUMIFS(Тех_Движение!$G$2:$G$5111,Тех_Движение!$D$2:$D$5111,$C5,Тех_Движение!$B$2:$B$5111,"<="&K$3)-$F5))) | L5: =IF(OR($B5="",L$3<$D5+Настройки!$B$7),0,MAX(0,$E5-MAX(0,SUMIFS(Тех_Движение!$G$2:$G$5111,Тех_Движение!$D$2:$D$5111,$C5,Тех_Движение!$B$2:$B$5111,"<="&L$3)-$F5))) | M5: =IF(OR($B5="",M$3<$D5+Настройки!$B$7),0,MAX(0,$E5-MAX(0,SUMIFS(Тех_Движение!$G$2:$G$5111,Тех_Движение!$D$2:$D$5111,$C5,Тех_Движение!$B$2:$B$5111,"<="&M$3)-$F5))) | N5: =IF(OR($B5="",N$3<$D5+Настройки!$B$7),0,MAX(0,$E5-MAX(0,SUMIFS(Тех_Движение!$G$2:$G$5111,Тех_Движение!$D$2:$D$5111,$C5,Тех_Движение!$B$2:$B$5111,"<="&N$3)-$F5))) | O5: =IF(OR($B5="",O$3<$D5+Настройки!$B$7),0,MAX(0,$E5-MAX(0,SUMIFS(Тех_Движение!$G$2:$G$5111,Тех_Движение!$D$2:$D$5111,$C5,Тех_Движение!$B$2:$B$5111,"<="&O$3)-$F5))) | P5: =IF(OR($B5="",P$3<$D5+Настройки!$B$7),0,MAX(0,$E5-MAX(0,SUMIFS(Тех_Движение!$G$2:$G$5111,Тех_Движение!$D$2:$D$5111,$C5,Тех_Движение!$B$2:$B$5111,"<="&P$3)-$F5))) | Q5: =IF(OR($B5="",Q$3<$D5+Настройки!$B$7),0,MAX(0,$E5-MAX(0,SUMIFS(Тех_Движение!$G$2:$G$5111,Тех_Движение!$D$2:$D$5111,$C5,Тех_Движение!$B$2:$B$5111,"<="&Q$3)-$F5))) | R5: =IF($B5="","",SUM($K5:$Q5)) | S5: =IF($B5="","",VLOOKUP($C5,Настройки!$A$11:$L$17,9,FALSE)) | T5: =IF($B5="","",$R5*$S5)
A6: =Тех_Движение!$A$3 | B6: =IF(Тех_Движение!$F$3>0,Тех_Движение!$I$3,"") | C6: =IF($B6="","",Тех_Движение!$D$3) | D6: =IF($B6="","",Тех_Движение!$B$3) | E6: =IF($B6="","",Тех_Движение!$F$3) | F6: =IF($B6="","",SUMIFS($E$5:$E5,$C$5:$C5,$C6)) | G6: =IF($B6="","",MAX(0,$E6-MAX(0,SUMIFS(Тех_Движение!$G$2:$G$5111,Тех_Движение!$D$2:$D$5111,$C6,Тех_Движение!$B$2:$B$5111,"<="&Настройки!$B$5-1)-$F6))) | H6: =IF($B6="","",IF(AND($D6>=Настройки!$B$5,$D6<=Настройки!$B$6),$E6,0)) | I6: =IF($B6="","",$G6+$H6-$J6) | J6: =IF($B6="","",MAX(0,$E6-MAX(0,SUMIFS(Тех_Движение!$G$2:$G$5111,Тех_Движение!$D$2:$D$5111,$C6,Тех_Движение!$B$2:$B$5111,"<="&Настройки!$B$6)-$F6))) | K6: =IF(OR($B6="",K$3<$D6+Настройки!$B$7),0,MAX(0,$E6-MAX(0,SUMIFS(Тех_Движение!$G$2:$G$5111,Тех_Движение!$D$2:$D$5111,$C6,Тех_Движение!$B$2:$B$5111,"<="&K$3)-$F6))) | L6: =IF(OR($B6="",L$3<$D6+Настройки!$B$7),0,MAX(0,$E6-MAX(0,SUMIFS(Тех_Движение!$G$2:$G$5111,Тех_Движение!$D$2:$D$5111,$C6,Тех_Движение!$B$2:$B$5111,"<="&L$3)-$F6))) | M6: =IF(OR($B6="",M$3<$D6+Настройки!$B$7),0,MAX(0,$E6-MAX(0,SUMIFS(Тех_Движение!$G$2:$G$5111,Тех_Движение!$D$2:$D$5111,$C6,Тех_Движение!$B$2:$B$5111,"<="&M$3)-$F6))) | N6: =IF(OR($B6="",N$3<$D6+Настройки!$B$7),0,MAX(0,$E6-MAX(0,SUMIFS(Тех_Движение!$G$2:$G$5111,Тех_Движение!$D$2:$D$5111,$C6,Тех_Движение!$B$2:$B$5111,"<="&N$3)-$F6))) | O6: =IF(OR($B6="",O$3<$D6+Настройки!$B$7),0,MAX(0,$E6-MAX(0,SUMIFS(Тех_Движение!$G$2:$G$5111,Тех_Движение!$D$2:$D$5111,$C6,Тех_Движение!$B$2:$B$5111,"<="&O$3)-$F6))) | P6: =IF(OR($B6="",P$3<$D6+Настройки!$B$7),0,MAX(0,$E6-MAX(0,SUMIFS(Тех_Движение!$G$2:$G$5111,Тех_Движение!$D$2:$D$5111,$C6,Тех_Движение!$B$2:$B$5111,"<="&P$3)-$F6))) | Q6: =IF(OR($B6="",Q$3<$D6+Настройки!$B$7),0,MAX(0,$E6-MAX(0,SUMIFS(Тех_Движение!$G$2:$G$5111,Тех_Движение!$D$2:$D$5111,$C6,Тех_Движение!$B$2:$B$5111,"<="&Q$3)-$F6))) | R6: =IF($B6="","",SUM($K6:$Q6)) | S6: =IF($B6="","",VLOOKUP($C6,Настройки!$A$11:$L$17,9,FALSE)) | T6: =IF($B6="","",$R6*$S6)
A7: =Тех_Движение!$A$4 | B7: =IF(Тех_Движение!$F$4>0,Тех_Движение!$I$4,"") | C7: =IF($B7="","",Тех_Движение!$D$4) | D7: =IF($B7="","",Тех_Движение!$B$4) | E7: =IF($B7="","",Тех_Движение!$F$4) | F7: =IF($B7="","",SUMIFS($E$5:$E6,$C$5:$C6,$C7)) | G7: =IF($B7="","",MAX(0,$E7-MAX(0,SUMIFS(Тех_Движение!$G$2:$G$5111,Тех_Движение!$D$2:$D$5111,$C7,Тех_Движение!$B$2:$B$5111,"<="&Настройки!$B$5-1)-$F7))) | H7: =IF($B7="","",IF(AND($D7>=Настройки!$B$5,$D7<=Настройки!$B$6),$E7,0)) | I7: =IF($B7="","",$G7+$H7-$J7) | J7: =IF($B7="","",MAX(0,$E7-MAX(0,SUMIFS(Тех_Движение!$G$2:$G$5111,Тех_Движение!$D$2:$D$5111,$C7,Тех_Движение!$B$2:$B$5111,"<="&Настройки!$B$6)-$F7))) | K7: =IF(OR($B7="",K$3<$D7+Настройки!$B$7),0,MAX(0,$E7-MAX(0,SUMIFS(Тех_Движение!$G$2:$G$5111,Тех_Движение!$D$2:$D$5111,$C7,Тех_Движение!$B$2:$B$5111,"<="&K$3)-$F7))) | L7: =IF(OR($B7="",L$3<$D7+Настройки!$B$7),0,MAX(0,$E7-MAX(0,SUMIFS(Тех_Движение!$G$2:$G$5111,Тех_Движение!$D$2:$D$5111,$C7,Тех_Движение!$B$2:$B$5111,"<="&L$3)-$F7))) | M7: =IF(OR($B7="",M$3<$D7+Настройки!$B$7),0,MAX(0,$E7-MAX(0,SUMIFS(Тех_Движение!$G$2:$G$5111,Тех_Движение!$D$2:$D$5111,$C7,Тех_Движение!$B$2:$B$5111,"<="&M$3)-$F7))) | N7: =IF(OR($B7="",N$3<$D7+Настройки!$B$7),0,MAX(0,$E7-MAX(0,SUMIFS(Тех_Движение!$G$2:$G$5111,Тех_Движение!$D$2:$D$5111,$C7,Тех_Движение!$B$2:$B$5111,"<="&N$3)-$F7))) | O7: =IF(OR($B7="",O$3<$D7+Настройки!$B$7),0,MAX(0,$E7-MAX(0,SUMIFS(Тех_Движение!$G$2:$G$5111,Тех_Движение!$D$2:$D$5111,$C7,Тех_Движение!$B$2:$B$5111,"<="&O$3)-$F7))) | P7: =IF(OR($B7="",P$3<$D7+Настройки!$B$7),0,MAX(0,$E7-MAX(0,SUMIFS(Тех_Движение!$G$2:$G$5111,Тех_Движение!$D$2:$D$5111,$C7,Тех_Движение!$B$2:$B$5111,"<="&P$3)-$F7))) | Q7: =IF(OR($B7="",Q$3<$D7+Настройки!$B$7),0,MAX(0,$E7-MAX(0,SUMIFS(Тех_Движение!$G$2:$G$5111,Тех_Движение!$D$2:$D$5111,$C7,Тех_Движение!$B$2:$B$5111,"<="&Q$3)-$F7))) | R7: =IF($B7="","",SUM($K7:$Q7)) | S7: =IF($B7="","",VLOOKUP($C7,Настройки!$A$11:$L$17,9,FALSE)) | T7: =IF($B7="","",$R7*$S7)
A8: =Тех_Движение!$A$5 | B8: =IF(Тех_Движение!$F$5>0,Тех_Движение!$I$5,"") | C8: =IF($B8="","",Тех_Движение!$D$5) | D8: =IF($B8="","",Тех_Движение!$B$5) | E8: =IF($B8="","",Тех_Движение!$F$5) | F8: =IF($B8="","",SUMIFS($E$5:$E7,$C$5:$C7,$C8)) | G8: =IF($B8="","",MAX(0,$E8-MAX(0,SUMIFS(Тех_Движение!$G$2:$G$5111,Тех_Движение!$D$2:$D$5111,$C8,Тех_Движение!$B$2:$B$5111,"<="&Настройки!$B$5-1)-$F8))) | H8: =IF($B8="","",IF(AND($D8>=Настройки!$B$5,$D8<=Настройки!$B$6),$E8,0)) | I8: =IF($B8="","",$G8+$H8-$J8) | J8: =IF($B8="","",MAX(0,$E8-MAX(0,SUMIFS(Тех_Движение!$G$2:$G$5111,Тех_Движение!$D$2:$D$5111,$C8,Тех_Движение!$B$2:$B$5111,"<="&Настройки!$B$6)-$F8))) | K8: =IF(OR($B8="",K$3<$D8+Настройки!$B$7),0,MAX(0,$E8-MAX(0,SUMIFS(Тех_Движение!$G$2:$G$5111,Тех_Движение!$D$2:$D$5111,$C8,Тех_Движение!$B$2:$B$5111,"<="&K$3)-$F8))) | L8: =IF(OR($B8="",L$3<$D8+Настройки!$B$7),0,MAX(0,$E8-MAX(0,SUMIFS(Тех_Движение!$G$2:$G$5111,Тех_Движение!$D$2:$D$5111,$C8,Тех_Движение!$B$2:$B$5111,"<="&L$3)-$F8))) | M8: =IF(OR($B8="",M$3<$D8+Настройки!$B$7),0,MAX(0,$E8-MAX(0,SUMIFS(Тех_Движение!$G$2:$G$5111,Тех_Движение!$D$2:$D$5111,$C8,Тех_Движение!$B$2:$B$5111,"<="&M$3)-$F8))) | N8: =IF(OR($B8="",N$3<$D8+Настройки!$B$7),0,MAX(0,$E8-MAX(0,SUMIFS(Тех_Движение!$G$2:$G$5111,Тех_Движение!$D$2:$D$5111,$C8,Тех_Движение!$B$2:$B$5111,"<="&N$3)-$F8))) | O8: =IF(OR($B8="",O$3<$D8+Настройки!$B$7),0,MAX(0,$E8-MAX(0,SUMIFS(Тех_Движение!$G$2:$G$5111,Тех_Движение!$D$2:$D$5111,$C8,Тех_Движение!$B$2:$B$5111,"<="&O$3)-$F8))) | P8: =IF(OR($B8="",P$3<$D8+Настройки!$B$7),0,MAX(0,$E8-MAX(0,SUMIFS(Тех_Движение!$G$2:$G$5111,Тех_Движение!$D$2:$D$5111,$C8,Тех_Движение!$B$2:$B$5111,"<="&P$3)-$F8))) | Q8: =IF(OR($B8="",Q$3<$D8+Настройки!$B$7),0,MAX(0,$E8-MAX(0,SUMIFS(Тех_Движение!$G$2:$G$5111,Тех_Движение!$D$2:$D$5111,$C8,Тех_Движение!$B$2:$B$5111,"<="&Q$3)-$F8))) | R8: =IF($B8="","",SUM($K8:$Q8)) | S8: =IF($B8="","",VLOOKUP($C8,Настройки!$A$11:$L$17,9,FALSE)) | T8: =IF($B8="","",$R8*$S8)
A9: =Тех_Движение!$A$6 | B9: =IF(Тех_Движение!$F$6>0,Тех_Движение!$I$6,"") | C9: =IF($B9="","",Тех_Движение!$D$6) | D9: =IF($B9="","",Тех_Движение!$B$6) | E9: =IF($B9="","",Тех_Движение!$F$6) | F9: =IF($B9="","",SUMIFS($E$5:$E8,$C$5:$C8,$C9)) | G9: =IF($B9="","",MAX(0,$E9-MAX(0,SUMIFS(Тех_Движение!$G$2:$G$5111,Тех_Движение!$D$2:$D$5111,$C9,Тех_Движение!$B$2:$B$5111,"<="&Настройки!$B$5-1)-$F9))) | H9: =IF($B9="","",IF(AND($D9>=Настройки!$B$5,$D9<=Настройки!$B$6),$E9,0)) | I9: =IF($B9="","",$G9+$H9-$J9) | J9: =IF($B9="","",MAX(0,$E9-MAX(0,SUMIFS(Тех_Движение!$G$2:$G$5111,Тех_Движение!$D$2:$D$5111,$C9,Тех_Движение!$B$2:$B$5111,"<="&Настройки!$B$6)-$F9))) | K9: =IF(OR($B9="",K$3<$D9+Настройки!$B$7),0,MAX(0,$E9-MAX(0,SUMIFS(Тех_Движение!$G$2:$G$5111,Тех_Движение!$D$2:$D$5111,$C9,Тех_Движение!$B$2:$B$5111,"<="&K$3)-$F9))) | L9: =IF(OR($B9="",L$3<$D9+Настройки!$B$7),0,MAX(0,$E9-MAX(0,SUMIFS(Тех_Движение!$G$2:$G$5111,Тех_Движение!$D$2:$D$5111,$C9,Тех_Движение!$B$2:$B$5111,"<="&L$3)-$F9))) | M9: =IF(OR($B9="",M$3<$D9+Настройки!$B$7),0,MAX(0,$E9-MAX(0,SUMIFS(Тех_Движение!$G$2:$G$5111,Тех_Движение!$D$2:$D$5111,$C9,Тех_Движение!$B$2:$B$5111,"<="&M$3)-$F9))) | N9: =IF(OR($B9="",N$3<$D9+Настройки!$B$7),0,MAX(0,$E9-MAX(0,SUMIFS(Тех_Движение!$G$2:$G$5111,Тех_Движение!$D$2:$D$5111,$C9,Тех_Движение!$B$2:$B$5111,"<="&N$3)-$F9))) | O9: =IF(OR($B9="",O$3<$D9+Настройки!$B$7),0,MAX(0,$E9-MAX(0,SUMIFS(Тех_Движение!$G$2:$G$5111,Тех_Движение!$D$2:$D$5111,$C9,Тех_Движение!$B$2:$B$5111,"<="&O$3)-$F9))) | P9: =IF(OR($B9="",P$3<$D9+Настройки!$B$7),0,MAX(0,$E9-MAX(0,SUMIFS(Тех_Движение!$G$2:$G$5111,Тех_Движение!$D$2:$D$5111,$C9,Тех_Движение!$B$2:$B$5111,"<="&P$3)-$F9))) | Q9: =IF(OR($B9="",Q$3<$D9+Настройки!$B$7),0,MAX(0,$E9-MAX(0,SUMIFS(Тех_Движение!$G$2:$G$5111,Тех_Движение!$D$2:$D$5111,$C9,Тех_Движение!$B$2:$B$5111,"<="&Q$3)-$F9))) | R9: =IF($B9="","",SUM($K9:$Q9)) | S9: =IF($B9="","",VLOOKUP($C9,Настройки!$A$11:$L$17,9,FALSE)) | T9: =IF($B9="","",$R9*$S9)
A10: =Тех_Движение!$A$7 | B10: =IF(Тех_Движение!$F$7>0,Тех_Движение!$I$7,"") | C10: =IF($B10="","",Тех_Движение!$D$7) | D10: =IF($B10="","",Тех_Движение!$B$7) | E10: =IF($B10="","",Тех_Движение!$F$7) | F10: =IF($B10="","",SUMIFS($E$5:$E9,$C$5:$C9,$C10)) | G10: =IF($B10="","",MAX(0,$E10-MAX(0,SUMIFS(Тех_Движение!$G$2:$G$5111,Тех_Движение!$D$2:$D$5111,$C10,Тех_Движение!$B$2:$B$5111,"<="&Настройки!$B$5-1)-$F10))) | H10: =IF($B10="","",IF(AND($D10>=Настройки!$B$5,$D10<=Настройки!$B$6),$E10,0)) | I10: =IF($B10="","",$G10+$H10-$J10) | J10: =IF($B10="","",MAX(0,$E10-MAX(0,SUMIFS(Тех_Движение!$G$2:$G$5111,Тех_Движение!$D$2:$D$5111,$C10,Тех_Движение!$B$2:$B$5111,"<="&Настройки!$B$6)-$F10))) | K10: =IF(OR($B10="",K$3<$D10+Настройки!$B$7),0,MAX(0,$E10-MAX(0,SUMIFS(Тех_Движение!$G$2:$G$5111,Тех_Движение!$D$2:$D$5111,$C10,Тех_Движение!$B$2:$B$5111,"<="&K$3)-$F10))) | L10: =IF(OR($B10="",L$3<$D10+Настройки!$B$7),0,MAX(0,$E10-MAX(0,SUMIFS(Тех_Движение!$G$2:$G$5111,Тех_Движение!$D$2:$D$5111,$C10,Тех_Движение!$B$2:$B$5111,"<="&L$3)-$F10))) | M10: =IF(OR($B10="",M$3<$D10+Настройки!$B$7),0,MAX(0,$E10-MAX(0,SUMIFS(Тех_Движение!$G$2:$G$5111,Тех_Движение!$D$2:$D$5111,$C10,Тех_Движение!$B$2:$B$5111,"<="&M$3)-$F10))) | N10: =IF(OR($B10="",N$3<$D10+Настройки!$B$7),0,MAX(0,$E10-MAX(0,SUMIFS(Тех_Движение!$G$2:$G$5111,Тех_Движение!$D$2:$D$5111,$C10,Тех_Движение!$B$2:$B$5111,"<="&N$3)-$F10))) | O10: =IF(OR($B10="",O$3<$D10+Настройки!$B$7),0,MAX(0,$E10-MAX(0,SUMIFS(Тех_Движение!$G$2:$G$5111,Тех_Движение!$D$2:$D$5111,$C10,Тех_Движение!$B$2:$B$5111,"<="&O$3)-$F10))) | P10: =IF(OR($B10="",P$3<$D10+Настройки!$B$7),0,MAX(0,$E10-MAX(0,SUMIFS(Тех_Движение!$G$2:$G$5111,Тех_Движение!$D$2:$D$5111,$C10,Тех_Движение!$B$2:$B$5111,"<="&P$3)-$F10))) | Q10: =IF(OR($B10="",Q$3<$D10+Настройки!$B$7),0,MAX(0,$E10-MAX(0,SUMIFS(Тех_Движение!$G$2:$G$5111,Тех_Движение!$D$2:$D$5111,$C10,Тех_Движение!$B$2:$B$5111,"<="&Q$3)-$F10))) | R10: =IF($B10="","",SUM($K10:$Q10)) | S10: =IF($B10="","",VLOOKUP($C10,Настройки!$A$11:$L$17,9,FALSE)) | T10: =IF($B10="","",$R10*$S10)
A11: =Тех_Движение!$A$8 | B11: =IF(Тех_Движение!$F$8>0,Тех_Движение!$I$8,"") | C11: =IF($B11="","",Тех_Движение!$D$8) | D11: =IF($B11="","",Тех_Движение!$B$8) | E11: =IF($B11="","",Тех_Движение!$F$8) | F11: =IF($B11="","",SUMIFS($E$5:$E10,$C$5:$C10,$C11)) | G11: =IF($B11="","",MAX(0,$E11-MAX(0,SUMIFS(Тех_Движение!$G$2:$G$5111,Тех_Движение!$D$2:$D$5111,$C11,Тех_Движение!$B$2:$B$5111,"<="&Настройки!$B$5-1)-$F11))) | H11: =IF($B11="","",IF(AND($D11>=Настройки!$B$5,$D11<=Настройки!$B$6),$E11,0)) | I11: =IF($B11="","",$G11+$H11-$J11) | J11: =IF($B11="","",MAX(0,$E11-MAX(0,SUMIFS(Тех_Движение!$G$2:$G$5111,Тех_Движение!$D$2:$D$5111,$C11,Тех_Движение!$B$2:$B$5111,"<="&Настройки!$B$6)-$F11))) | K11: =IF(OR($B11="",K$3<$D11+Настройки!$B$7),0,MAX(0,$E11-MAX(0,SUMIFS(Тех_Движение!$G$2:$G$5111,Тех_Движение!$D$2:$D$5111,$C11,Тех_Движение!$B$2:$B$5111,"<="&K$3)-$F11))) | L11: =IF(OR($B11="",L$3<$D11+Настройки!$B$7),0,MAX(0,$E11-MAX(0,SUMIFS(Тех_Движение!$G$2:$G$5111,Тех_Движение!$D$2:$D$5111,$C11,Тех_Движение!$B$2:$B$5111,"<="&L$3)-$F11))) | M11: =IF(OR($B11="",M$3<$D11+Настройки!$B$7),0,MAX(0,$E11-MAX(0,SUMIFS(Тех_Движение!$G$2:$G$5111,Тех_Движение!$D$2:$D$5111,$C11,Тех_Движение!$B$2:$B$5111,"<="&M$3)-$F11))) | N11: =IF(OR($B11="",N$3<$D11+Настройки!$B$7),0,MAX(0,$E11-MAX(0,SUMIFS(Тех_Движение!$G$2:$G$5111,Тех_Движение!$D$2:$D$5111,$C11,Тех_Движение!$B$2:$B$5111,"<="&N$3)-$F11))) | O11: =IF(OR($B11="",O$3<$D11+Настройки!$B$7),0,MAX(0,$E11-MAX(0,SUMIFS(Тех_Движение!$G$2:$G$5111,Тех_Движение!$D$2:$D$5111,$C11,Тех_Движение!$B$2:$B$5111,"<="&O$3)-$F11))) | P11: =IF(OR($B11="",P$3<$D11+Настройки!$B$7),0,MAX(0,$E11-MAX(0,SUMIFS(Тех_Движение!$G$2:$G$5111,Тех_Движение!$D$2:$D$5111,$C11,Тех_Движение!$B$2:$B$5111,"<="&P$3)-$F11))) | Q11: =IF(OR($B11="",Q$3<$D11+Настройки!$B$7),0,MAX(0,$E11-MAX(0,SUMIFS(Тех_Движение!$G$2:$G$5111,Тех_Движение!$D$2:$D$5111,$C11,Тех_Движение!$B$2:$B$5111,"<="&Q$3)-$F11))) | R11: =IF($B11="","",SUM($K11:$Q11)) | S11: =IF($B11="","",VLOOKUP($C11,Настройки!$A$11:$L$17,9,FALSE)) | T11: =IF($B11="","",$R11*$S11)
A12: =Тех_Движение!$A$9 | B12: =IF(Тех_Движение!$F$9>0,Тех_Движение!$I$9,"") | C12: =IF($B12="","",Тех_Движение!$D$9) | D12: =IF($B12="","",Тех_Движение!$B$9) | E12: =IF($B12="","",Тех_Движение!$F$9) | F12: =IF($B12="","",SUMIFS($E$5:$E11,$C$5:$C11,$C12)) | G12: =IF($B12="","",MAX(0,$E12-MAX(0,SUMIFS(Тех_Движение!$G$2:$G$5111,Тех_Движение!$D$2:$D$5111,$C12,Тех_Движение!$B$2:$B$5111,"<="&Настройки!$B$5-1)-$F12))) | H12: =IF($B12="","",IF(AND($D12>=Настройки!$B$5,$D12<=Настройки!$B$6),$E12,0)) | I12: =IF($B12="","",$G12+$H12-$J12) | J12: =IF($B12="","",MAX(0,$E12-MAX(0,SUMIFS(Тех_Движение!$G$2:$G$5111,Тех_Движение!$D$2:$D$5111,$C12,Тех_Движение!$B$2:$B$5111,"<="&Настройки!$B$6)-$F12))) | K12: =IF(OR($B12="",K$3<$D12+Настройки!$B$7),0,MAX(0,$E12-MAX(0,SUMIFS(Тех_Движение!$G$2:$G$5111,Тех_Движение!$D$2:$D$5111,$C12,Тех_Движение!$B$2:$B$5111,"<="&K$3)-$F12))) | L12: =IF(OR($B12="",L$3<$D12+Настройки!$B$7),0,MAX(0,$E12-MAX(0,SUMIFS(Тех_Движение!$G$2:$G$5111,Тех_Движение!$D$2:$D$5111,$C12,Тех_Движение!$B$2:$B$5111,"<="&L$3)-$F12))) | M12: =IF(OR($B12="",M$3<$D12+Настройки!$B$7),0,MAX(0,$E12-MAX(0,SUMIFS(Тех_Движение!$G$2:$G$5111,Тех_Движение!$D$2:$D$5111,$C12,Тех_Движение!$B$2:$B$5111,"<="&M$3)-$F12))) | N12: =IF(OR($B12="",N$3<$D12+Настройки!$B$7),0,MAX(0,$E12-MAX(0,SUMIFS(Тех_Движение!$G$2:$G$5111,Тех_Движение!$D$2:$D$5111,$C12,Тех_Движение!$B$2:$B$5111,"<="&N$3)-$F12))) | O12: =IF(OR($B12="",O$3<$D12+Настройки!$B$7),0,MAX(0,$E12-MAX(0,SUMIFS(Тех_Движение!$G$2:$G$5111,Тех_Движение!$D$2:$D$5111,$C12,Тех_Движение!$B$2:$B$5111,"<="&O$3)-$F12))) | P12: =IF(OR($B12="",P$3<$D12+Настройки!$B$7),0,MAX(0,$E12-MAX(0,SUMIFS(Тех_Движение!$G$2:$G$5111,Тех_Движение!$D$2:$D$5111,$C12,Тех_Движение!$B$2:$B$5111,"<="&P$3)-$F12))) | Q12: =IF(OR($B12="",Q$3<$D12+Настройки!$B$7),0,MAX(0,$E12-MAX(0,SUMIFS(Тех_Движение!$G$2:$G$5111,Тех_Движение!$D$2:$D$5111,$C12,Тех_Движение!$B$2:$B$5111,"<="&Q$3)-$F12))) | R12: =IF($B12="","",SUM($K12:$Q12)) | S12: =IF($B12="","",VLOOKUP($C12,Настройки!$A$11:$L$17,9,FALSE)) | T12: =IF($B12="","",$R12*$S12)
A13: =Тех_Движение!$A$10 | B13: =IF(Тех_Движение!$F$10>0,Тех_Движение!$I$10,"") | C13: =IF($B13="","",Тех_Движение!$D$10) | D13: =IF($B13="","",Тех_Движение!$B$10) | E13: =IF($B13="","",Тех_Движение!$F$10) | F13: =IF($B13="","",SUMIFS($E$5:$E12,$C$5:$C12,$C13)) | G13: =IF($B13="","",MAX(0,$E13-MAX(0,SUMIFS(Тех_Движение!$G$2:$G$5111,Тех_Движение!$D$2:$D$5111,$C13,Тех_Движение!$B$2:$B$5111,"<="&Настройки!$B$5-1)-$F13))) | H13: =IF($B13="","",IF(AND($D13>=Настройки!$B$5,$D13<=Настройки!$B$6),$E13,0)) | I13: =IF($B13="","",$G13+$H13-$J13) | J13: =IF($B13="","",MAX(0,$E13-MAX(0,SUMIFS(Тех_Движение!$G$2:$G$5111,Тех_Движение!$D$2:$D$5111,$C13,Тех_Движение!$B$2:$B$5111,"<="&Настройки!$B$6)-$F13))) | K13: =IF(OR($B13="",K$3<$D13+Настройки!$B$7),0,MAX(0,$E13-MAX(0,SUMIFS(Тех_Движение!$G$2:$G$5111,Тех_Движение!$D$2:$D$5111,$C13,Тех_Движение!$B$2:$B$5111,"<="&K$3)-$F13))) | L13: =IF(OR($B13="",L$3<$D13+Настройки!$B$7),0,MAX(0,$E13-MAX(0,SUMIFS(Тех_Движение!$G$2:$G$5111,Тех_Движение!$D$2:$D$5111,$C13,Тех_Движение!$B$2:$B$5111,"<="&L$3)-$F13))) | M13: =IF(OR($B13="",M$3<$D13+Настройки!$B$7),0,MAX(0,$E13-MAX(0,SUMIFS(Тех_Движение!$G$2:$G$5111,Тех_Движение!$D$2:$D$5111,$C13,Тех_Движение!$B$2:$B$5111,"<="&M$3)-$F13))) | N13: =IF(OR($B13="",N$3<$D13+Настройки!$B$7),0,MAX(0,$E13-MAX(0,SUMIFS(Тех_Движение!$G$2:$G$5111,Тех_Движение!$D$2:$D$5111,$C13,Тех_Движение!$B$2:$B$5111,"<="&N$3)-$F13))) | O13: =IF(OR($B13="",O$3<$D13+Настройки!$B$7),0,MAX(0,$E13-MAX(0,SUMIFS(Тех_Движение!$G$2:$G$5111,Тех_Движение!$D$2:$D$5111,$C13,Тех_Движение!$B$2:$B$5111,"<="&O$3)-$F13))) | P13: =IF(OR($B13="",P$3<$D13+Настройки!$B$7),0,MAX(0,$E13-MAX(0,SUMIFS(Тех_Движение!$G$2:$G$5111,Тех_Движение!$D$2:$D$5111,$C13,Тех_Движение!$B$2:$B$5111,"<="&P$3)-$F13))) | Q13: =IF(OR($B13="",Q$3<$D13+Настройки!$B$7),0,MAX(0,$E13-MAX(0,SUMIFS(Тех_Движение!$G$2:$G$5111,Тех_Движение!$D$2:$D$5111,$C13,Тех_Движение!$B$2:$B$5111,"<="&Q$3)-$F13))) | R13: =IF($B13="","",SUM($K13:$Q13)) | S13: =IF($B13="","",VLOOKUP($C13,Настройки!$A$11:$L$17,9,FALSE)) | T13: =IF($B13="","",$R13*$S13)
A14: =Тех_Движение!$A$11 | B14: =IF(Тех_Движение!$F$11>0,Тех_Движение!$I$11,"") | C14: =IF($B14="","",Тех_Движение!$D$11) | D14: =IF($B14="","",Тех_Движение!$B$11) | E14: =IF($B14="","",Тех_Движение!$F$11) | F14: =IF($B14="","",SUMIFS($E$5:$E13,$C$5:$C13,$C14)) | G14: =IF($B14="","",MAX(0,$E14-MAX(0,SUMIFS(Тех_Движение!$G$2:$G$5111,Тех_Движение!$D$2:$D$5111,$C14,Тех_Движение!$B$2:$B$5111,"<="&Настройки!$B$5-1)-$F14))) | H14: =IF($B14="","",IF(AND($D14>=Настройки!$B$5,$D14<=Настройки!$B$6),$E14,0)) | I14: =IF($B14="","",$G14+$H14-$J14) | J14: =IF($B14="","",MAX(0,$E14-MAX(0,SUMIFS(Тех_Движение!$G$2:$G$5111,Тех_Движение!$D$2:$D$5111,$C14,Тех_Движение!$B$2:$B$5111,"<="&Настройки!$B$6)-$F14))) | K14: =IF(OR($B14="",K$3<$D14+Настройки!$B$7),0,MAX(0,$E14-MAX(0,SUMIFS(Тех_Движение!$G$2:$G$5111,Тех_Движение!$D$2:$D$5111,$C14,Тех_Движение!$B$2:$B$5111,"<="&K$3)-$F14))) | L14: =IF(OR($B14="",L$3<$D14+Настройки!$B$7),0,MAX(0,$E14-MAX(0,SUMIFS(Тех_Движение!$G$2:$G$5111,Тех_Движение!$D$2:$D$5111,$C14,Тех_Движение!$B$2:$B$5111,"<="&L$3)-$F14))) | M14: =IF(OR($B14="",M$3<$D14+Настройки!$B$7),0,MAX(0,$E14-MAX(0,SUMIFS(Тех_Движение!$G$2:$G$5111,Тех_Движение!$D$2:$D$5111,$C14,Тех_Движение!$B$2:$B$5111,"<="&M$3)-$F14))) | N14: =IF(OR($B14="",N$3<$D14+Настройки!$B$7),0,MAX(0,$E14-MAX(0,SUMIFS(Тех_Движение!$G$2:$G$5111,Тех_Движение!$D$2:$D$5111,$C14,Тех_Движение!$B$2:$B$5111,"<="&N$3)-$F14))) | O14: =IF(OR($B14="",O$3<$D14+Настройки!$B$7),0,MAX(0,$E14-MAX(0,SUMIFS(Тех_Движение!$G$2:$G$5111,Тех_Движение!$D$2:$D$5111,$C14,Тех_Движение!$B$2:$B$5111,"<="&O$3)-$F14))) | P14: =IF(OR($B14="",P$3<$D14+Настройки!$B$7),0,MAX(0,$E14-MAX(0,SUMIFS(Тех_Движение!$G$2:$G$5111,Тех_Движение!$D$2:$D$5111,$C14,Тех_Движение!$B$2:$B$5111,"<="&P$3)-$F14))) | Q14: =IF(OR($B14="",Q$3<$D14+Настройки!$B$7),0,MAX(0,$E14-MAX(0,SUMIFS(Тех_Движение!$G$2:$G$5111,Тех_Движение!$D$2:$D$5111,$C14,Тех_Движение!$B$2:$B$5111,"<="&Q$3)-$F14))) | R14: =IF($B14="","",SUM($K14:$Q14)) | S14: =IF($B14="","",VLOOKUP($C14,Настройки!$A$11:$L$17,9,FALSE)) | T14: =IF($B14="","",$R14*$S14)
A15: =Тех_Движение!$A$12 | B15: =IF(Тех_Движение!$F$12>0,Тех_Движение!$I$12,"") | C15: =IF($B15="","",Тех_Движение!$D$12) | D15: =IF($B15="","",Тех_Движение!$B$12) | E15: =IF($B15="","",Тех_Движение!$F$12) | F15: =IF($B15="","",SUMIFS($E$5:$E14,$C$5:$C14,$C15)) | G15: =IF($B15="","",MAX(0,$E15-MAX(0,SUMIFS(Тех_Движение!$G$2:$G$5111,Тех_Движение!$D$2:$D$5111,$C15,Тех_Движение!$B$2:$B$5111,"<="&Настройки!$B$5-1)-$F15))) | H15: =IF($B15="","",IF(AND($D15>=Настройки!$B$5,$D15<=Настройки!$B$6),$E15,0)) | I15: =IF($B15="","",$G15+$H15-$J15) | J15: =IF($B15="","",MAX(0,$E15-MAX(0,SUMIFS(Тех_Движение!$G$2:$G$5111,Тех_Движение!$D$2:$D$5111,$C15,Тех_Движение!$B$2:$B$5111,"<="&Настройки!$B$6)-$F15))) | K15: =IF(OR($B15="",K$3<$D15+Настройки!$B$7),0,MAX(0,$E15-MAX(0,SUMIFS(Тех_Движение!$G$2:$G$5111,Тех_Движение!$D$2:$D$5111,$C15,Тех_Движение!$B$2:$B$5111,"<="&K$3)-$F15))) | L15: =IF(OR($B15="",L$3<$D15+Настройки!$B$7),0,MAX(0,$E15-MAX(0,SUMIFS(Тех_Движение!$G$2:$G$5111,Тех_Движение!$D$2:$D$5111,$C15,Тех_Движение!$B$2:$B$5111,"<="&L$3)-$F15))) | M15: =IF(OR($B15="",M$3<$D15+Настройки!$B$7),0,MAX(0,$E15-MAX(0,SUMIFS(Тех_Движение!$G$2:$G$5111,Тех_Движение!$D$2:$D$5111,$C15,Тех_Движение!$B$2:$B$5111,"<="&M$3)-$F15))) | N15: =IF(OR($B15="",N$3<$D15+Настройки!$B$7),0,MAX(0,$E15-MAX(0,SUMIFS(Тех_Движение!$G$2:$G$5111,Тех_Движение!$D$2:$D$5111,$C15,Тех_Движение!$B$2:$B$5111,"<="&N$3)-$F15))) | O15: =IF(OR($B15="",O$3<$D15+Настройки!$B$7),0,MAX(0,$E15-MAX(0,SUMIFS(Тех_Движение!$G$2:$G$5111,Тех_Движение!$D$2:$D$5111,$C15,Тех_Движение!$B$2:$B$5111,"<="&O$3)-$F15))) | P15: =IF(OR($B15="",P$3<$D15+Настройки!$B$7),0,MAX(0,$E15-MAX(0,SUMIFS(Тех_Движение!$G$2:$G$5111,Тех_Движение!$D$2:$D$5111,$C15,Тех_Движение!$B$2:$B$5111,"<="&P$3)-$F15))) | Q15: =IF(OR($B15="",Q$3<$D15+Настройки!$B$7),0,MAX(0,$E15-MAX(0,SUMIFS(Тех_Движение!$G$2:$G$5111,Тех_Движение!$D$2:$D$5111,$C15,Тех_Движение!$B$2:$B$5111,"<="&Q$3)-$F15))) | R15: =IF($B15="","",SUM($K15:$Q15)) | S15: =IF($B15="","",VLOOKUP($C15,Настройки!$A$11:$L$17,9,FALSE)) | T15: =IF($B15="","",$R15*$S15)
A16: =Тех_Движение!$A$13 | B16: =IF(Тех_Движение!$F$13>0,Тех_Движение!$I$13,"") | C16: =IF($B16="","",Тех_Движение!$D$13) | D16: =IF($B16="","",Тех_Движение!$B$13) | E16: =IF($B16="","",Тех_Движение!$F$13) | F16: =IF($B16="","",SUMIFS($E$5:$E15,$C$5:$C15,$C16)) | G16: =IF($B16="","",MAX(0,$E16-MAX(0,SUMIFS(Тех_Движение!$G$2:$G$5111,Тех_Движение!$D$2:$D$5111,$C16,Тех_Движение!$B$2:$B$5111,"<="&Настройки!$B$5-1)-$F16))) | H16: =IF($B16="","",IF(AND($D16>=Настройки!$B$5,$D16<=Настройки!$B$6),$E16,0)) | I16: =IF($B16="","",$G16+$H16-$J16) | J16: =IF($B16="","",MAX(0,$E16-MAX(0,SUMIFS(Тех_Движение!$G$2:$G$5111,Тех_Движение!$D$2:$D$5111,$C16,Тех_Движение!$B$2:$B$5111,"<="&Настройки!$B$6)-$F16))) | K16: =IF(OR($B16="",K$3<$D16+Настройки!$B$7),0,MAX(0,$E16-MAX(0,SUMIFS(Тех_Движение!$G$2:$G$5111,Тех_Движение!$D$2:$D$5111,$C16,Тех_Движение!$B$2:$B$5111,"<="&K$3)-$F16))) | L16: =IF(OR($B16="",L$3<$D16+Настройки!$B$7),0,MAX(0,$E16-MAX(0,SUMIFS(Тех_Движение!$G$2:$G$5111,Тех_Движение!$D$2:$D$5111,$C16,Тех_Движение!$B$2:$B$5111,"<="&L$3)-$F16))) | M16: =IF(OR($B16="",M$3<$D16+Настройки!$B$7),0,MAX(0,$E16-MAX(0,SUMIFS(Тех_Движение!$G$2:$G$5111,Тех_Движение!$D$2:$D$5111,$C16,Тех_Движение!$B$2:$B$5111,"<="&M$3)-$F16))) | N16: =IF(OR($B16="",N$3<$D16+Настройки!$B$7),0,MAX(0,$E16-MAX(0,SUMIFS(Тех_Движение!$G$2:$G$5111,Тех_Движение!$D$2:$D$5111,$C16,Тех_Движение!$B$2:$B$5111,"<="&N$3)-$F16))) | O16: =IF(OR($B16="",O$3<$D16+Настройки!$B$7),0,MAX(0,$E16-MAX(0,SUMIFS(Тех_Движение!$G$2:$G$5111,Тех_Движение!$D$2:$D$5111,$C16,Тех_Движение!$B$2:$B$5111,"<="&O$3)-$F16))) | P16: =IF(OR($B16="",P$3<$D16+Настройки!$B$7),0,MAX(0,$E16-MAX(0,SUMIFS(Тех_Движение!$G$2:$G$5111,Тех_Движение!$D$2:$D$5111,$C16,Тех_Движение!$B$2:$B$5111,"<="&P$3)-$F16))) | Q16: =IF(OR($B16="",Q$3<$D16+Настройки!$B$7),0,MAX(0,$E16-MAX(0,SUMIFS(Тех_Движение!$G$2:$G$5111,Тех_Движение!$D$2:$D$5111,$C16,Тех_Движение!$B$2:$B$5111,"<="&Q$3)-$F16))) | R16: =IF($B16="","",SUM($K16:$Q16)) | S16: =IF($B16="","",VLOOKUP($C16,Настройки!$A$11:$L$17,9,FALSE)) | T16: =IF($B16="","",$R16*$S16)
A17: =Тех_Движение!$A$14 | B17: =IF(Тех_Движение!$F$14>0,Тех_Движение!$I$14,"") | C17: =IF($B17="","",Тех_Движение!$D$14) | D17: =IF($B17="","",Тех_Движение!$B$14) | E17: =IF($B17="","",Тех_Движение!$F$14) | F17: =IF($B17="","",SUMIFS($E$5:$E16,$C$5:$C16,$C17)) | G17: =IF($B17="","",MAX(0,$E17-MAX(0,SUMIFS(Тех_Движение!$G$2:$G$5111,Тех_Движение!$D$2:$D$5111,$C17,Тех_Движение!$B$2:$B$5111,"<="&Настройки!$B$5-1)-$F17))) | H17: =IF($B17="","",IF(AND($D17>=Настройки!$B$5,$D17<=Настройки!$B$6),$E17,0)) | I17: =IF($B17="","",$G17+$H17-$J17) | J17: =IF($B17="","",MAX(0,$E17-MAX(0,SUMIFS(Тех_Движение!$G$2:$G$5111,Тех_Движение!$D$2:$D$5111,$C17,Тех_Движение!$B$2:$B$5111,"<="&Настройки!$B$6)-$F17))) | K17: =IF(OR($B17="",K$3<$D17+Настройки!$B$7),0,MAX(0,$E17-MAX(0,SUMIFS(Тех_Движение!$G$2:$G$5111,Тех_Движение!$D$2:$D$5111,$C17,Тех_Движение!$B$2:$B$5111,"<="&K$3)-$F17))) | L17: =IF(OR($B17="",L$3<$D17+Настройки!$B$7),0,MAX(0,$E17-MAX(0,SUMIFS(Тех_Движение!$G$2:$G$5111,Тех_Движение!$D$2:$D$5111,$C17,Тех_Движение!$B$2:$B$5111,"<="&L$3)-$F17))) | M17: =IF(OR($B17="",M$3<$D17+Настройки!$B$7),0,MAX(0,$E17-MAX(0,SUMIFS(Тех_Движение!$G$2:$G$5111,Тех_Движение!$D$2:$D$5111,$C17,Тех_Движение!$B$2:$B$5111,"<="&M$3)-$F17))) | N17: =IF(OR($B17="",N$3<$D17+Настройки!$B$7),0,MAX(0,$E17-MAX(0,SUMIFS(Тех_Движение!$G$2:$G$5111,Тех_Движение!$D$2:$D$5111,$C17,Тех_Движение!$B$2:$B$5111,"<="&N$3)-$F17))) | O17: =IF(OR($B17="",O$3<$D17+Настройки!$B$7),0,MAX(0,$E17-MAX(0,SUMIFS(Тех_Движение!$G$2:$G$5111,Тех_Движение!$D$2:$D$5111,$C17,Тех_Движение!$B$2:$B$5111,"<="&O$3)-$F17))) | P17: =IF(OR($B17="",P$3<$D17+Настройки!$B$7),0,MAX(0,$E17-MAX(0,SUMIFS(Тех_Движение!$G$2:$G$5111,Тех_Движение!$D$2:$D$5111,$C17,Тех_Движение!$B$2:$B$5111,"<="&P$3)-$F17))) | Q17: =IF(OR($B17="",Q$3<$D17+Настройки!$B$7),0,MAX(0,$E17-MAX(0,SUMIFS(Тех_Движение!$G$2:$G$5111,Тех_Движение!$D$2:$D$5111,$C17,Тех_Движение!$B$2:$B$5111,"<="&Q$3)-$F17))) | R17: =IF($B17="","",SUM($K17:$Q17)) | S17: =IF($B17="","",VLOOKUP($C17,Настройки!$A$11:$L$17,9,FALSE)) | T17: =IF($B17="","",$R17*$S17)
