Workbook

Sheet Настройки
A1: PVZ.FLOW | Настройки
A4: Начало расчёта | B4: 46286
A5: Окончание расчёта | B5: 46287
A6: Бесплатных дней | B6: 5
A9: Товар | B9: Приёмка селлер | C9: Бренд селлер | D9: Упаковка селлер | E9: Сборка селлер | F9: Хранение | G9: Приёмка персонал | H9: Бренд персонал | I9: Упаковка персонал | J9: Сборка персонал
A10: АК-10 | B10: 10 | C10: 10 | D10: 20 | E10: 10 | F10: 0.35714286 | G10: 1 | H10: 3 | I10: 6 | J10: 3
A11: АК-15 | B11: 10 | C11: 10 | D11: 20 | E11: 10 | F11: 0.35714286 | G11: 1 | H11: 3 | I11: 6 | J11: 3
A12: Г 3500 | B12: 10 | C12: 15 | D12: 35 | E12: 25 | F12: 5 | G12: 3 | H12: 6 | I12: 16 | J12: 12
A13: Г 1800 | B13: 10 | C13: 10 | D13: 30 | E13: 15 | F13: 5 | G13: 2 | H13: 4 | I13: 12 | J13: 7
A14: Г 800 | B14: 10 | C14: 10 | D14: 30 | E14: 15 | F14: 5 | G14: 2 | H14: 4 | I14: 12 | J14: 7
A15: Ми-К | B15: 10 | C15: 0 | D15: 20 | E15: 10 | F15: 1.3636364 | G15: 1 | H15: 2 | I15: 5 | J15: 5
A16: Ми-П | B16: 10 | C16: 0 | D16: 20 | E16: 10 | F16: 0.16304348 | G16: 1 | H16: 2 | I16: 5 | J16: 5

Sheet Широкая_таблица
A1: PVZ.FLOW | Канон движения
A2: =Настройки!B4 -> 46286 | C2: =Настройки!B5 -> 46287
A4: Дата | B4: День | C4: Оператор | D4: АК-10 | K4: АК-15 | R4: Г 3500 | Y4: Г 1800 | AF4: Г 800 | AM4: Ми-К | AT4: Ми-П
D5: Было | E5: Приход | F5: Возврат | G5: Корректировка | H5: Инв. корр. | I5: Расход | J5: Остаток | K5: Было | L5: Приход | M5: Возврат | N5: Корректировка | O5: Инв. корр. | P5: Расход | Q5: Остаток | R5: Было | S5: Приход | T5: Возврат | U5: Корректировка | V5: Инв. корр. | W5: Расход | X5: Остаток | Y5: Было | Z5: Приход | AA5: Возврат | AB5: Корректировка | AC5: Инв. корр. | AD5: Расход | AE5: Остаток | AF5: Было | AG5: Приход | AH5: Возврат | AI5: Корректировка | AJ5: Инв. корр. | AK5: Расход | AL5: Остаток | AM5: Было | AN5: Приход | AO5: Возврат | AP5: Корректировка | AQ5: Инв. корр. | AR5: Расход | AS5: Остаток | AT5: Было | AU5: Приход | AV5: Возврат | AW5: Корректировка | AX5: Инв. корр. | AY5: Расход | AZ5: Остаток
A6: 46272 | B6: ПН | C6: Пузанов Д.В. | D6: 18 | E6: 0 | F6: 0 | G6: 13 | H6: 0 | I6: 0 | J6: =D6+E6+F6+G6+H6-I6 -> 31 | K6: 24 | L6: 0 | M6: 0 | N6: 14 | O6: 0 | P6: 0 | Q6: =K6+L6+M6+N6+O6-P6 -> 38 | R6: 3 | S6: 0 | T6: 0 | U6: 1 | V6: 0 | W6: 0 | X6: =R6+S6+T6+U6+V6-W6 -> 4 | Y6: 66 | Z6: 3 | AA6: 0 | AB6: -22 | AC6: 0 | AD6: 3 | AE6: =Y6+Z6+AA6+AB6+AC6-AD6 -> 44 | AF6: 39 | AG6: 2 | AH6: 0 | AI6: -1 | AJ6: 0 | AK6: 2 | AL6: =AF6+AG6+AH6+AI6+AJ6-AK6 -> 38 | AM6: 17 | AN6: 1 | AO6: 0 | AP6: -12 | AQ6: 0 | AR6: 1 | AS6: =AM6+AN6+AO6+AP6+AQ6-AR6 -> 5 | AT6: 0 | AU6: 0 | AV6: 0 | AW6: 0 | AX6: 0 | AY6: 0 | AZ6: =AT6+AU6+AV6+AW6+AX6-AY6 -> 0
A7: 46273 | B7: ВТ | C7: Завалишин Д.Л. | D7: =J6 -> 31 | E7: 0 | F7: 0 | G7: 0 | H7: 0 | I7: 1 | J7: =D7+E7+F7+G7+H7-I7 -> 30 | K7: =Q6 -> 38 | L7: 0 | M7: 0 | N7: 0 | O7: 0 | P7: 1 | Q7: =K7+L7+M7+N7+O7-P7 -> 37 | R7: =X6 -> 4 | S7: 0 | T7: 0 | U7: 0 | V7: 0 | W7: 0 | X7: =R7+S7+T7+U7+V7-W7 -> 4 | Y7: =AE6 -> 44 | Z7: 0 | AA7: 0 | AB7: 0 | AC7: 0 | AD7: 11 | AE7: =Y7+Z7+AA7+AB7+AC7-AD7 -> 33 | AF7: =AL6 -> 38 | AG7: 0 | AH7: 0 | AI7: 0 | AJ7: 0 | AK7: 3 | AL7: =AF7+AG7+AH7+AI7+AJ7-AK7 -> 35 | AM7: =AS6 -> 5 | AN7: 0 | AO7: 0 | AP7: 0 | AQ7: 0 | AR7: 0 | AS7: =AM7+AN7+AO7+AP7+AQ7-AR7 -> 5 | AT7: =AZ6 -> 0 | AU7: 0 | AV7: 0 | AW7: 0 | AX7: 0 | AY7: 0 | AZ7: =AT7+AU7+AV7+AW7+AX7-AY7 -> 0
A8: 46274 | B8: СР | C8: Завалишин Д.Л. | D8: =J7 -> 30 | E8: 0 | F8: 0 | G8: 0 | H8: 0 | I8: 0 | J8: =D8+E8+F8+G8+H8-I8 -> 30 | K8: =Q7 -> 37 | L8: 0 | M8: 0 | N8: 0 | O8: 0 | P8: 1 | Q8: =K8+L8+M8+N8+O8-P8 -> 36 | R8: =X7 -> 4 | S8: 0 | T8: 0 | U8: 0 | V8: 0 | W8: 0 | X8: =R8+S8+T8+U8+V8-W8 -> 4 | Y8: =AE7 -> 33 | Z8: 0 | AA8: 0 | AB8: 0 | AC8: 0 | AD8: 8 | AE8: =Y8+Z8+AA8+AB8+AC8-AD8 -> 25 | AF8: =AL7 -> 35 | AG8: 0 | AH8: 0 | AI8: 0 | AJ8: 0 | AK8: 5 | AL8: =AF8+AG8+AH8+AI8+AJ8-AK8 -> 30 | AM8: =AS7 -> 5 | AN8: 0 | AO8: 0 | AP8: 0 | AQ8: 0 | AR8: 1 | AS8: =AM8+AN8+AO8+AP8+AQ8-AR8 -> 4 | AT8: =AZ7 -> 0 | AU8: 0 | AV8: 0 | AW8: 0 | AX8: 0 | AY8: 0 | AZ8: =AT8+AU8+AV8+AW8+AX8-AY8 -> 0
A9: 46275 | B9: ЧТ | C9: Завалишин Д.Л. | D9: =J8 -> 30 | E9: 0 | F9: 0 | G9: 0 | H9: 0 | I9: 0 | J9: =D9+E9+F9+G9+H9-I9 -> 30 | K9: =Q8 -> 36 | L9: 10 | M9: 0 | N9: 0 | O9: 0 | P9: 0 | Q9: =K9+L9+M9+N9+O9-P9 -> 46 | R9: =X8 -> 4 | S9: 2 | T9: 0 | U9: 0 | V9: 0 | W9: 0 | X9: =R9+S9+T9+U9+V9-W9 -> 6 | Y9: =AE8 -> 25 | Z9: 129 | AA9: 0 | AB9: 0 | AC9: 0 | AD9: 10 | AE9: =Y9+Z9+AA9+AB9+AC9-AD9 -> 144 | AF9: =AL8 -> 30 | AG9: 0 | AH9: 0 | AI9: 0 | AJ9: 0 | AK9: 8 | AL9: =AF9+AG9+AH9+AI9+AJ9-AK9 -> 22 | AM9: =AS8 -> 4 | AN9: 10 | AO9: 0 | AP9: 0 | AQ9: 0 | AR9: 1 | AS9: =AM9+AN9+AO9+AP9+AQ9-AR9 -> 13 | AT9: =AZ8 -> 0 | AU9: 27 | AV9: 0 | AW9: -2 | AX9: 0 | AY9: 1 | AZ9: =AT9+AU9+AV9+AW9+AX9-AY9 -> 24
A10: 46276 | B10: ПТ | C10: Пузанов Д.В. | D10: =J9 -> 30 | E10: 0 | F10: 0 | G10: 0 | H10: 0 | I10: 5 | J10: =D10+E10+F10+G10+H10-I10 -> 25 | K10: =Q9 -> 46 | L10: 0 | M10: 0 | N10: 0 | O10: 0 | P10: 2 | Q10: =K10+L10+M10+N10+O10-P10 -> 44 | R10: =X9 -> 6 | S10: 0 | T10: 0 | U10: 0 | V10: 0 | W10: 2 | X10: =R10+S10+T10+U10+V10-W10 -> 4 | Y10: =AE9 -> 144 | Z10: 0 | AA10: 0 | AB10: 0 | AC10: 0 | AD10: 12 | AE10: =Y10+Z10+AA10+AB10+AC10-AD10 -> 132 | AF10: =AL9 -> 22 | AG10: 64 | AH10: 0 | AI10: 0 | AJ10: 0 | AK10: 4 | AL10: =AF10+AG10+AH10+AI10+AJ10-AK10 -> 82 | AM10: =AS9 -> 13 | AN10: 0 | AO10: 0 | AP10: 0 | AQ10: 0 | AR10: 6 | AS10: =AM10+AN10+AO10+AP10+AQ10-AR10 -> 7 | AT10: =AZ9 -> 24 | AU10: 0 | AV10: 0 | AW10: 0 | AX10: 0 | AY10: 1 | AZ10: =AT10+AU10+AV10+AW10+AX10-AY10 -> 23
A11: 46277 | B11: СБ | C11: Завалишин Д.Л. | D11: =J10 -> 25 | E11: 0 | F11: 0 | G11: 0 | H11: 0 | I11: 1 | J11: =D11+E11+F11+G11+H11-I11 -> 24 | K11: =Q10 -> 44 | L11: 0 | M11: 0 | N11: 0 | O11: 0 | P11: 2 | Q11: =K11+L11+M11+N11+O11-P11 -> 42 | R11: =X10 -> 4 | S11: 0 | T11: 0 | U11: 0 | V11: 0 | W11: 1 | X11: =R11+S11+T11+U11+V11-W11 -> 3 | Y11: =AE10 -> 132 | Z11: 0 | AA11: 0 | AB11: 0 | AC11: 0 | AD11: 5 | AE11: =Y11+Z11+AA11+AB11+AC11-AD11 -> 127 | AF11: =AL10 -> 82 | AG11: 0 | AH11: 0 | AI11: 0 | AJ11: 0 | AK11: 8 | AL11: =AF11+AG11+AH11+AI11+AJ11-AK11 -> 74 | AM11: =AS10 -> 7 | AN11: 0 | AO11: 0 | AP11: 0 | AQ11: 0 | AR11: 4 | AS11: =AM11+AN11+AO11+AP11+AQ11-AR11 -> 3 | AT11: =AZ10 -> 23 | AU11: 0 | AV11: 0 | AW11: 0 | AX11: 0 | AY11: 1 | AZ11: =AT11+AU11+AV11+AW11+AX11-AY11 -> 22
A12: 46278 | B12: ВС | C12: Завалишин Д.Л. | D12: =J11 -> 24 | E12: 0 | F12: 0 | G12: 0 | H12: 0 | I12: 4 | J12: =D12+E12+F12+G12+H12-I12 -> 20 | K12: =Q11 -> 42 | L12: 0 | M12: 0 | N12: 0 | O12: 0 | P12: 2 | Q12: =K12+L12+M12+N12+O12-P12 -> 40 | R12: =X11 -> 3 | S12: 2 | T12: 0 | U12: 0 | V12: 0 | W12: 2 | X12: =R12+S12+T12+U12+V12-W12 -> 3 | Y12: =AE11 -> 127 | Z12: 0 | AA12: 0 | AB12: 0 | AC12: 0 | AD12: 2 | AE12: =Y12+Z12+AA12+AB12+AC12-AD12 -> 125 | AF12: =AL11 -> 74 | AG12: 0 | AH12: 0 | AI12: 0 | AJ12: 0 | AK12: 4 | AL12: =AF12+AG12+AH12+AI12+AJ12-AK12 -> 70 | AM12: =AS11 -> 3 | AN12: 0 | AO12: 0 | AP12: 0 | AQ12: 0 | AR12: 0 | AS12: =AM12+AN12+AO12+AP12+AQ12-AR12 -> 3 | AT12: =AZ11 -> 22 | AU12: 0 | AV12: 0 | AW12: 0 | AX12: 0 | AY12: 0 | AZ12: =AT12+AU12+AV12+AW12+AX12-AY12 -> 22
A13: 46279 | B13: ПН | C13: Пузанов Д.В. | D13: =J12 -> 20 | E13: 15 | F13: 0 | G13: 0 | H13: 0 | I13: 2 | J13: =D13+E13+F13+G13+H13-I13 -> 33 | K13: =Q12 -> 40 | L13: 0 | M13: 0 | N13: 0 | O13: 0 | P13: 2 | Q13: =K13+L13+M13+N13+O13-P13 -> 38 | R13: =X12 -> 3 | S13: 14 | T13: 0 | U13: 0 | V13: 0 | W13: 0 | X13: =R13+S13+T13+U13+V13-W13 -> 17 | Y13: =AE12 -> 125 | Z13: 0 | AA13: 0 | AB13: 0 | AC13: 0 | AD13: 8 | AE13: =Y13+Z13+AA13+AB13+AC13-AD13 -> 117 | AF13: =AL12 -> 70 | AG13: 0 | AH13: 0 | AI13: 0 | AJ13: 0 | AK13: 9 | AL13: =AF13+AG13+AH13+AI13+AJ13-AK13 -> 61 | AM13: =AS12 -> 3 | AN13: 0 | AO13: 1 | AP13: 0 | AQ13: 0 | AR13: 4 | AS13: =AM13+AN13+AO13+AP13+AQ13-AR13 -> 0 | AT13: =AZ12 -> 22 | AU13: 0 | AV13: 0 | AW13: 0 | AX13: 0 | AY13: 1 | AZ13: =AT13+AU13+AV13+AW13+AX13-AY13 -> 21
A14: 46280 | B14: ВТ | C14: Завалишин Д.Л. | D14: =J13 -> 33 | E14: 0 | F14: 0 | G14: 0 | H14: 0 | I14: 0 | J14: =D14+E14+F14+G14+H14-I14 -> 33 | K14: =Q13 -> 38 | L14: 0 | M14: 0 | N14: 0 | O14: 0 | P14: 1 | Q14: =K14+L14+M14+N14+O14-P14 -> 37 | R14: =X13 -> 17 | S14: 0 | T14: 0 | U14: 0 | V14: 0 | W14: 1 | X14: =R14+S14+T14+U14+V14-W14 -> 16 | Y14: =AE13 -> 117 | Z14: 0 | AA14: 0 | AB14: 0 | AC14: 0 | AD14: 11 | AE14: =Y14+Z14+AA14+AB14+AC14-AD14 -> 106 | AF14: =AL13 -> 61 | AG14: 0 | AH14: 0 | AI14: 0 | AJ14: 0 | AK14: 7 | AL14: =AF14+AG14+AH14+AI14+AJ14-AK14 -> 54 | AM14: =AS13 -> 0 | AN14: 20 | AO14: 0 | AP14: 0 | AQ14: 0 | AR14: 4 | AS14: =AM14+AN14+AO14+AP14+AQ14-AR14 -> 16 | AT14: =AZ13 -> 21 | AU14: 0 | AV14: 0 | AW14: 0 | AX14: 0 | AY14: 1 | AZ14: =AT14+AU14+AV14+AW14+AX14-AY14 -> 20
A15: 46281 | B15: СР | C15: Завалишин Д.Л. | D15: =J14 -> 33 | E15: 0 | F15: 0 | G15: 0 | H15: 0 | I15: 1 | J15: =D15+E15+F15+G15+H15-I15 -> 32 | K15: =Q14 -> 37 | L15: 0 | M15: 0 | N15: 0 | O15: 0 | P15: 3 | Q15: =K15+L15+M15+N15+O15-P15 -> 34 | R15: =X14 -> 16 | S15: 0 | T15: 0 | U15: 0 | V15: 0 | W15: 0 | X15: =R15+S15+T15+U15+V15-W15 -> 16 | Y15: =AE14 -> 106 | Z15: 0 | AA15: 0 | AB15: 0 | AC15: 0 | AD15: 13 | AE15: =Y15+Z15+AA15+AB15+AC15-AD15 -> 93 | AF15: =AL14 -> 54 | AG15: 0 | AH15: 0 | AI15: 0 | AJ15: 0 | AK15: 12 | AL15: =AF15+AG15+AH15+AI15+AJ15-AK15 -> 42 | AM15: =AS14 -> 16 | AN15: 0 | AO15: 0 | AP15: 0 | AQ15: 0 | AR15: 0 | AS15: =AM15+AN15+AO15+AP15+AQ15-AR15 -> 16 | AT15: =AZ14 -> 20 | AU15: 0 | AV15: 0 | AW15: 0 | AX15: 0 | AY15: 1 | AZ15: =AT15+AU15+AV15+AW15+AX15-AY15 -> 19
A16: 46282 | B16: ЧТ | C16: Завалишин Д.Л. | D16: =J15 -> 32 | E16: 0 | F16: 0 | G16: 0 | H16: 0 | I16: 1 | J16: =D16+E16+F16+G16+H16-I16 -> 31 | K16: =Q15 -> 34 | L16: 0 | M16: 0 | N16: 0 | O16: 0 | P16: 3 | Q16: =K16+L16+M16+N16+O16-P16 -> 31 | R16: =X15 -> 16 | S16: 0 | T16: 0 | U16: 0 | V16: 0 | W16: 0 | X16: =R16+S16+T16+U16+V16-W16 -> 16 | Y16: =AE15 -> 93 | Z16: 0 | AA16: 0 | AB16: 0 | AC16: 0 | AD16: 13 | AE16: =Y16+Z16+AA16+AB16+AC16-AD16 -> 80 | AF16: =AL15 -> 42 | AG16: 0 | AH16: 0 | AI16: 0 | AJ16: 0 | AK16: 3 | AL16: =AF16+AG16+AH16+AI16+AJ16-AK16 -> 39 | AM16: =AS15 -> 16 | AN16: 0 | AO16: 0 | AP16: 0 | AQ16: 0 | AR16: 1 | AS16: =AM16+AN16+AO16+AP16+AQ16-AR16 -> 15 | AT16: =AZ15 -> 19 | AU16: 0 | AV16: 0 | AW16: 0 | AX16: 0 | AY16: 2 | AZ16: =AT16+AU16+AV16+AW16+AX16-AY16 -> 17
A17: 46283 | B17: ПТ | C17: Пузанов Д.В. | D17: =J16 -> 31 | E17: 0 | F17: 0 | G17: 0 | H17: 0 | I17: 1 | J17: =D17+E17+F17+G17+H17-I17 -> 30 | K17: =Q16 -> 31 | L17: 0 | M17: 0 | N17: 0 | O17: 0 | P17: 1 | Q17: =K17+L17+M17+N17+O17-P17 -> 30 | R17: =X16 -> 16 | S17: 0 | T17: 0 | U17: 0 | V17: 0 | W17: 1 | X17: =R17+S17+T17+U17+V17-W17 -> 15 | Y17: =AE16 -> 80 | Z17: 0 | AA17: 0 | AB17: 0 | AC17: 0 | AD17: 13 | AE17: =Y17+Z17+AA17+AB17+AC17-AD17 -> 67 | AF17: =AL16 -> 39 | AG17: 0 | AH17: 0 | AI17: 0 | AJ17: 0 | AK17: 4 | AL17: =AF17+AG17+AH17+AI17+AJ17-AK17 -> 35 | AM17: =AS16 -> 15 | AN17: 0 | AO17: 0 | AP17: 0 | AQ17: 0 | AR17: 0 | AS17: =AM17+AN17+AO17+AP17+AQ17-AR17 -> 15 | AT17: =AZ16 -> 17 | AU17: 0 | AV17: 0 | AW17: 0 | AX17: 0 | AY17: 0 | AZ17: =AT17+AU17+AV17+AW17+AX17-AY17 -> 17
A18: 46284 | B18: СБ | C18: Завалишин Д.Л. | D18: =J17 -> 30 | E18: 0 | F18: 0 | G18: 0 | H18: 0 | I18: 0 | J18: =D18+E18+F18+G18+H18-I18 -> 30 | K18: =Q17 -> 30 | L18: 0 | M18: 0 | N18: 0 | O18: 0 | P18: 0 | Q18: =K18+L18+M18+N18+O18-P18 -> 30 | R18: =X17 -> 15 | S18: 0 | T18: 0 | U18: 0 | V18: 0 | W18: 0 | X18: =R18+S18+T18+U18+V18-W18 -> 15 | Y18: =AE17 -> 67 | Z18: 0 | AA18: 0 | AB18: 0 | AC18: 0 | AD18: 15 | AE18: =Y18+Z18+AA18+AB18+AC18-AD18 -> 52 | AF18: =AL17 -> 35 | AG18: 0 | AH18: 0 | AI18: 0 | AJ18: 0 | AK18: 7 | AL18: =AF18+AG18+AH18+AI18+AJ18-AK18 -> 28 | AM18: =AS17 -> 15 | AN18: 0 | AO18: 0 | AP18: 0 | AQ18: 0 | AR18: 0 | AS18: =AM18+AN18+AO18+AP18+AQ18-AR18 -> 15 | AT18: =AZ17 -> 17 | AU18: 0 | AV18: 0 | AW18: 0 | AX18: 0 | AY18: 0 | AZ18: =AT18+AU18+AV18+AW18+AX18-AY18 -> 17
... A21: 46287 | B21: ВТ | C21: Завалишин Д.Л. | D21: =J20 -> 26 | E21: 0 | F21: 0 | G21: 0 | H21: 0 | I21: 0 | J21: =D21+E21+F21+G21+H21-I21 -> 26 | K21: =Q20 -> 25 | L21: 0 | M21: 0 | N21: 0 | O21: 0 | P21: 0 | Q21: =K21+L21+M21+N21+O21-P21 -> 25 | R21: =X20 -> 13 | S21: 0 | T21: 0 | U21: 0 | V21: 0 | W21: 0 | X21: =R21+S21+T21+U21+V21-W21 -> 13 | Y21: =AE20 -> 25 | Z21: 0 | AA21: 0 | AB21: 0 | AC21: 0 | AD21: 0 | AE21: =Y21+Z21+AA21+AB21+AC21-AD21 -> 25 | AF21: =AL20 -> 15 | AG21: 0 | AH21: 0 | AI21: 0 | AJ21: 0 | AK21: 0 | AL21: =AF21+AG21+AH21+AI21+AJ21-AK21 -> 15 | AM21: =AS20 -> 8 | AN21: 0 | AO21: 0 | AP21: 0 | AQ21: 0 | AR21: 0 | AS21: =AM21+AN21+AO21+AP21+AQ21-AR21 -> 8 | AT21: =AZ20 -> 13 | AU21: 0 | AV21: 0 | AW21: 0 | AX21: 0 | AY21: 0 | AZ21: =AT21+AU21+AV21+AW21+AX21-AY21 -> 13
A22: 46288 | B22: СР | C22: Завалишин Д.Л. | D22: =J21 -> 26 | E22: 0 | F22: 0 | G22: 0 | H22: 0 | I22: 0 | J22: =D22+E22+F22+G22+H22-I22 -> 26 | K22: =Q21 -> 25 | Q22: =K22+L22+M22+N22+O22-P22 -> 25 | R22: =X21 -> 13 | X22: =R22+S22+T22+U22+V22-W22 -> 13 | Y22: =AE21 -> 25 | AE22: =Y22+Z22+AA22+AB22+AC22-AD22 -> 25 | AF22: =AL21 -> 15 | AL22: =AF22+AG22+AH22+AI22+AJ22-AK22 -> 15 | AM22: =AS21 -> 8 | AS22: =AM22+AN22+AO22+AP22+AQ22-AR22 -> 8 | AT22: =AZ21 -> 13 | AZ22: =AT22+AU22+AV22+AW22+AX22-AY22 -> 13
A23: 46289 | B23: ЧТ | C23: Завалишин Д.Л. | D23: =J22 -> 26 | E23: 0 | F23: 0 | G23: 0 | H23: 0 | I23: 0 | J23: =D23+E23+F23+G23+H23-I23 -> 26 | K23: =Q22 -> 25 | Q23: =K23+L23+M23+N23+O23-P23 -> 25 | R23: =X22 -> 13 | X23: =R23+S23+T23+U23+V23-W23 -> 13 | Y23: =AE22 -> 25 | AE23: =Y23+Z23+AA23+AB23+AC23-AD23 -> 25 | AF23: =AL22 -> 15 | AL23: =AF23+AG23+AH23+AI23+AJ23-AK23 -> 15 | AM23: =AS22 -> 8 | AS23: =AM23+AN23+AO23+AP23+AQ23-AR23 -> 8 | AT23: =AZ22 -> 13 | AZ23: =AT23+AU23+AV23+AW23+AX23-AY23 -> 13
A24: 46290 | B24: ПТ | C24: Пузанов Д.В. | D24: =J23 -> 26 | E24: 0 | F24: 0 | G24: 0 | H24: 0 | I24: 0 | J24: =D24+E24+F24+G24+H24-I24 -> 26 | K24: =Q23 -> 25 | Q24: =K24+L24+M24+N24+O24-P24 -> 25 | R24: =X23 -> 13 | X24: =R24+S24+T24+U24+V24-W24 -> 13 | Y24: =AE23 -> 25 | AE24: =Y24+Z24+AA24+AB24+AC24-AD24 -> 25 | AF24: =AL23 -> 15 | AL24: =AF24+AG24+AH24+AI24+AJ24-AK24 -> 15 | AM24: =AS23 -> 8 | AS24: =AM24+AN24+AO24+AP24+AQ24-AR24 -> 8 | AT24: =AZ23 -> 13 | AZ24: =AT24+AU24+AV24+AW24+AX24-AY24 -> 13
A25: 46291 | B25: СБ | C25: Завалишин Д.Л. | D25: =J24 -> 26 | E25: 0 | F25: 0 | G25: 0 | H25: 0 | I25: 0 | J25: =D25+E25+F25+G25+H25-I25 -> 26 | K25: =Q24 -> 25 | Q25: =K25+L25+M25+N25+O25-P25 -> 25 | R25: =X24 -> 13 | X25: =R25+S25+T25+U25+V25-W25 -> 13 | Y25: =AE24 -> 25 | AE25: =Y25+Z25+AA25+AB25+AC25-AD25 -> 25 | AF25: =AL24 -> 15 | AL25: =AF25+AG25+AH25+AI25+AJ25-AK25 -> 15 | AM25: =AS24 -> 8 | AS25: =AM25+AN25+AO25+AP25+AQ25-AR25 -> 8 | AT25: =AZ24 -> 13 | AZ25: =AT25+AU25+AV25+AW25+AX25-AY25 -> 13
A26: 46292 | B26: ВС | C26: Завалишин Д.Л. | D26: =J25 -> 26 | E26: 0 | F26: 0 | G26: 0 | H26: 0 | I26: 0 | J26: =D26+E26+F26+G26+H26-I26 -> 26 | K26: =Q25 -> 25 | Q26: =K26+L26+M26+N26+O26-P26 -> 25 | R26: =X25 -> 13 | X26: =R26+S26+T26+U26+V26-W26 -> 13 | Y26: =AE25 -> 25 | AE26: =Y26+Z26+AA26+AB26+AC26-AD26 -> 25 | AF26: =AL25 -> 15 | AL26: =AF26+AG26+AH26+AI26+AJ26-AK26 -> 15 | AM26: =AS25 -> 8 | AS26: =AM26+AN26+AO26+AP26+AQ26-AR26 -> 8 | AT26: =AZ25 -> 13 | AZ26: =AT26+AU26+AV26+AW26+AX26-AY26 -> 13
A27: 46293 | B27: ПН | C27: Пузанов Д.В. | D27: =J26 -> 26 | E27: 0 | F27: 0 | G27: 0 | H27: 0 | I27: 0 | J27: =D27+E27+F27+G27+H27-I27 -> 26 | K27: =Q26 -> 25 | Q27: =K27+L27+M27+N27+O27-P27 -> 25 | R27: =X26 -> 13 | X27: =R27+S27+T27+U27+V27-W27 -> 13 | Y27: =AE26 -> 25 | AE27: =Y27+Z27+AA27+AB27+AC27-AD27 -> 25 | AF27: =AL26 -> 15 | AL27: =AF27+AG27+AH27+AI27+AJ27-AK27 -> 15 | AM27: =AS26 -> 8 | AS27: =AM27+AN27+AO27+AP27+AQ27-AR27 -> 8 | AT27: =AZ26 -> 13 | AZ27: =AT27+AU27+AV27+AW27+AX27-AY27 -> 13
A28: 46294 | B28: ВТ | C28: Завалишин Д.Л. | D28: =J27 -> 26 | E28: 0 | F28: 0 | G28: 0 | H28: 0 | I28: 0 | J28: =D28+E28+F28+G28+H28-I28 -> 26 | K28: =Q27 -> 25 | Q28: =K28+L28+M28+N28+O28-P28 -> 25 | R28: =X27 -> 13 | X28: =R28+S28+T28+U28+V28-W28 -> 13 | Y28: =AE27 -> 25 | AE28: =Y28+Z28+AA28+AB28+AC28-AD28 -> 25 | AF28: =AL27 -> 15 | AL28: =AF28+AG28+AH28+AI28+AJ28-AK28 -> 15 | AM28: =AS27 -> 8 | AS28: =AM28+AN28+AO28+AP28+AQ28-AR28 -> 8 | AT28: =AZ27 -> 13 | AZ28: =AT28+AU28+AV28+AW28+AX28-AY28 -> 13
A29: 46295 | B29: СР | C29: Завалишин Д.Л. | D29: =J28 -> 26 | E29: 0 | F29: 0 | G29: 0 | H29: 0 | I29: 0 | J29: =D29+E29+F29+G29+H29-I29 -> 26 | K29: =Q28 -> 25 | Q29: =K29+L29+M29+N29+O29-P29 -> 25 | R29: =X28 -> 13 | X29: =R29+S29+T29+U29+V29-W29 -> 13 | Y29: =AE28 -> 25 | AE29: =Y29+Z29+AA29+AB29+AC29-AD29 -> 25 | AF29: =AL28 -> 15 | AL29: =AF29+AG29+AH29+AI29+AJ29-AK29 -> 15 | AM29: =AS28 -> 8 | AS29: =AM29+AN29+AO29+AP29+AQ29-AR29 -> 8 | AT29: =AZ28 -> 13 | AZ29: =AT29+AU29+AV29+AW29+AX29-AY29 -> 13
A30: 46296 | B30: ЧТ | C30: Завалишин Д.Л. | D30: =J29 -> 26 | E30: 0 | F30: 0 | G30: 0 | H30: 0 | I30: 0 | J30: =D30+E30+F30+G30+H30-I30 -> 26 | K30: =Q29 -> 25 | Q30: =K30+L30+M30+N30+O30-P30 -> 25 | R30: =X29 -> 13 | X30: =R30+S30+T30+U30+V30-W30 -> 13 | Y30: =AE29 -> 25 | AE30: =Y30+Z30+AA30+AB30+AC30-AD30 -> 25 | AF30: =AL29 -> 15 | AL30: =AF30+AG30+AH30+AI30+AJ30-AK30 -> 15 | AM30: =AS29 -> 8 | AS30: =AM30+AN30+AO30+AP30+AQ30-AR30 -> 8 | AT30: =AZ29 -> 13 | AZ30: =AT30+AU30+AV30+AW30+AX30-AY30 -> 13
A31: 46297 | B31: ПТ | C31: Пузанов Д.В. | D31: =J30 -> 26 | E31: 0 | F31: 0 | G31: 0 | H31: 0 | I31: 0 | J31: =D31+E31+F31+G31+H31-I31 -> 26 | K31: =Q30 -> 25 | Q31: =K31+L31+M31+N31+O31-P31 -> 25 | R31: =X30 -> 13 | X31: =R31+S31+T31+U31+V31-W31 -> 13 | Y31: =AE30 -> 25 | AE31: =Y31+Z31+AA31+AB31+AC31-AD31 -> 25 | AF31: =AL30 -> 15 | AL31: =AF31+AG31+AH31+AI31+AJ31-AK31 -> 15 | AM31: =AS30 -> 8 | AS31: =AM31+AN31+AO31+AP31+AQ31-AR31 -> 8 | AT31: =AZ30 -> 13 | AZ31: =AT31+AU31+AV31+AW31+AX31-AY31 -> 13
A32: 46298 | B32: СБ | C32: Завалишин Д.Л. | D32: =J31 -> 26 | E32: 0 | F32: 0 | G32: 0 | H32: 0 | I32: 0 | J32: =D32+E32+F32+G32+H32-I32 -> 26 | K32: =Q31 -> 25 | Q32: =K32+L32+M32+N32+O32-P32 -> 25 | R32: =X31 -> 13 | X32: =R32+S32+T32+U32+V32-W32 -> 13 | Y32: =AE31 -> 25 | AE32: =Y32+Z32+AA32+AB32+AC32-AD32 -> 25 | AF32: =AL31 -> 15 | AL32: =AF32+AG32+AH32+AI32+AJ32-AK32 -> 15 | AM32: =AS31 -> 8 | AS32: =AM32+AN32+AO32+AP32+AQ32-AR32 -> 8 | AT32: =AZ31 -> 13 | AZ32: =AT32+AU32+AV32+AW32+AX32-AY32 -> 13
A33: 46299 | B33: ВС | C33: Завалишин Д.Л. | D33: =J32 -> 26 | E33: 0 | F33: 0 | G33: 0 | H33: 0 | I33: 0 | J33: =D33+E33+F33+G33+H33-I33 -> 26 | K33: =Q32 -> 25 | Q33: =K33+L33+M33+N33+O33-P33 -> 25 | R33: =X32 -> 13 | X33: =R33+S33+T33+U33+V33-W33 -> 13 | Y33: =AE32 -> 25 | AE33: =Y33+Z33+AA33+AB33+AC33-AD33 -> 25 | AF33: =AL32 -> 15 | AL33: =AF33+AG33+AH33+AI33+AJ33-AK33 -> 15 | AM33: =AS32 -> 8 | AS33: =AM33+AN33+AO33+AP33+AQ33-AR33 -> 8 | AT33: =AZ32 -> 13 | AZ33: =AT33+AU33+AV33+AW33+AX33-AY33 -> 13
A34: 46300 | B34: ПН | D34: =J33 -> 26 | E34: 0 | F34: 0 | G34: 0 | H34: 0 | I34: 0 | J34: =D34+E34+F34+G34+H34-I34 -> 26 | K34: =Q33 -> 25 | Q34: =K34+L34+M34+N34+O34-P34 -> 25 | R34: =X33 -> 13 | X34: =R34+S34+T34+U34+V34-W34 -> 13 | Y34: =AE33 -> 25 | AE34: =Y34+Z34+AA34+AB34+AC34-AD34 -> 25 | AF34: =AL33 -> 15 | AL34: =AF34+AG34+AH34+AI34+AJ34-AK34 -> 15 | AM34: =AS33 -> 8 | AS34: =AM34+AN34+AO34+AP34+AQ34-AR34 -> 8 | AT34: =AZ33 -> 13 | AZ34: =AT34+AU34+AV34+AW34+AX34-AY34 -> 13
A35: 46301 | B35: ВТ | D35: =J34 -> 26 | E35: 0 | F35: 0 | G35: 0 | H35: 0 | I35: 0 | J35: =D35+E35+F35+G35+H35-I35 -> 26 | K35: =Q34 -> 25 | Q35: =K35+L35+M35+N35+O35-P35 -> 25 | R35: =X34 -> 13 | X35: =R35+S35+T35+U35+V35-W35 -> 13 | Y35: =AE34 -> 25 | AE35: =Y35+Z35+AA35+AB35+AC35-AD35 -> 25 | AF35: =AL34 -> 15 | AL35: =AF35+AG35+AH35+AI35+AJ35-AK35 -> 15 | AM35: =AS34 -> 8 | AS35: =AM35+AN35+AO35+AP35+AQ35-AR35 -> 8 | AT35: =AZ34 -> 13 | AZ35: =AT35+AU35+AV35+AW35+AX35-AY35 -> 13
A36: 46302 | B36: СР | D36: =J35 -> 26 | E36: 0 | F36: 0 | G36: 0 | H36: 0 | I36: 0 | J36: =D36+E36+F36+G36+H36-I36 -> 26 | K36: =Q35 -> 25 | Q36: =K36+L36+M36+N36+O36-P36 -> 25 | R36: =X35 -> 13 | X36: =R36+S36+T36+U36+V36-W36 -> 13 | Y36: =AE35 -> 25 | AE36: =Y36+Z36+AA36+AB36+AC36-AD36 -> 25 | AF36: =AL35 -> 15 | AL36: =AF36+AG36+AH36+AI36+AJ36-AK36 -> 15 | AM36: =AS35 -> 8 | AS36: =AM36+AN36+AO36+AP36+AQ36-AR36 -> 8 | AT36: =AZ35 -> 13 | AZ36: =AT36+AU36+AV36+AW36+AX36-AY36 -> 13

Sheet Обработка
A1: PVZ.FLOW | Обработка товаров
A4: Дата | B4: Оператор | C4: Товар | D4: Было | E4: Приход | F4: Возврат | G4: Корректировки | H4: Расход | I4: Остаток
A5: =Широкая_таблица!$A$6 -> 46272 | B5: =Широкая_таблица!$C$6 -> Пузанов Д.В. | C5: =INDEX(Настройки!$A$10:$A$16,1) -> АК-10 | D5: =Широкая_таблица!$D$6 -> 18 | E5: =Широкая_таблица!$E$6 -> 0 | F5: =Широкая_таблица!$F$6 -> 0 | G5: =Широкая_таблица!$G$6+Широкая_таблица!$H$6 -> 13 | H5: =Широкая_таблица!$I$6 -> 0 | I5: =Широкая_таблица!$J$6 -> 31
A6: =Широкая_таблица!$A$6 -> 46272 | B6: =Широкая_таблица!$C$6 -> Пузанов Д.В. | C6: =INDEX(Настройки!$A$10:$A$16,2) -> АК-15 | D6: =Широкая_таблица!$K$6 -> 24 | E6: =Широкая_таблица!$L$6 -> 0 | F6: =Широкая_таблица!$M$6 -> 0 | G6: =Широкая_таблица!$N$6+Широкая_таблица!$O$6 -> 14 | H6: =Широкая_таблица!$P$6 -> 0 | I6: =Широкая_таблица!$Q$6 -> 38
A7: =Широкая_таблица!$A$6 -> 46272 | B7: =Широкая_таблица!$C$6 -> Пузанов Д.В. | C7: =INDEX(Настройки!$A$10:$A$16,3) -> Г 3500 | D7: =Широкая_таблица!$R$6 -> 3 | E7: =Широкая_таблица!$S$6 -> 0 | F7: =Широкая_таблица!$T$6 -> 0 | G7: =Широкая_таблица!$U$6+Широкая_таблица!$V$6 -> 1 | H7: =Широкая_таблица!$W$6 -> 0 | I7: =Широкая_таблица!$X$6 -> 4
A8: =Широкая_таблица!$A$6 -> 46272 | B8: =Широкая_таблица!$C$6 -> Пузанов Д.В. | C8: =INDEX(Настройки!$A$10:$A$16,4) -> Г 1800 | D8: =Широкая_таблица!$Y$6 -> 66 | E8: =Широкая_таблица!$Z$6 -> 3 | F8: =Широкая_таблица!$AA$6 -> 0 | G8: =Широкая_таблица!$AB$6+Широкая_таблица!$AC$6 -> -22 | H8: =Широкая_таблица!$AD$6 -> 3 | I8: =Широкая_таблица!$AE$6 -> 44
A9: =Широкая_таблица!$A$6 -> 46272 | B9: =Широкая_таблица!$C$6 -> Пузанов Д.В. | C9: =INDEX(Настройки!$A$10:$A$16,5) -> Г 800 | D9: =Широкая_таблица!$AF$6 -> 39 | E9: =Широкая_таблица!$AG$6 -> 2 | F9: =Широкая_таблица!$AH$6 -> 0 | G9: =Широкая_таблица!$AI$6+Широкая_таблица!$AJ$6 -> -1 | H9: =Широкая_таблица!$AK$6 -> 2 | I9: =Широкая_таблица!$AL$6 -> 38
A10: =Широкая_таблица!$A$6 -> 46272 | B10: =Широкая_таблица!$C$6 -> Пузанов Д.В. | C10: =INDEX(Настройки!$A$10:$A$16,6) -> Ми-К | D10: =Широкая_таблица!$AM$6 -> 17 | E10: =Широкая_таблица!$AN$6 -> 1 | F10: =Широкая_таблица!$AO$6 -> 0 | G10: =Широкая_таблица!$AP$6+Широкая_таблица!$AQ$6 -> -12 | H10: =Широкая_таблица!$AR$6 -> 1 | I10: =Широкая_таблица!$AS$6 -> 5
A11: =Широкая_таблица!$A$6 -> 46272 | B11: =Широкая_таблица!$C$6 -> Пузанов Д.В. | C11: =INDEX(Настройки!$A$10:$A$16,7) -> Ми-П | D11: =Широкая_таблица!$AT$6 -> 0 | E11: =Широкая_таблица!$AU$6 -> 0 | F11: =Широкая_таблица!$AV$6 -> 0 | G11: =Широкая_таблица!$AW$6+Широкая_таблица!$AX$6 -> 0 | H11: =Широкая_таблица!$AY$6 -> 0 | I11: =Широкая_таблица!$AZ$6 -> 0
A12: =Широкая_таблица!$A$7 -> 46273 | B12: =Широкая_таблица!$C$7 -> Завалишин Д.Л. | C12: =INDEX(Настройки!$A$10:$A$16,1) -> АК-10 | D12: =Широкая_таблица!$D$7 -> 31 | E12: =Широкая_таблица!$E$7 -> 0 | F12: =Широкая_таблица!$F$7 -> 0 | G12: =Широкая_таблица!$G$7+Широкая_таблица!$H$7 -> 0 | H12: =Широкая_таблица!$I$7 -> 1 | I12: =Широкая_таблица!$J$7 -> 30
A13: =Широкая_таблица!$A$7 -> 46273 | B13: =Широкая_таблица!$C$7 -> Завалишин Д.Л. | C13: =INDEX(Настройки!$A$10:$A$16,2) -> АК-15 | D13: =Широкая_таблица!$K$7 -> 38 | E13: =Широкая_таблица!$L$7 -> 0 | F13: =Широкая_таблица!$M$7 -> 0 | G13: =Широкая_таблица!$N$7+Широкая_таблица!$O$7 -> 0 | H13: =Широкая_таблица!$P$7 -> 1 | I13: =Широкая_таблица!$Q$7 -> 37
A14: =Широкая_таблица!$A$7 -> 46273 | B14: =Широкая_таблица!$C$7 -> Завалишин Д.Л. | C14: =INDEX(Настройки!$A$10:$A$16,3) -> Г 3500 | D14: =Широкая_таблица!$R$7 -> 4 | E14: =Широкая_таблица!$S$7 -> 0 | F14: =Широкая_таблица!$T$7 -> 0 | G14: =Широкая_таблица!$U$7+Широкая_таблица!$V$7 -> 0 | H14: =Широкая_таблица!$W$7 -> 0 | I14: =Широкая_таблица!$X$7 -> 4
A15: =Широкая_таблица!$A$7 -> 46273 | B15: =Широкая_таблица!$C$7 -> Завалишин Д.Л. | C15: =INDEX(Настройки!$A$10:$A$16,4) -> Г 1800 | D15: =Широкая_таблица!$Y$7 -> 44 | E15: =Широкая_таблица!$Z$7 -> 0 | F15: =Широкая_таблица!$AA$7 -> 0 | G15: =Широкая_таблица!$AB$7+Широкая_таблица!$AC$7 -> 0 | H15: =Широкая_таблица!$AD$7 -> 11 | I15: =Широкая_таблица!$AE$7 -> 33
A16: =Широкая_таблица!$A$7 -> 46273 | B16: =Широкая_таблица!$C$7 -> Завалишин Д.Л. | C16: =INDEX(Настройки!$A$10:$A$16,5) -> Г 800 | D16: =Широкая_таблица!$AF$7 -> 38 | E16: =Широкая_таблица!$AG$7 -> 0 | F16: =Широкая_таблица!$AH$7 -> 0 | G16: =Широкая_таблица!$AI$7+Широкая_таблица!$AJ$7 -> 0 | H16: =Широкая_таблица!$AK$7 -> 3 | I16: =Широкая_таблица!$AL$7 -> 35
A17: =Широкая_таблица!$A$7 -> 46273 | B17: =Широкая_таблица!$C$7 -> Завалишин Д.Л. | C17: =INDEX(Настройки!$A$10:$A$16,6) -> Ми-К | D17: =Широкая_таблица!$AM$7 -> 5 | E17: =Широкая_таблица!$AN$7 -> 0 | F17: =Широкая_таблица!$AO$7 -> 0 | G17: =Широкая_таблица!$AP$7+Широкая_таблица!$AQ$7 -> 0 | H17: =Широкая_таблица!$AR$7 -> 0 | I17: =Широкая_таблица!$AS$7 -> 5
A18: =Широкая_таблица!$A$7 -> 46273 | B18: =Широкая_таблица!$C$7 -> Завалишин Д.Л. | C18: =INDEX(Настройки!$A$10:$A$16,7) -> Ми-П | D18: =Широкая_таблица!$AT$7 -> 0 | E18: =Широкая_таблица!$AU$7 -> 0 | F18: =Широкая_таблица!$AV$7 -> 0 | G18: =Широкая_таблица!$AW$7+Широкая_таблица!$AX$7 -> 0 | H18: =Широкая_таблица!$AY$7 -> 0 | I18: =Широкая_таблица!$AZ$7 -> 0
A19: =Широкая_таблица!$A$8 -> 46274 | B19: =Широкая_таблица!$C$8 -> Завалишин Д.Л. | C19: =INDEX(Настройки!$A$10:$A$16,1) -> АК-10 | D19: =Широкая_таблица!$D$8 -> 30 | E19: =Широкая_таблица!$E$8 -> 0 | F19: =Широкая_таблица!$F$8 -> 0 | G19: =Широкая_таблица!$G$8+Широкая_таблица!$H$8 -> 0 | H19: =Широкая_таблица!$I$8 -> 0 | I19: =Широкая_таблица!$J$8 -> 30
A20: =Широкая_таблица!$A$8 -> 46274 | B20: =Широкая_таблица!$C$8 -> Завалишин Д.Л. | C20: =INDEX(Настройки!$A$10:$A$16,2) -> АК-15 | D20: =Широкая_таблица!$K$8 -> 37 | E20: =Широкая_таблица!$L$8 -> 0 | F20: =Широкая_таблица!$M$8 -> 0 | G20: =Широкая_таблица!$N$8+Широкая_таблица!$O$8 -> 0 | H20: =Широкая_таблица!$P$8 -> 1 | I20: =Широкая_таблица!$Q$8 -> 36
A21: =Широкая_таблица!$A$8 -> 46274 | B21: =Широкая_таблица!$C$8 -> Завалишин Д.Л. | C21: =INDEX(Настройки!$A$10:$A$16,3) -> Г 3500 | D21: =Широкая_таблица!$R$8 -> 4 | E21: =Широкая_таблица!$S$8 -> 0 | F21: =Широкая_таблица!$T$8 -> 0 | G21: =Широкая_таблица!$U$8+Широкая_таблица!$V$8 -> 0 | H21: =Широкая_таблица!$W$8 -> 0 | I21: =Широкая_таблица!$X$8 -> 4
A22: =Широкая_таблица!$A$8 -> 46274 | B22: =Широкая_таблица!$C$8 -> Завалишин Д.Л. | C22: =INDEX(Настройки!$A$10:$A$16,4) -> Г 1800 | D22: =Широкая_таблица!$Y$8 -> 33 | E22: =Широкая_таблица!$Z$8 -> 0 | F22: =Широкая_таблица!$AA$8 -> 0 | G22: =Широкая_таблица!$AB$8+Широкая_таблица!$AC$8 -> 0 | H22: =Широкая_таблица!$AD$8 -> 8 | I22: =Широкая_таблица!$AE$8 -> 25
A23: =Широкая_таблица!$A$8 -> 46274 | B23: =Широкая_таблица!$C$8 -> Завалишин Д.Л. | C23: =INDEX(Настройки!$A$10:$A$16,5) -> Г 800 | D23: =Широкая_таблица!$AF$8 -> 35 | E23: =Широкая_таблица!$AG$8 -> 0 | F23: =Широкая_таблица!$AH$8 -> 0 | G23: =Широкая_таблица!$AI$8+Широкая_таблица!$AJ$8 -> 0 | H23: =Широкая_таблица!$AK$8 -> 5 | I23: =Широкая_таблица!$AL$8 -> 30
A24: =Широкая_таблица!$A$8 -> 46274 | B24: =Широкая_таблица!$C$8 -> Завалишин Д.Л. | C24: =INDEX(Настройки!$A$10:$A$16,6) -> Ми-К | D24: =Широкая_таблица!$AM$8 -> 5 | E24: =Широкая_таблица!$AN$8 -> 0 | F24: =Широкая_таблица!$AO$8 -> 0 | G24: =Широкая_таблица!$AP$8+Широкая_таблица!$AQ$8 -> 0 | H24: =Широкая_таблица!$AR$8 -> 1 | I24: =Широкая_таблица!$AS$8 -> 4
A25: =Широкая_таблица!$A$8 -> 46274 | B25: =Широкая_таблица!$C$8 -> Завалишин Д.Л. | C25: =INDEX(Настройки!$A$10:$A$16,7) -> Ми-П | D25: =Широкая_таблица!$AT$8 -> 0 | E25: =Широкая_таблица!$AU$8 -> 0 | F25: =Широкая_таблица!$AV$8 -> 0 | G25: =Широкая_таблица!$AW$8+Широкая_таблица!$AX$8 -> 0 | H25: =Широкая_таблица!$AY$8 -> 0 | I25: =Широкая_таблица!$AZ$8 -> 0
A26: =Широкая_таблица!$A$9 -> 46275 | B26: =Широкая_таблица!$C$9 -> Завалишин Д.Л. | C26: =INDEX(Настройки!$A$10:$A$16,1) -> АК-10 | D26: =Широкая_таблица!$D$9 -> 30 | E26: =Широкая_таблица!$E$9 -> 0 | F26: =Широкая_таблица!$F$9 -> 0 | G26: =Широкая_таблица!$G$9+Широкая_таблица!$H$9 -> 0 | H26: =Широкая_таблица!$I$9 -> 0 | I26: =Широкая_таблица!$J$9 -> 30
A27: =Широкая_таблица!$A$9 -> 46275 | B27: =Широкая_таблица!$C$9 -> Завалишин Д.Л. | C27: =INDEX(Настройки!$A$10:$A$16,2) -> АК-15 | D27: =Широкая_таблица!$K$9 -> 36 | E27: =Широкая_таблица!$L$9 -> 10 | F27: =Широкая_таблица!$M$9 -> 0 | G27: =Широкая_таблица!$N$9+Широкая_таблица!$O$9 -> 0 | H27: =Широкая_таблица!$P$9 -> 0 | I27: =Широкая_таблица!$Q$9 -> 46
A28: =Широкая_таблица!$A$9 -> 46275 | B28: =Широкая_таблица!$C$9 -> Завалишин Д.Л. | C28: =INDEX(Настройки!$A$10:$A$16,3) -> Г 3500 | D28: =Широкая_таблица!$R$9 -> 4 | E28: =Широкая_таблица!$S$9 -> 2 | F28: =Широкая_таблица!$T$9 -> 0 | G28: =Широкая_таблица!$U$9+Широкая_таблица!$V$9 -> 0 | H28: =Широкая_таблица!$W$9 -> 0 | I28: =Широкая_таблица!$X$9 -> 6
A29: =Широкая_таблица!$A$9 -> 46275 | B29: =Широкая_таблица!$C$9 -> Завалишин Д.Л. | C29: =INDEX(Настройки!$A$10:$A$16,4) -> Г 1800 | D29: =Широкая_таблица!$Y$9 -> 25 | E29: =Широкая_таблица!$Z$9 -> 129 | F29: =Широкая_таблица!$AA$9 -> 0 | G29: =Широкая_таблица!$AB$9+Широкая_таблица!$AC$9 -> 0 | H29: =Широкая_таблица!$AD$9 -> 10 | I29: =Широкая_таблица!$AE$9 -> 144
A30: =Широкая_таблица!$A$9 -> 46275 | B30: =Широкая_таблица!$C$9 -> Завалишин Д.Л. | C30: =INDEX(Настройки!$A$10:$A$16,5) -> Г 800 | D30: =Широкая_таблица!$AF$9 -> 30 | E30: =Широкая_таблица!$AG$9 -> 0 | F30: =Широкая_таблица!$AH$9 -> 0 | G30: =Широкая_таблица!$AI$9+Широкая_таблица!$AJ$9 -> 0 | H30: =Широкая_таблица!$AK$9 -> 8 | I30: =Широкая_таблица!$AL$9 -> 22
A31: =Широкая_таблица!$A$9 -> 46275 | B31: =Широкая_таблица!$C$9 -> Завалишин Д.Л. | C31: =INDEX(Настройки!$A$10:$A$16,6) -> Ми-К | D31: =Широкая_таблица!$AM$9 -> 4 | E31: =Широкая_таблица!$AN$9 -> 10 | F31: =Широкая_таблица!$AO$9 -> 0 | G31: =Широкая_таблица!$AP$9+Широкая_таблица!$AQ$9 -> 0 | H31: =Широкая_таблица!$AR$9 -> 1 | I31: =Широкая_таблица!$AS$9 -> 13
A32: =Широкая_таблица!$A$9 -> 46275 | B32: =Широкая_таблица!$C$9 -> Завалишин Д.Л. | C32: =INDEX(Настройки!$A$10:$A$16,7) -> Ми-П | D32: =Широкая_таблица!$AT$9 -> 0 | E32: =Широкая_таблица!$AU$9 -> 27 | F32: =Широкая_таблица!$AV$9 -> 0 | G32: =Широкая_таблица!$AW$9+Широкая_таблица!$AX$9 -> -2 | H32: =Широкая_таблица!$AY$9 -> 1 | I32: =Широкая_таблица!$AZ$9 -> 24
A33: =Широкая_таблица!$A$10 -> 46276 | B33: =Широкая_таблица!$C$10 -> Пузанов Д.В. | C33: =INDEX(Настройки!$A$10:$A$16,1) -> АК-10 | D33: =Широкая_таблица!$D$10 -> 30 | E33: =Широкая_таблица!$E$10 -> 0 | F33: =Широкая_таблица!$F$10 -> 0 | G33: =Широкая_таблица!$G$10+Широкая_таблица!$H$10 -> 0 | H33: =Широкая_таблица!$I$10 -> 5 | I33: =Широкая_таблица!$J$10 -> 25
A34: =Широкая_таблица!$A$10 -> 46276 | B34: =Широкая_таблица!$C$10 -> Пузанов Д.В. | C34: =INDEX(Настройки!$A$10:$A$16,2) -> АК-15 | D34: =Широкая_таблица!$K$10 -> 46 | E34: =Широкая_таблица!$L$10 -> 0 | F34: =Широкая_таблица!$M$10 -> 0 | G34: =Широкая_таблица!$N$10+Широкая_таблица!$O$10 -> 0 | H34: =Широкая_таблица!$P$10 -> 2 | I34: =Широкая_таблица!$Q$10 -> 44
A35: =Широкая_таблица!$A$10 -> 46276 | B35: =Широкая_таблица!$C$10 -> Пузанов Д.В. | C35: =INDEX(Настройки!$A$10:$A$16,3) -> Г 3500 | D35: =Широкая_таблица!$R$10 -> 6 | E35: =Широкая_таблица!$S$10 -> 0 | F35: =Широкая_таблица!$T$10 -> 0 | G35: =Широкая_таблица!$U$10+Широкая_таблица!$V$10 -> 0 | H35: =Широкая_таблица!$W$10 -> 2 | I35: =Широкая_таблица!$X$10 -> 4
A36: =Широкая_таблица!$A$10 -> 46276 | B36: =Широкая_таблица!$C$10 -> Пузанов Д.В. | C36: =INDEX(Настройки!$A$10:$A$16,4) -> Г 1800 | D36: =Широкая_таблица!$Y$10 -> 144 | E36: =Широкая_таблица!$Z$10 -> 0 | F36: =Широкая_таблица!$AA$10 -> 0 | G36: =Широкая_таблица!$AB$10+Широкая_таблица!$AC$10 -> 0 | H36: =Широкая_таблица!$AD$10 -> 12 | I36: =Широкая_таблица!$AE$10 -> 132
A37: =Широкая_таблица!$A$10 -> 46276 | B37: =Широкая_таблица!$C$10 -> Пузанов Д.В. | C37: =INDEX(Настройки!$A$10:$A$16,5) -> Г 800 | D37: =Широкая_таблица!$AF$10 -> 22 | E37: =Широкая_таблица!$AG$10 -> 64 | F37: =Широкая_таблица!$AH$10 -> 0 | G37: =Широкая_таблица!$AI$10+Широкая_таблица!$AJ$10 -> 0 | H37: =Широкая_таблица!$AK$10 -> 4 | I37: =Широкая_таблица!$AL$10 -> 82
A38: =Широкая_таблица!$A$10 -> 46276 | B38: =Широкая_таблица!$C$10 -> Пузанов Д.В. | C38: =INDEX(Настройки!$A$10:$A$16,6) -> Ми-К | D38: =Широкая_таблица!$AM$10 -> 13 | E38: =Широкая_таблица!$AN$10 -> 0 | F38: =Широкая_таблица!$AO$10 -> 0 | G38: =Широкая_таблица!$AP$10+Широкая_таблица!$AQ$10 -> 0 | H38: =Широкая_таблица!$AR$10 -> 6 | I38: =Широкая_таблица!$AS$10 -> 7
A39: =Широкая_таблица!$A$10 -> 46276 | B39: =Широкая_таблица!$C$10 -> Пузанов Д.В. | C39: =INDEX(Настройки!$A$10:$A$16,7) -> Ми-П | D39: =Широкая_таблица!$AT$10 -> 24 | E39: =Широкая_таблица!$AU$10 -> 0 | F39: =Широкая_таблица!$AV$10 -> 0 | G39: =Широкая_таблица!$AW$10+Широкая_таблица!$AX$10 -> 0 | H39: =Широкая_таблица!$AY$10 -> 1 | I39: =Широкая_таблица!$AZ$10 -> 23
A40: =Широкая_таблица!$A$11 -> 46277 | B40: =Широкая_таблица!$C$11 -> Завалишин Д.Л. | C40: =INDEX(Настройки!$A$10:$A$16,1) -> АК-10 | D40: =Широкая_таблица!$D$11 -> 25 | E40: =Широкая_таблица!$E$11 -> 0 | F40: =Широкая_таблица!$F$11 -> 0 | G40: =Широкая_таблица!$G$11+Широкая_таблица!$H$11 -> 0 | H40: =Широкая_таблица!$I$11 -> 1 | I40: =Широкая_таблица!$J$11 -> 24
A41: =Широкая_таблица!$A$11 -> 46277 | B41: =Широкая_таблица!$C$11 -> Завалишин Д.Л. | C41: =INDEX(Настройки!$A$10:$A$16,2) -> АК-15 | D41: =Широкая_таблица!$K$11 -> 44 | E41: =Широкая_таблица!$L$11 -> 0 | F41: =Широкая_таблица!$M$11 -> 0 | G41: =Широкая_таблица!$N$11+Широкая_таблица!$O$11 -> 0 | H41: =Широкая_таблица!$P$11 -> 2 | I41: =Широкая_таблица!$Q$11 -> 42
A42: =Широкая_таблица!$A$11 -> 46277 | B42: =Широкая_таблица!$C$11 -> Завалишин Д.Л. | C42: =INDEX(Настройки!$A$10:$A$16,3) -> Г 3500 | D42: =Широкая_таблица!$R$11 -> 4 | E42: =Широкая_таблица!$S$11 -> 0 | F42: =Широкая_таблица!$T$11 -> 0 | G42: =Широкая_таблица!$U$11+Широкая_таблица!$V$11 -> 0 | H42: =Широкая_таблица!$W$11 -> 1 | I42: =Широкая_таблица!$X$11 -> 3
...

Sheet Фулфилмент
A1: PVZ.FLOW | Фулфилмент
A4: Дата | B4: Товар | C4: Приход | D4: Возврат | E4: Выбытие | F4: Приёмка | G4: Брендирование | H4: Упаковка | I4: Сборка | J4: Итого
A5: =Обработка!$A$54 -> 46279 | B5: =Обработка!$C$54 -> АК-10 | C5: =Обработка!$E$54 -> 15 | D5: =Обработка!$F$54 -> 0 | E5: =Обработка!$H$54 -> 2 | F5: =(C5+D5)*INDEX(Настройки!$B$10:$B$16,MATCH($B5,Настройки!$A$10:$A$16,0)) -> 150 | G5: =E5*INDEX(Настройки!$C$10:$C$16,MATCH($B5,Настройки!$A$10:$A$16,0)) -> 20 | H5: =E5*INDEX(Настройки!$D$10:$D$16,MATCH($B5,Настройки!$A$10:$A$16,0)) -> 40 | I5: =E5*INDEX(Настройки!$E$10:$E$16,MATCH($B5,Настройки!$A$10:$A$16,0)) -> 20 | J5: =SUM(F5:I5) -> 230
A6: =Обработка!$A$55 -> 46279 | B6: =Обработка!$C$55 -> АК-15 | C6: =Обработка!$E$55 -> 0 | D6: =Обработка!$F$55 -> 0 | E6: =Обработка!$H$55 -> 2 | F6: =(C6+D6)*INDEX(Настройки!$B$10:$B$16,MATCH($B6,Настройки!$A$10:$A$16,0)) -> 0 | G6: =E6*INDEX(Настройки!$C$10:$C$16,MATCH($B6,Настройки!$A$10:$A$16,0)) -> 20 | H6: =E6*INDEX(Настройки!$D$10:$D$16,MATCH($B6,Настройки!$A$10:$A$16,0)) -> 40 | I6: =E6*INDEX(Настройки!$E$10:$E$16,MATCH($B6,Настройки!$A$10:$A$16,0)) -> 20 | J6: =SUM(F6:I6) -> 80
A7: =Обработка!$A$56 -> 46279 | B7: =Обработка!$C$56 -> Г 3500 | C7: =Обработка!$E$56 -> 14 | D7: =Обработка!$F$56 -> 0 | E7: =Обработка!$H$56 -> 0 | F7: =(C7+D7)*INDEX(Настройки!$B$10:$B$16,MATCH($B7,Настройки!$A$10:$A$16,0)) -> 140 | G7: =E7*INDEX(Настройки!$C$10:$C$16,MATCH($B7,Настройки!$A$10:$A$16,0)) -> 0 | H7: =E7*INDEX(Настройки!$D$10:$D$16,MATCH($B7,Настройки!$A$10:$A$16,0)) -> 0 | I7: =E7*INDEX(Настройки!$E$10:$E$16,MATCH($B7,Настройки!$A$10:$A$16,0)) -> 0 | J7: =SUM(F7:I7) -> 140
A8: =Обработка!$A$57 -> 46279 | B8: =Обработка!$C$57 -> Г 1800 | C8: =Обработка!$E$57 -> 0 | D8: =Обработка!$F$57 -> 0 | E8: =Обработка!$H$57 -> 8 | F8: =(C8+D8)*INDEX(Настройки!$B$10:$B$16,MATCH($B8,Настройки!$A$10:$A$16,0)) -> 0 | G8: =E8*INDEX(Настройки!$C$10:$C$16,MATCH($B8,Настройки!$A$10:$A$16,0)) -> 80 | H8: =E8*INDEX(Настройки!$D$10:$D$16,MATCH($B8,Настройки!$A$10:$A$16,0)) -> 240 | I8: =E8*INDEX(Настройки!$E$10:$E$16,MATCH($B8,Настройки!$A$10:$A$16,0)) -> 120 | J8: =SUM(F8:I8) -> 440
A9: =Обработка!$A$58 -> 46279 | B9: =Обработка!$C$58 -> Г 800 | C9: =Обработка!$E$58 -> 0 | D9: =Обработка!$F$58 -> 0 | E9: =Обработка!$H$58 -> 9 | F9: =(C9+D9)*INDEX(Настройки!$B$10:$B$16,MATCH($B9,Настройки!$A$10:$A$16,0)) -> 0 | G9: =E9*INDEX(Настройки!$C$10:$C$16,MATCH($B9,Настройки!$A$10:$A$16,0)) -> 90 | H9: =E9*INDEX(Настройки!$D$10:$D$16,MATCH($B9,Настройки!$A$10:$A$16,0)) -> 270 | I9: =E9*INDEX(Настройки!$E$10:$E$16,MATCH($B9,Настройки!$A$10:$A$16,0)) -> 135 | J9: =SUM(F9:I9) -> 495
A10: =Обработка!$A$59 -> 46279 | B10: =Обработка!$C$59 -> Ми-К | C10: =Обработка!$E$59 -> 0 | D10: =Обработка!$F$59 -> 1 | E10: =Обработка!$H$59 -> 4 | F10: =(C10+D10)*INDEX(Настройки!$B$10:$B$16,MATCH($B10,Настройки!$A$10:$A$16,0)) -> 10 | G10: =E10*INDEX(Настройки!$C$10:$C$16,MATCH($B10,Настройки!$A$10:$A$16,0)) -> 0 | H10: =E10*INDEX(Настройки!$D$10:$D$16,MATCH($B10,Настройки!$A$10:$A$16,0)) -> 80 | I10: =E10*INDEX(Настройки!$E$10:$E$16,MATCH($B10,Настройки!$A$10:$A$16,0)) -> 40 | J10: =SUM(F10:I10) -> 130
A11: =Обработка!$A$60 -> 46279 | B11: =Обработка!$C$60 -> Ми-П | C11: =Обработка!$E$60 -> 0 | D11: =Обработка!$F$60 -> 0 | E11: =Обработка!$H$60 -> 1 | F11: =(C11+D11)*INDEX(Настройки!$B$10:$B$16,MATCH($B11,Настройки!$A$10:$A$16,0)) -> 0 | G11: =E11*INDEX(Настройки!$C$10:$C$16,MATCH($B11,Настройки!$A$10:$A$16,0)) -> 0 | H11: =E11*INDEX(Настройки!$D$10:$D$16,MATCH($B11,Настройки!$A$10:$A$16,0)) -> 20 | I11: =E11*INDEX(Настройки!$E$10:$E$16,MATCH($B11,Настройки!$A$10:$A$16,0)) -> 10 | J11: =SUM(F11:I11) -> 30
A12: =Обработка!$A$61 -> 46280 | B12: =Обработка!$C$61 -> АК-10 | C12: =Обработка!$E$61 -> 0 | D12: =Обработка!$F$61 -> 0 | E12: =Обработка!$H$61 -> 0 | F12: =(C12+D12)*INDEX(Настройки!$B$10:$B$16,MATCH($B12,Настройки!$A$10:$A$16,0)) -> 0 | G12: =E12*INDEX(Настройки!$C$10:$C$16,MATCH($B12,Настройки!$A$10:$A$16,0)) -> 0 | H12: =E12*INDEX(Настройки!$D$10:$D$16,MATCH($B12,Настройки!$A$10:$A$16,0)) -> 0 | I12: =E12*INDEX(Настройки!$E$10:$E$16,MATCH($B12,Настройки!$A$10:$A$16,0)) -> 0 | J12: =SUM(F12:I12) -> 0
A13: =Обработка!$A$62 -> 46280 | B13: =Обработка!$C$62 -> АК-15 | C13: =Обработка!$E$62 -> 0 | D13: =Обработка!$F$62 -> 0 | E13: =Обработка!$H$62 -> 1 | F13: =(C13+D13)*INDEX(Настройки!$B$10:$B$16,MATCH($B13,Настройки!$A$10:$A$16,0)) -> 0 | G13: =E13*INDEX(Настройки!$C$10:$C$16,MATCH($B13,Настройки!$A$10:$A$16,0)) -> 10 | H13: =E13*INDEX(Настройки!$D$10:$D$16,MATCH($B13,Настройки!$A$10:$A$16,0)) -> 20 | I13: =E13*INDEX(Настройки!$E$10:$E$16,MATCH($B13,Настройки!$A$10:$A$16,0)) -> 10 | J13: =SUM(F13:I13) -> 40
A14: =Обработка!$A$63 -> 46280 | B14: =Обработка!$C$63 -> Г 3500 | C14: =Обработка!$E$63 -> 0 | D14: =Обработка!$F$63 -> 0 | E14: =Обработка!$H$63 -> 1 | F14: =(C14+D14)*INDEX(Настройки!$B$10:$B$16,MATCH($B14,Настройки!$A$10:$A$16,0)) -> 0 | G14: =E14*INDEX(Настройки!$C$10:$C$16,MATCH($B14,Настройки!$A$10:$A$16,0)) -> 15 | H14: =E14*INDEX(Настройки!$D$10:$D$16,MATCH($B14,Настройки!$A$10:$A$16,0)) -> 35 | I14: =E14*INDEX(Настройки!$E$10:$E$16,MATCH($B14,Настройки!$A$10:$A$16,0)) -> 25 | J14: =SUM(F14:I14) -> 75
A15: =Обработка!$A$64 -> 46280 | B15: =Обработка!$C$64 -> Г 1800 | C15: =Обработка!$E$64 -> 0 | D15: =Обработка!$F$64 -> 0 | E15: =Обработка!$H$64 -> 11 | F15: =(C15+D15)*INDEX(Настройки!$B$10:$B$16,MATCH($B15,Настройки!$A$10:$A$16,0)) -> 0 | G15: =E15*INDEX(Настройки!$C$10:$C$16,MATCH($B15,Настройки!$A$10:$A$16,0)) -> 110 | H15: =E15*INDEX(Настройки!$D$10:$D$16,MATCH($B15,Настройки!$A$10:$A$16,0)) -> 330 | I15: =E15*INDEX(Настройки!$E$10:$E$16,MATCH($B15,Настройки!$A$10:$A$16,0)) -> 165 | J15: =SUM(F15:I15) -> 605
A16: =Обработка!$A$65 -> 46280 | B16: =Обработка!$C$65 -> Г 800 | C16: =Обработка!$E$65 -> 0 | D16: =Обработка!$F$65 -> 0 | E16: =Обработка!$H$65 -> 7 | F16: =(C16+D16)*INDEX(Настройки!$B$10:$B$16,MATCH($B16,Настройки!$A$10:$A$16,0)) -> 0 | G16: =E16*INDEX(Настройки!$C$10:$C$16,MATCH($B16,Настройки!$A$10:$A$16,0)) -> 70 | H16: =E16*INDEX(Настройки!$D$10:$D$16,MATCH($B16,Настройки!$A$10:$A$16,0)) -> 210 | I16: =E16*INDEX(Настройки!$E$10:$E$16,MATCH($B16,Настройки!$A$10:$A$16,0)) -> 105 | J16: =SUM(F16:I16) -> 385
A17: =Обработка!$A$66 -> 46280 | B17: =Обработка!$C$66 -> Ми-К | C17: =Обработка!$E$66 -> 20 | D17: =Обработка!$F$66 -> 0 | E17: =Обработка!$H$66 -> 4 | F17: =(C17+D17)*INDEX(Настройки!$B$10:$B$16,MATCH($B17,Настройки!$A$10:$A$16,0)) -> 200 | G17: =E17*INDEX(Настройки!$C$10:$C$16,MATCH($B17,Настройки!$A$10:$A$16,0)) -> 0 | H17: =E17*INDEX(Настройки!$D$10:$D$16,MATCH($B17,Настройки!$A$10:$A$16,0)) -> 80 | I17: =E17*INDEX(Настройки!$E$10:$E$16,MATCH($B17,Настройки!$A$10:$A$16,0)) -> 40 | J17: =SUM(F17:I17) -> 320
A18: =Обработка!$A$67 -> 46280 | B18: =Обработка!$C$67 -> Ми-П | C18: =Обработка!$E$67 -> 0 | D18: =Обработка!$F$67 -> 0 | E18: =Обработка!$H$67 -> 1 | F18: =(C18+D18)*INDEX(Настройки!$B$10:$B$16,MATCH($B18,Настройки!$A$10:$A$16,0)) -> 0 | G18: =E18*INDEX(Настройки!$C$10:$C$16,MATCH($B18,Настройки!$A$10:$A$16,0)) -> 0 | H18: =E18*INDEX(Настройки!$D$10:$D$16,MATCH($B18,Настройки!$A$10:$A$16,0)) -> 20 | I18: =E18*INDEX(Настройки!$E$10:$E$16,MATCH($B18,Настройки!$A$10:$A$16,0)) -> 10 | J18: =SUM(F18:I18) -> 30
A19: =Обработка!$A$68 -> 46281 | B19: =Обработка!$C$68 -> АК-10 | C19: =Обработка!$E$68 -> 0 | D19: =Обработка!$F$68 -> 0 | E19: =Обработка!$H$68 -> 1 | F19: =(C19+D19)*INDEX(Настройки!$B$10:$B$16,MATCH($B19,Настройки!$A$10:$A$16,0)) -> 0 | G19: =E19*INDEX(Настройки!$C$10:$C$16,MATCH($B19,Настройки!$A$10:$A$16,0)) -> 10 | H19: =E19*INDEX(Настройки!$D$10:$D$16,MATCH($B19,Настройки!$A$10:$A$16,0)) -> 20 | I19: =E19*INDEX(Настройки!$E$10:$E$16,MATCH($B19,Настройки!$A$10:$A$16,0)) -> 10 | J19: =SUM(F19:I19) -> 40
A20: =Обработка!$A$69 -> 46281 | B20: =Обработка!$C$69 -> АК-15 | C20: =Обработка!$E$69 -> 0 | D20: =Обработка!$F$69 -> 0 | E20: =Обработка!$H$69 -> 3 | F20: =(C20+D20)*INDEX(Настройки!$B$10:$B$16,MATCH($B20,Настройки!$A$10:$A$16,0)) -> 0 | G20: =E20*INDEX(Настройки!$C$10:$C$16,MATCH($B20,Настройки!$A$10:$A$16,0)) -> 30 | H20: =E20*INDEX(Настройки!$D$10:$D$16,MATCH($B20,Настройки!$A$10:$A$16,0)) -> 60 | I20: =E20*INDEX(Настройки!$E$10:$E$16,MATCH($B20,Настройки!$A$10:$A$16,0)) -> 30 | J20: =SUM(F20:I20) -> 120
A21: =Обработка!$A$70 -> 46281 | B21: =Обработка!$C$70 -> Г 3500 | C21: =Обработка!$E$70 -> 0 | D21: =Обработка!$F$70 -> 0 | E21: =Обработка!$H$70 -> 0 | F21: =(C21+D21)*INDEX(Настройки!$B$10:$B$16,MATCH($B21,Настройки!$A$10:$A$16,0)) -> 0 | G21: =E21*INDEX(Настройки!$C$10:$C$16,MATCH($B21,Настройки!$A$10:$A$16,0)) -> 0 | H21: =E21*INDEX(Настройки!$D$10:$D$16,MATCH($B21,Настройки!$A$10:$A$16,0)) -> 0 | I21: =E21*INDEX(Настройки!$E$10:$E$16,MATCH($B21,Настройки!$A$10:$A$16,0)) -> 0 | J21: =SUM(F21:I21) -> 0
A22: =Обработка!$A$71 -> 46281 | B22: =Обработка!$C$71 -> Г 1800 | C22: =Обработка!$E$71 -> 0 | D22: =Обработка!$F$71 -> 0 | E22: =Обработка!$H$71 -> 13 | F22: =(C22+D22)*INDEX(Настройки!$B$10:$B$16,MATCH($B22,Настройки!$A$10:$A$16,0)) -> 0 | G22: =E22*INDEX(Настройки!$C$10:$C$16,MATCH($B22,Настройки!$A$10:$A$16,0)) -> 130 | H22: =E22*INDEX(Настройки!$D$10:$D$16,MATCH($B22,Настройки!$A$10:$A$16,0)) -> 390 | I22: =E22*INDEX(Настройки!$E$10:$E$16,MATCH($B22,Настройки!$A$10:$A$16,0)) -> 195 | J22: =SUM(F22:I22) -> 715
A23: =Обработка!$A$72 -> 46281 | B23: =Обработка!$C$72 -> Г 800 | C23: =Обработка!$E$72 -> 0 | D23: =Обработка!$F$72 -> 0 | E23: =Обработка!$H$72 -> 12 | F23: =(C23+D23)*INDEX(Настройки!$B$10:$B$16,MATCH($B23,Настройки!$A$10:$A$16,0)) -> 0 | G23: =E23*INDEX(Настройки!$C$10:$C$16,MATCH($B23,Настройки!$A$10:$A$16,0)) -> 120 | H23: =E23*INDEX(Настройки!$D$10:$D$16,MATCH($B23,Настройки!$A$10:$A$16,0)) -> 360 | I23: =E23*INDEX(Настройки!$E$10:$E$16,MATCH($B23,Настройки!$A$10:$A$16,0)) -> 180 | J23: =SUM(F23:I23) -> 660
A24: =Обработка!$A$73 -> 46281 | B24: =Обработка!$C$73 -> Ми-К | C24: =Обработка!$E$73 -> 0 | D24: =Обработка!$F$73 -> 0 | E24: =Обработка!$H$73 -> 0 | F24: =(C24+D24)*INDEX(Настройки!$B$10:$B$16,MATCH($B24,Настройки!$A$10:$A$16,0)) -> 0 | G24: =E24*INDEX(Настройки!$C$10:$C$16,MATCH($B24,Настройки!$A$10:$A$16,0)) -> 0 | H24: =E24*INDEX(Настройки!$D$10:$D$16,MATCH($B24,Настройки!$A$10:$A$16,0)) -> 0 | I24: =E24*INDEX(Настройки!$E$10:$E$16,MATCH($B24,Настройки!$A$10:$A$16,0)) -> 0 | J24: =SUM(F24:I24) -> 0
A25: =Обработка!$A$74 -> 46281 | B25: =Обработка!$C$74 -> Ми-П | C25: =Обработка!$E$74 -> 0 | D25: =Обработка!$F$74 -> 0 | E25: =Обработка!$H$74 -> 1 | F25: =(C25+D25)*INDEX(Настройки!$B$10:$B$16,MATCH($B25,Настройки!$A$10:$A$16,0)) -> 0 | G25: =E25*INDEX(Настройки!$C$10:$C$16,MATCH($B25,Настройки!$A$10:$A$16,0)) -> 0 | H25: =E25*INDEX(Настройки!$D$10:$D$16,MATCH($B25,Настройки!$A$10:$A$16,0)) -> 20 | I25: =E25*INDEX(Настройки!$E$10:$E$16,MATCH($B25,Настройки!$A$10:$A$16,0)) -> 10 | J25: =SUM(F25:I25) -> 30
A26: =Обработка!$A$75 -> 46282 | B26: =Обработка!$C$75 -> АК-10 | C26: =Обработка!$E$75 -> 0 | D26: =Обработка!$F$75 -> 0 | E26: =Обработка!$H$75 -> 1 | F26: =(C26+D26)*INDEX(Настройки!$B$10:$B$16,MATCH($B26,Настройки!$A$10:$A$16,0)) -> 0 | G26: =E26*INDEX(Настройки!$C$10:$C$16,MATCH($B26,Настройки!$A$10:$A$16,0)) -> 10 | H26: =E26*INDEX(Настройки!$D$10:$D$16,MATCH($B26,Настройки!$A$10:$A$16,0)) -> 20 | I26: =E26*INDEX(Настройки!$E$10:$E$16,MATCH($B26,Настройки!$A$10:$A$16,0)) -> 10 | J26: =SUM(F26:I26) -> 40
A27: =Обработка!$A$76 -> 46282 | B27: =Обработка!$C$76 -> АК-15 | C27: =Обработка!$E$76 -> 0 | D27: =Обработка!$F$76 -> 0 | E27: =Обработка!$H$76 -> 3 | F27: =(C27+D27)*INDEX(Настройки!$B$10:$B$16,MATCH($B27,Настройки!$A$10:$A$16,0)) -> 0 | G27: =E27*INDEX(Настройки!$C$10:$C$16,MATCH($B27,Настройки!$A$10:$A$16,0)) -> 30 | H27: =E27*INDEX(Настройки!$D$10:$D$16,MATCH($B27,Настройки!$A$10:$A$16,0)) -> 60 | I27: =E27*INDEX(Настройки!$E$10:$E$16,MATCH($B27,Настройки!$A$10:$A$16,0)) -> 30 | J27: =SUM(F27:I27) -> 120
A28: =Обработка!$A$77 -> 46282 | B28: =Обработка!$C$77 -> Г 3500 | C28: =Обработка!$E$77 -> 0 | D28: =Обработка!$F$77 -> 0 | E28: =Обработка!$H$77 -> 0 | F28: =(C28+D28)*INDEX(Настройки!$B$10:$B$16,MATCH($B28,Настройки!$A$10:$A$16,0)) -> 0 | G28: =E28*INDEX(Настройки!$C$10:$C$16,MATCH($B28,Настройки!$A$10:$A$16,0)) -> 0 | H28: =E28*INDEX(Настройки!$D$10:$D$16,MATCH($B28,Настройки!$A$10:$A$16,0)) -> 0 | I28: =E28*INDEX(Настройки!$E$10:$E$16,MATCH($B28,Настройки!$A$10:$A$16,0)) -> 0 | J28: =SUM(F28:I28) -> 0
A29: =Обработка!$A$78 -> 46282 | B29: =Обработка!$C$78 -> Г 1800 | C29: =Обработка!$E$78 -> 0 | D29: =Обработка!$F$78 -> 0 | E29: =Обработка!$H$78 -> 13 | F29: =(C29+D29)*INDEX(Настройки!$B$10:$B$16,MATCH($B29,Настройки!$A$10:$A$16,0)) -> 0 | G29: =E29*INDEX(Настройки!$C$10:$C$16,MATCH($B29,Настройки!$A$10:$A$16,0)) -> 130 | H29: =E29*INDEX(Настройки!$D$10:$D$16,MATCH($B29,Настройки!$A$10:$A$16,0)) -> 390 | I29: =E29*INDEX(Настройки!$E$10:$E$16,MATCH($B29,Настройки!$A$10:$A$16,0)) -> 195 | J29: =SUM(F29:I29) -> 715
A30: =Обработка!$A$79 -> 46282 | B30: =Обработка!$C$79 -> Г 800 | C30: =Обработка!$E$79 -> 0 | D30: =Обработка!$F$79 -> 0 | E30: =Обработка!$H$79 -> 3 | F30: =(C30+D30)*INDEX(Настройки!$B$10:$B$16,MATCH($B30,Настройки!$A$10:$A$16,0)) -> 0 | G30: =E30*INDEX(Настройки!$C$10:$C$16,MATCH($B30,Настройки!$A$10:$A$16,0)) -> 30 | H30: =E30*INDEX(Настройки!$D$10:$D$16,MATCH($B30,Настройки!$A$10:$A$16,0)) -> 90 | I30: =E30*INDEX(Настройки!$E$10:$E$16,MATCH($B30,Настройки!$A$10:$A$16,0)) -> 45 | J30: =SUM(F30:I30) -> 165
A31: =Обработка!$A$80 -> 46282 | B31: =Обработка!$C$80 -> Ми-К | C31: =Обработка!$E$80 -> 0 | D31: =Обработка!$F$80 -> 0 | E31: =Обработка!$H$80 -> 1 | F31: =(C31+D31)*INDEX(Настройки!$B$10:$B$16,MATCH($B31,Настройки!$A$10:$A$16,0)) -> 0 | G31: =E31*INDEX(Настройки!$C$10:$C$16,MATCH($B31,Настройки!$A$10:$A$16,0)) -> 0 | H31: =E31*INDEX(Настройки!$D$10:$D$16,MATCH($B31,Настройки!$A$10:$A$16,0)) -> 20 | I31: =E31*INDEX(Настройки!$E$10:$E$16,MATCH($B31,Настройки!$A$10:$A$16,0)) -> 10 | J31: =SUM(F31:I31) -> 30
A32: =Обработка!$A$81 -> 46282 | B32: =Обработка!$C$81 -> Ми-П | C32: =Обработка!$E$81 -> 0 | D32: =Обработка!$F$81 -> 0 | E32: =Обработка!$H$81 -> 2 | F32: =(C32+D32)*INDEX(Настройки!$B$10:$B$16,MATCH($B32,Настройки!$A$10:$A$16,0)) -> 0 | G32: =E32*INDEX(Настройки!$C$10:$C$16,MATCH($B32,Настройки!$A$10:$A$16,0)) -> 0 | H32: =E32*INDEX(Настройки!$D$10:$D$16,MATCH($B32,Настройки!$A$10:$A$16,0)) -> 40 | I32: =E32*INDEX(Настройки!$E$10:$E$16,MATCH($B32,Настройки!$A$10:$A$16,0)) -> 20 | J32: =SUM(F32:I32) -> 60
A33: =Обработка!$A$82 -> 46283 | B33: =Обработка!$C$82 -> АК-10 | C33: =Обработка!$E$82 -> 0 | D33: =Обработка!$F$82 -> 0 | E33: =Обработка!$H$82 -> 1 | F33: =(C33+D33)*INDEX(Настройки!$B$10:$B$16,MATCH($B33,Настройки!$A$10:$A$16,0)) -> 0 | G33: =E33*INDEX(Настройки!$C$10:$C$16,MATCH($B33,Настройки!$A$10:$A$16,0)) -> 10 | H33: =E33*INDEX(Настройки!$D$10:$D$16,MATCH($B33,Настройки!$A$10:$A$16,0)) -> 20 | I33: =E33*INDEX(Настройки!$E$10:$E$16,MATCH($B33,Настройки!$A$10:$A$16,0)) -> 10 | J33: =SUM(F33:I33) -> 40
A34: =Обработка!$A$83 -> 46283 | B34: =Обработка!$C$83 -> АК-15 | C34: =Обработка!$E$83 -> 0 | D34: =Обработка!$F$83 -> 0 | E34: =Обработка!$H$83 -> 1 | F34: =(C34+D34)*INDEX(Настройки!$B$10:$B$16,MATCH($B34,Настройки!$A$10:$A$16,0)) -> 0 | G34: =E34*INDEX(Настройки!$C$10:$C$16,MATCH($B34,Настройки!$A$10:$A$16,0)) -> 10 | H34: =E34*INDEX(Настройки!$D$10:$D$16,MATCH($B34,Настройки!$A$10:$A$16,0)) -> 20 | I34: =E34*INDEX(Настройки!$E$10:$E$16,MATCH($B34,Настройки!$A$10:$A$16,0)) -> 10 | J34: =SUM(F34:I34) -> 40
A35: =Обработка!$A$84 -> 46283 | B35: =Обработка!$C$84 -> Г 3500 | C35: =Обработка!$E$84 -> 0 | D35: =Обработка!$F$84 -> 0 | E35: =Обработка!$H$84 -> 1 | F35: =(C35+D35)*INDEX(Настройки!$B$10:$B$16,MATCH($B35,Настройки!$A$10:$A$16,0)) -> 0 | G35: =E35*INDEX(Настройки!$C$10:$C$16,MATCH($B35,Настройки!$A$10:$A$16,0)) -> 15 | H35: =E35*INDEX(Настройки!$D$10:$D$16,MATCH($B35,Настройки!$A$10:$A$16,0)) -> 35 | I35: =E35*INDEX(Настройки!$E$10:$E$16,MATCH($B35,Настройки!$A$10:$A$16,0)) -> 25 | J35: =SUM(F35:I35) -> 75
A36: =Обработка!$A$85 -> 46283 | B36: =Обработка!$C$85 -> Г 1800 | C36: =Обработка!$E$85 -> 0 | D36: =Обработка!$F$85 -> 0 | E36: =Обработка!$H$85 -> 13 | F36: =(C36+D36)*INDEX(Настройки!$B$10:$B$16,MATCH($B36,Настройки!$A$10:$A$16,0)) -> 0 | G36: =E36*INDEX(Настройки!$C$10:$C$16,MATCH($B36,Настройки!$A$10:$A$16,0)) -> 130 | H36: =E36*INDEX(Настройки!$D$10:$D$16,MATCH($B36,Настройки!$A$10:$A$16,0)) -> 390 | I36: =E36*INDEX(Настройки!$E$10:$E$16,MATCH($B36,Настройки!$A$10:$A$16,0)) -> 195 | J36: =SUM(F36:I36) -> 715
A37: =Обработка!$A$86 -> 46283 | B37: =Обработка!$C$86 -> Г 800 | C37: =Обработка!$E$86 -> 0 | D37: =Обработка!$F$86 -> 0 | E37: =Обработка!$H$86 -> 4 | F37: =(C37+D37)*INDEX(Настройки!$B$10:$B$16,MATCH($B37,Настройки!$A$10:$A$16,0)) -> 0 | G37: =E37*INDEX(Настройки!$C$10:$C$16,MATCH($B37,Настройки!$A$10:$A$16,0)) -> 40 | H37: =E37*INDEX(Настройки!$D$10:$D$16,MATCH($B37,Настройки!$A$10:$A$16,0)) -> 120 | I37: =E37*INDEX(Настройки!$E$10:$E$16,MATCH($B37,Настройки!$A$10:$A$16,0)) -> 60 | J37: =SUM(F37:I37) -> 220
A38: =Обработка!$A$87 -> 46283 | B38: =Обработка!$C$87 -> Ми-К | C38: =Обработка!$E$87 -> 0 | D38: =Обработка!$F$87 -> 0 | E38: =Обработка!$H$87 -> 0 | F38: =(C38+D38)*INDEX(Настройки!$B$10:$B$16,MATCH($B38,Настройки!$A$10:$A$16,0)) -> 0 | G38: =E38*INDEX(Настройки!$C$10:$C$16,MATCH($B38,Настройки!$A$10:$A$16,0)) -> 0 | H38: =E38*INDEX(Настройки!$D$10:$D$16,MATCH($B38,Настройки!$A$10:$A$16,0)) -> 0 | I38: =E38*INDEX(Настройки!$E$10:$E$16,MATCH($B38,Настройки!$A$10:$A$16,0)) -> 0 | J38: =SUM(F38:I38) -> 0
A39: =Обработка!$A$88 -> 46283 | B39: =Обработка!$C$88 -> Ми-П | C39: =Обработка!$E$88 -> 0 | D39: =Обработка!$F$88 -> 0 | E39: =Обработка!$H$88 -> 0 | F39: =(C39+D39)*INDEX(Настройки!$B$10:$B$16,MATCH($B39,Настройки!$A$10:$A$16,0)) -> 0 | G39: =E39*INDEX(Настройки!$C$10:$C$16,MATCH($B39,Настройки!$A$10:$A$16,0)) -> 0 | H39: =E39*INDEX(Настройки!$D$10:$D$16,MATCH($B39,Настройки!$A$10:$A$16,0)) -> 0 | I39: =E39*INDEX(Настройки!$E$10:$E$16,MATCH($B39,Настройки!$A$10:$A$16,0)) -> 0 | J39: =SUM(F39:I39) -> 0
A40: =Обработка!$A$89 -> 46284 | B40: =Обработка!$C$89 -> АК-10 | C40: =Обработка!$E$89 -> 0 | D40: =Обработка!$F$89 -> 0 | E40: =Обработка!$H$89 -> 0 | F40: =(C40+D40)*INDEX(Настройки!$B$10:$B$16,MATCH($B40,Настройки!$A$10:$A$16,0)) -> 0 | G40: =E40*INDEX(Настройки!$C$10:$C$16,MATCH($B40,Настройки!$A$10:$A$16,0)) -> 0 | H40: =E40*INDEX(Настройки!$D$10:$D$16,MATCH($B40,Настройки!$A$10:$A$16,0)) -> 0 | I40: =E40*INDEX(Настройки!$E$10:$E$16,MATCH($B40,Настройки!$A$10:$A$16,0)) -> 0 | J40: =SUM(F40:I40) -> 0
A41: =Обработка!$A$90 -> 46284 | B41: =Обработка!$C$90 -> АК-15 | C41: =Обработка!$E$90 -> 0 | D41: =Обработка!$F$90 -> 0 | E41: =Обработка!$H$90 -> 0 | F41: =(C41+D41)*INDEX(Настройки!$B$10:$B$16,MATCH($B41,Настройки!$A$10:$A$16,0)) -> 0 | G41: =E41*INDEX(Настройки!$C$10:$C$16,MATCH($B41,Настройки!$A$10:$A$16,0)) -> 0 | H41: =E41*INDEX(Настройки!$D$10:$D$16,MATCH($B41,Настройки!$A$10:$A$16,0)) -> 0 | I41: =E41*INDEX(Настройки!$E$10:$E$16,MATCH($B41,Настройки!$A$10:$A$16,0)) -> 0 | J41: =SUM(F41:I41) -> 0
A42: =Обработка!$A$91 -> 46284 | B42: =Обработка!$C$91 -> Г 3500 | C42: =Обработка!$E$91 -> 0 | D42: =Обработка!$F$91 -> 0 | E42: =Обработка!$H$91 -> 0 | F42: =(C42+D42)*INDEX(Настройки!$B$10:$B$16,MATCH($B42,Настройки!$A$10:$A$16,0)) -> 0 | G42: =E42*INDEX(Настройки!$C$10:$C$16,MATCH($B42,Настройки!$A$10:$A$16,0)) -> 0 | H42: =E42*INDEX(Настройки!$D$10:$D$16,MATCH($B42,Настройки!$A$10:$A$16,0)) -> 0 | I42: =E42*INDEX(Настройки!$E$10:$E$16,MATCH($B42,Настройки!$A$10:$A$16,0)) -> 0 | J42: =SUM(F42:I42) -> 0
...

Sheet Мотивация
A1: PVZ.FLOW | Мотивация
A4: Дата | B4: Оператор | C4: Товар | D4: Приход | E4: Возврат | F4: Выбытие | G4: Приёмка | H4: Брендирование | I4: Упаковка | J4: Сборка | K4: Итого
A5: =Обработка!$A$54 -> 46279 | B5: =Обработка!$B$54 -> Пузанов Д.В. | C5: =Обработка!$C$54 -> АК-10 | D5: =Обработка!$E$54 -> 15 | E5: =Обработка!$F$54 -> 0 | F5: =Обработка!$H$54 -> 2 | G5: =(D5+E5)*INDEX(Настройки!$G$10:$G$16,MATCH($C5,Настройки!$A$10:$A$16,0)) -> 15 | H5: =F5*INDEX(Настройки!$H$10:$H$16,MATCH($C5,Настройки!$A$10:$A$16,0)) -> 6 | I5: =F5*INDEX(Настройки!$I$10:$I$16,MATCH($C5,Настройки!$A$10:$A$16,0)) -> 12 | J5: =F5*INDEX(Настройки!$J$10:$J$16,MATCH($C5,Настройки!$A$10:$A$16,0)) -> 6 | K5: =SUM(G5:J5) -> 39
A6: =Обработка!$A$55 -> 46279 | B6: =Обработка!$B$55 -> Пузанов Д.В. | C6: =Обработка!$C$55 -> АК-15 | D6: =Обработка!$E$55 -> 0 | E6: =Обработка!$F$55 -> 0 | F6: =Обработка!$H$55 -> 2 | G6: =(D6+E6)*INDEX(Настройки!$G$10:$G$16,MATCH($C6,Настройки!$A$10:$A$16,0)) -> 0 | H6: =F6*INDEX(Настройки!$H$10:$H$16,MATCH($C6,Настройки!$A$10:$A$16,0)) -> 6 | I6: =F6*INDEX(Настройки!$I$10:$I$16,MATCH($C6,Настройки!$A$10:$A$16,0)) -> 12 | J6: =F6*INDEX(Настройки!$J$10:$J$16,MATCH($C6,Настройки!$A$10:$A$16,0)) -> 6 | K6: =SUM(G6:J6) -> 24
A7: =Обработка!$A$56 -> 46279 | B7: =Обработка!$B$56 -> Пузанов Д.В. | C7: =Обработка!$C$56 -> Г 3500 | D7: =Обработка!$E$56 -> 14 | E7: =Обработка!$F$56 -> 0 | F7: =Обработка!$H$56 -> 0 | G7: =(D7+E7)*INDEX(Настройки!$G$10:$G$16,MATCH($C7,Настройки!$A$10:$A$16,0)) -> 42 | H7: =F7*INDEX(Настройки!$H$10:$H$16,MATCH($C7,Настройки!$A$10:$A$16,0)) -> 0 | I7: =F7*INDEX(Настройки!$I$10:$I$16,MATCH($C7,Настройки!$A$10:$A$16,0)) -> 0 | J7: =F7*INDEX(Настройки!$J$10:$J$16,MATCH($C7,Настройки!$A$10:$A$16,0)) -> 0 | K7: =SUM(G7:J7) -> 42
A8: =Обработка!$A$57 -> 46279 | B8: =Обработка!$B$57 -> Пузанов Д.В. | C8: =Обработка!$C$57 -> Г 1800 | D8: =Обработка!$E$57 -> 0 | E8: =Обработка!$F$57 -> 0 | F8: =Обработка!$H$57 -> 8 | G8: =(D8+E8)*INDEX(Настройки!$G$10:$G$16,MATCH($C8,Настройки!$A$10:$A$16,0)) -> 0 | H8: =F8*INDEX(Настройки!$H$10:$H$16,MATCH($C8,Настройки!$A$10:$A$16,0)) -> 32 | I8: =F8*INDEX(Настройки!$I$10:$I$16,MATCH($C8,Настройки!$A$10:$A$16,0)) -> 96 | J8: =F8*INDEX(Настройки!$J$10:$J$16,MATCH($C8,Настройки!$A$10:$A$16,0)) -> 56 | K8: =SUM(G8:J8) -> 184
A9: =Обработка!$A$58 -> 46279 | B9: =Обработка!$B$58 -> Пузанов Д.В. | C9: =Обработка!$C$58 -> Г 800 | D9: =Обработка!$E$58 -> 0 | E9: =Обработка!$F$58 -> 0 | F9: =Обработка!$H$58 -> 9 | G9: =(D9+E9)*INDEX(Настройки!$G$10:$G$16,MATCH($C9,Настройки!$A$10:$A$16,0)) -> 0 | H9: =F9*INDEX(Настройки!$H$10:$H$16,MATCH($C9,Настройки!$A$10:$A$16,0)) -> 36 | I9: =F9*INDEX(Настройки!$I$10:$I$16,MATCH($C9,Настройки!$A$10:$A$16,0)) -> 108 | J9: =F9*INDEX(Настройки!$J$10:$J$16,MATCH($C9,Настройки!$A$10:$A$16,0)) -> 63 | K9: =SUM(G9:J9) -> 207
A10: =Обработка!$A$59 -> 46279 | B10: =Обработка!$B$59 -> Пузанов Д.В. | C10: =Обработка!$C$59 -> Ми-К | D10: =Обработка!$E$59 -> 0 | E10: =Обработка!$F$59 -> 1 | F10: =Обработка!$H$59 -> 4 | G10: =(D10+E10)*INDEX(Настройки!$G$10:$G$16,MATCH($C10,Настройки!$A$10:$A$16,0)) -> 1 | H10: =F10*INDEX(Настройки!$H$10:$H$16,MATCH($C10,Настройки!$A$10:$A$16,0)) -> 8 | I10: =F10*INDEX(Настройки!$I$10:$I$16,MATCH($C10,Настройки!$A$10:$A$16,0)) -> 20 | J10: =F10*INDEX(Настройки!$J$10:$J$16,MATCH($C10,Настройки!$A$10:$A$16,0)) -> 20 | K10: =SUM(G10:J10) -> 49
A11: =Обработка!$A$60 -> 46279 | B11: =Обработка!$B$60 -> Пузанов Д.В. | C11: =Обработка!$C$60 -> Ми-П | D11: =Обработка!$E$60 -> 0 | E11: =Обработка!$F$60 -> 0 | F11: =Обработка!$H$60 -> 1 | G11: =(D11+E11)*INDEX(Настройки!$G$10:$G$16,MATCH($C11,Настройки!$A$10:$A$16,0)) -> 0 | H11: =F11*INDEX(Настройки!$H$10:$H$16,MATCH($C11,Настройки!$A$10:$A$16,0)) -> 2 | I11: =F11*INDEX(Настройки!$I$10:$I$16,MATCH($C11,Настройки!$A$10:$A$16,0)) -> 5 | J11: =F11*INDEX(Настройки!$J$10:$J$16,MATCH($C11,Настройки!$A$10:$A$16,0)) -> 5 | K11: =SUM(G11:J11) -> 12
A12: =Обработка!$A$61 -> 46280 | B12: =Обработка!$B$61 -> Завалишин Д.Л. | C12: =Обработка!$C$61 -> АК-10 | D12: =Обработка!$E$61 -> 0 | E12: =Обработка!$F$61 -> 0 | F12: =Обработка!$H$61 -> 0 | G12: =(D12+E12)*INDEX(Настройки!$G$10:$G$16,MATCH($C12,Настройки!$A$10:$A$16,0)) -> 0 | H12: =F12*INDEX(Настройки!$H$10:$H$16,MATCH($C12,Настройки!$A$10:$A$16,0)) -> 0 | I12: =F12*INDEX(Настройки!$I$10:$I$16,MATCH($C12,Настройки!$A$10:$A$16,0)) -> 0 | J12: =F12*INDEX(Настройки!$J$10:$J$16,MATCH($C12,Настройки!$A$10:$A$16,0)) -> 0 | K12: =SUM(G12:J12) -> 0
A13: =Обработка!$A$62 -> 46280 | B13: =Обработка!$B$62 -> Завалишин Д.Л. | C13: =Обработка!$C$62 -> АК-15 | D13: =Обработка!$E$62 -> 0 | E13: =Обработка!$F$62 -> 0 | F13: =Обработка!$H$62 -> 1 | G13: =(D13+E13)*INDEX(Настройки!$G$10:$G$16,MATCH($C13,Настройки!$A$10:$A$16,0)) -> 0 | H13: =F13*INDEX(Настройки!$H$10:$H$16,MATCH($C13,Настройки!$A$10:$A$16,0)) -> 3 | I13: =F13*INDEX(Настройки!$I$10:$I$16,MATCH($C13,Настройки!$A$10:$A$16,0)) -> 6 | J13: =F13*INDEX(Настройки!$J$10:$J$16,MATCH($C13,Настройки!$A$10:$A$16,0)) -> 3 | K13: =SUM(G13:J13) -> 12
A14: =Обработка!$A$63 -> 46280 | B14: =Обработка!$B$63 -> Завалишин Д.Л. | C14: =Обработка!$C$63 -> Г 3500 | D14: =Обработка!$E$63 -> 0 | E14: =Обработка!$F$63 -> 0 | F14: =Обработка!$H$63 -> 1 | G14: =(D14+E14)*INDEX(Настройки!$G$10:$G$16,MATCH($C14,Настройки!$A$10:$A$16,0)) -> 0 | H14: =F14*INDEX(Настройки!$H$10:$H$16,MATCH($C14,Настройки!$A$10:$A$16,0)) -> 6 | I14: =F14*INDEX(Настройки!$I$10:$I$16,MATCH($C14,Настройки!$A$10:$A$16,0)) -> 16 | J14: =F14*INDEX(Настройки!$J$10:$J$16,MATCH($C14,Настройки!$A$10:$A$16,0)) -> 12 | K14: =SUM(G14:J14) -> 34
