Workbook

Sheet 01_Справочник_Товары
A1: СПРАВОЧНИК ТОВАРОВ
A2: Артикул WB | B2: Код | C2: Название | D2: Вес, кг | E2: Объём, л | F2: Кол-во в ячейке | G2: Брендирование | H2: Вес-категория | I2: Хранение
A3: 1088614022 | B3: АК-10 | C3: Аккумулятор 10 | D3: 0.55 | E3: =12.5*9*8.3/1000 -> 0.93375 | F3: 42 | G3: да | H3: =IF(D3="","",IF(D3<=1,"до 1кг",IF(D3<=5,"1-5кг",IF(D3<=10,"5-10кг",">10кг")))) -> до 1кг | I3: =15/F3 -> 0.35714286
A4: 604564457 | B4: АК-15 | C4: Аккумулятор 15 | D4: 0.76 | E4: 0.93375 | F4: 42 | G4: да | H4: =IF(D4="","",IF(D4<=1,"до 1кг",IF(D4<=5,"1-5кг",IF(D4<=10,"5-10кг",">10кг")))) -> до 1кг | I4: =15/F4 -> 0.35714286
A5: 402395402 | B5: Г 1800 | C5: Гайковерт 1800 | D5: 5.12 | E5: 14.76 | F5: 2 | G5: да | H5: =IF(D5="","",IF(D5<=1,"до 1кг",IF(D5<=5,"1-5кг",IF(D5<=10,"5-10кг",">10кг")))) -> 5-10кг | I5: 5
A6: 548182523 | B6: Г 3500 | C6: Гайковерт 3500 | D6: 4.7 | E6: 14.76 | F6: 2 | G6: да | H6: =IF(D6="","",IF(D6<=1,"до 1кг",IF(D6<=5,"1-5кг",IF(D6<=10,"5-10кг",">10кг")))) -> 1-5кг | I6: 5
A7: 1006014419 | B7: Г 800 | C7: Гайковерт 800 | D7: 3.7 | E7: 12.768 | F7: 3 | G7: да | H7: =IF(D7="","",IF(D7<=1,"до 1кг",IF(D7<=5,"1-5кг",IF(D7<=10,"5-10кг",">10кг")))) -> 1-5кг | I7: 5
A8: 706101815 | B8: Ми-К | C8: Микрофон KMS-902MC | D8: 0.67 | E8: =30*19*6/1000 -> 3.42 | F8: =ROUNDDOWN(40/E8,0) -> 11 | G8: нет | H8: =IF(D8="","",IF(D8<=1,"до 1кг",IF(D8<=5,"1-5кг",IF(D8<=10,"5-10кг",">10кг")))) -> до 1кг | I8: =15/F8 -> 1.3636364
B9: Ми-П | C9: Петличный Микрофон | D9: 0.3 | E9: =12*9*4/1000 -> 0.432 | F9: =ROUNDDOWN(40/E9,0) -> 92 | G9: нет | H9: =IF(D9="","",IF(D9<=1,"до 1кг",IF(D9<=5,"1-5кг",IF(D9<=10,"5-10кг",">10кг")))) -> до 1кг | I9: =15/F9 -> 0.16304348

Sheet 02Тариф
A1: ТАРИФЫ НАЧИСЛЕНИЯ СЕЛЛЕРУ (₽/шт)
A2: Этап | B2: до 1кг | C2: 1-5кг | D2: 5-10кг | E2: >10кг | H2: Код | I2: Приемка | J2: Отправка | K2: Всего
A3: ПриёмкаПРЯМОЙ ПОТОК | B3: 10 | C3: 10 | D3: 10 | E3: 10 | H3: ='01_Справочник_Товары'!B3 -> АК-10 | I3: =B3 -> 10 | J3: =+B4+B5+B6 -> 40 | K3: =I3+J3 -> 50
A4: БрендПРЯМОЙ ПОТОК | B4: 10 | C4: 10 | D4: 15 | E4: 20 | H4: ='01_Справочник_Товары'!B4 -> АК-15 | I4: =B3 -> 10 | J4: =B4+B5+B6 -> 40 | K4: =I4+J4 -> 50
A5: УпаковкаПРЯМОЙ ПОТОК | B5: 20 | C5: 30 | D5: 35 | E5: 45 | H5: ='01_Справочник_Товары'!B5 -> Г 1800 | I5: =C3 -> 10 | J5: =C4+C5+C6 -> 55 | K5: =I5+J5 -> 65
A6: СборкаПРЯМОЙ ПОТОК | B6: 10 | C6: 15 | D6: 25 | E6: 30 | H6: ='01_Справочник_Товары'!B6 -> Г 3500 | I6: =D3 -> 10 | J6: =D4+D5+D6 -> 75 | K6: =I6+J6 -> 85
A7: ПриёмкаОБРАТНЫЙ ПОТОК | B7: 10 | C7: 10 | D7: 10 | E7: 10 | H7: ='01_Справочник_Товары'!B7 -> Г 800 | I7: =C3 -> 10 | J7: =C4+C5+C6 -> 55 | K7: =I7+J7 -> 65
A8: ПроверкаОБРАТНЫЙ ПОТОК | B8: 10 | C8: 15 | D8: 20 | E8: 25 | H8: ='01_Справочник_Товары'!B8 -> Ми-К | I8: =B3 -> 10 | J8: =B4+B6 -> 20 | K8: =I8+J8 -> 30
A9: РемонтОБРАТНЫЙ ПОТОК | B9: 30 | C9: 30 | D9: 35 | E9: 45 | H9: ='01_Справочник_Товары'!B9 -> Ми-П | I9: =B3 -> 10 | J9: =B4+B6 -> 20 | K9: =I9+J9 -> 30
A10: УпаковкаОБРАТНЫЙ ПОТОК | B10: 15 | C10: 15 | D10: 25 | E10: 30
A11: ВОЗВРАТ_СКЛАД | B11: 10 | C11: 10 | D11: 10 | E11: 10
A12: ВОЗВРАТ_РЕМОНТ | B12: 30 | C12: 30 | D12: 35 | E12: 45
A13: ВОЗВРАТ_СЕЛЛЕРУ | B13: 10 | C13: 10 | D13: 15 | E13: 15
A15: ТАРИФЫ МОТИВАЦИИ ПЕРСОНАЛУ (₽/шт)
A16: Этап | B16: до 1кг | C16: 1-5кг | D16: 5-10кг | E16: >10кг | H16: Код | I16: Приемка | J16: Отправка | K16: Всего
A17: ПриёмкаПРЯМОЙ ПОТОК | B17: 1 | C17: 2 | D17: 3 | E17: 2 | H17: ='01_Справочник_Товары'!B3 -> АК-10 | I17: =B17 -> 1 | J17: =+B18+B19+B20 -> 12 | K17: =I17+J17 -> 13
A18: БрендПРЯМОЙ ПОТОК | B18: 3 | C18: 5 | D18: 10 | E18: 10 | H18: ='01_Справочник_Товары'!B4 -> АК-15 | I18: =B17 -> 1 | J18: =B18+B19+B20 -> 12 | K18: =I18+J18 -> 13
A19: УпаковкаПРЯМОЙ ПОТОК | B19: 8 | C19: 16 | D19: 21 | E19: 25 | H19: ='01_Справочник_Товары'!B5 -> Г 1800 | I19: =C17 -> 2 | J19: =C18+C19+C20 -> 23 | K19: =I19+J19 -> 25
A20: СборкаПРЯМОЙ ПОТОК | B20: 1 | C20: 2 | D20: 3 | E20: 3 | H20: ='01_Справочник_Товары'!B6 -> Г 3500 | I20: =D17 -> 3 | J20: =D18+D19+D20 -> 34 | K20: =I20+J20 -> 37
A21: ПриёмкаОБРАТНЫЙ ПОТОК | B21: 1 | C21: 2 | D21: 3 | E21: 2 | H21: ='01_Справочник_Товары'!B7 -> Г 800 | I21: =C17 -> 2 | J21: =C18+C19+C20 -> 23 | K21: =I21+J21 -> 25
A22: ПроверкаОБРАТНЫЙ ПОТОК | B22: 5 | C22: 8 | D22: 13 | E22: 15 | H22: ='01_Справочник_Товары'!B8 -> Ми-К | I22: =B17 -> 1 | J22: =B18+B20 -> 4 | K22: =I22+J22 -> 5
A23: РемонтОБРАТНЫЙ ПОТОК | B23: 15 | C23: 15 | D23: 18 | E23: 20 | H23: ='01_Справочник_Товары'!B9 -> Ми-П | I23: =B17 -> 1 | J23: =B18+B20 -> 4 | K23: =I23+J23 -> 5
A24: УпаковкаОБРАТНЫЙ ПОТОК | B24: 9 | C24: 11 | D24: 13 | E24: 15
A25: ВОЗВРАТ_СКЛАД | B25: 1 | C25: 2 | D25: 3 | E25: 2
A26: ВОЗВРАТ_РЕМОНТ | B26: 15 | C26: 15 | D26: 18 | E26: 20
A27: ВОЗВРАТ_СЕЛЛЕРУ | B27: 3 | C27: 4 | D27: 5 | E27: 5
A29: КОФФИЦИЕНТ ПЕРЕВОДА
A30: Этап | B30: до 1кг | C30: 1-5кг | D30: 5-10кг | E30: >10кг
A31: ПриёмкаПРЯМОЙ ПОТОК | B31: =B17/B3 -> 0.1 | C31: =C17/C3 -> 0.2 | D31: =D17/D3 -> 0.3 | E31: =E17/E3 -> 0.2
A32: БрендПРЯМОЙ ПОТОК | B32: =B18/B4 -> 0.3 | C32: =C18/C4 -> 0.5 | D32: =D18/D4 -> 0.66666667 | E32: =E18/E4 -> 0.5
A33: УпаковкаПРЯМОЙ ПОТОК | B33: =B19/B5 -> 0.4 | C33: =C19/C5 -> 0.53333333 | D33: =D19/D5 -> 0.6 | E33: =E19/E5 -> 0.55555556
A34: СборкаПРЯМОЙ ПОТОК | B34: =B20/B6 -> 0.1 | C34: =C20/C6 -> 0.13333333 | D34: =D20/D6 -> 0.12 | E34: =E20/E6 -> 0.1
A35: ПриёмкаОБРАТНЫЙ ПОТОК | B35: =B21/B7 -> 0.1 | C35: =C21/C7 -> 0.2 | D35: =D21/D7 -> 0.3 | E35: =E21/E7 -> 0.2
A36: ПроверкаОБРАТНЫЙ ПОТОК | B36: =B22/B8 -> 0.5 | C36: =C22/C8 -> 0.53333333 | D36: =D22/D8 -> 0.65 | E36: =E22/E8 -> 0.6
A37: РемонтОБРАТНЫЙ ПОТОК | B37: =B23/B9 -> 0.5 | C37: =C23/C9 -> 0.5 | D37: =D23/D9 -> 0.51428571 | E37: =E23/E9 -> 0.44444444
A38: УпаковкаОБРАТНЫЙ ПОТОК | B38: =B24/B10 -> 0.6 | C38: =C24/C10 -> 0.73333333 | D38: =D24/D10 -> 0.52 | E38: =E24/E10 -> 0.5
A39: ВОЗВРАТ_СКЛАД | B39: =B25/B11 -> 0.1 | C39: =C25/C11 -> 0.2 | D39: =D25/D11 -> 0.3 | E39: =E25/E11 -> 0.2
A40: ВОЗВРАТ_РЕМОНТ | B40: =B26/B12 -> 0.5 | C40: =C26/C12 -> 0.5 | D40: =D26/D12 -> 0.51428571 | E40: =E26/E12 -> 0.44444444
A41: ВОЗВРАТ_СЕЛЛЕРУ | B41: =B27/B13 -> 0.3 | C41: =C27/C13 -> 0.4 | D41: =D27/D13 -> 0.33333333 | E41: =E27/E13 -> 0.33333333

Sheet Motivation
A1: Дата | B1: Товар | C1: Приход | D1: Убытие | E1: Тариф приемки | F1: Тариф отправки | G1: Приемка, руб | H1: Отправка, руб | I1: ИТОГО, руб | J1: Оператор
A2: 46241 | B2: Ми-К | C2: 10 | D2: 0 | E2: 1 | F2: 12 | G2: 10 | H2: 0 | I2: 10
A3: 46242 | B3: Г 1800 | C3: 9 | D3: 0 | E3: 2 | F3: 23 | G3: 18 | H3: 0 | I3: 18
A4: 46242 | B4: Г 3500 | C4: 2 | D4: 2 | E4: 3 | F4: 34 | G4: 6 | H4: 68 | I4: 74
A5: 46242 | B5: Ми-К | C5: 0 | D5: 3 | E5: 1 | F5: 12 | G5: 0 | H5: 36 | I5: 36
A6: 46243 | B6: Г 1800 | C6: 10 | D6: 0 | E6: 2 | F6: 23 | G6: 20 | H6: 0 | I6: 20
A7: 46243 | B7: Г 3500 | C7: 2 | D7: 0 | E7: 3 | F7: 34 | G7: 6 | H7: 0 | I7: 6
A8: 46243 | B8: Ми-К | C8: 10 | D8: 5 | E8: 1 | F8: 12 | G8: 10 | H8: 60 | I8: 70
A9: 46244 | B9: Г 1800 | C9: 0 | D9: 6 | E9: 2 | F9: 23 | G9: 0 | H9: 138 | I9: 138
A10: 46244 | B10: Г 3500 | C10: 0 | D10: 2 | E10: 3 | F10: 34 | G10: 0 | H10: 68 | I10: 68
A11: 46244 | B11: Ми-К | C11: 0 | D11: 2 | E11: 1 | F11: 12 | G11: 0 | H11: 24 | I11: 24
A12: 46245 | B12: Г 1800 | C12: 0 | D12: 2 | E12: 2 | F12: 23 | G12: 0 | H12: 46 | I12: 46
A13: 46245 | B13: Г 3500 | C13: 10 | D13: 3 | E13: 3 | F13: 34 | G13: 30 | H13: 102 | I13: 132
... A121: 46271 | B121: Г 800 | C121: 0 | D121: 10 | E121: 2 | F121: 23 | G121: 0 | H121: 230 | I121: 230
A124: 46273 | B124: АК-10 | C124: 0 | D124: 1 | E124: 1 | F124: 12 | G124: 0 | H124: 12 | I124: 12 | J124: Завалишин Д.Л.
A125: 46273 | B125: АК-15 | C125: 0 | D125: 1 | E125: 1 | F125: 12 | G125: 0 | H125: 12 | I125: 12 | J125: Завалишин Д.Л.
A126: 46273 | B126: Г 1800 | C126: 0 | D126: 11 | E126: 2 | F126: 23 | G126: 0 | H126: 253 | I126: 253 | J126: Завалишин Д.Л.
A127: 46273 | B127: Г 800 | C127: 0 | D127: 3 | E127: 2 | F127: 23 | G127: 0 | H127: 69 | I127: 69 | J127: Завалишин Д.Л.
A128: 46274 | B128: АК-15 | C128: 0 | D128: 1 | E128: 1 | F128: 12 | G128: 0 | H128: 12 | I128: 12 | J128: Завалишин Д.Л.
A129: 46274 | B129: Г 1800 | C129: 0 | D129: 8 | E129: 2 | F129: 23 | G129: 0 | H129: 184 | I129: 184 | J129: Завалишин Д.Л.
A130: 46274 | B130: Г 800 | C130: 0 | D130: 5 | E130: 2 | F130: 23 | G130: 0 | H130: 115 | I130: 115 | J130: Завалишин Д.Л.
A131: 46274 | B131: Ми-К | C131: 0 | D131: 1 | E131: 1 | F131: 12 | G131: 0 | H131: 12 | I131: 12 | J131: Завалишин Д.Л.
A132: 46275 | B132: АК-15 | C132: 10 | D132: 0 | E132: 1 | F132: 12 | G132: 10 | H132: 0 | I132: 10 | J132: Завалишин Д.Л.
A133: 46275 | B133: Г 1800 | C133: 129 | D133: 10 | E133: 2 | F133: 23 | G133: 258 | H133: 230 | I133: 488 | J133: Завалишин Д.Л.
A134: 46275 | B134: Г 3500 | C134: 2 | D134: 0 | E134: 3 | F134: 34 | G134: 6 | H134: 0 | I134: 6 | J134: Завалишин Д.Л.
A135: 46275 | B135: Г 800 | C135: 0 | D135: 8 | E135: 2 | F135: 23 | G135: 0 | H135: 184 | I135: 184 | J135: Завалишин Д.Л.
... A149: 46278 | B149: Г 800 | C149: 0 | D149: 4 | E149: 2 | F149: 23 | G149: 0 | H149: 92 | I149: 92 | J149: Завалишин Д.Л.
I150: =SUM(I124:I149) -> 2131 | K150: =I150-300 -> 1831
A152: 46272 | B152: Г 1800 | C152: 3 | D152: 3 | E152: 2 | F152: 23 | G152: 6 | H152: 69 | I152: 75 | J152: Пузанов Д.В.
A153: 46272 | B153: Г 800 | C153: 2 | D153: 2 | E153: 2 | F153: 23 | G153: 4 | H153: 46 | I153: 50 | J153: Пузанов Д.В.
A154: 46272 | B154: Ми-К | C154: 1 | D154: 1 | E154: 1 | F154: 12 | G154: 1 | H154: 12 | I154: 13 | J154: Пузанов Д.В.
A155: 46276 | B155: АК-10 | C155: 0 | D155: 5 | E155: 1 | F155: 12 | G155: 0 | H155: 60 | I155: 60 | J155: Пузанов Д.В.
A156: 46276 | B156: АК-15 | C156: 0 | D156: 2 | E156: 1 | F156: 12 | G156: 0 | H156: 24 | I156: 24 | J156: Пузанов Д.В.
A157: 46276 | B157: Г 1800 | C157: 0 | D157: 12 | E157: 2 | F157: 23 | G157: 0 | H157: 276 | I157: 276 | J157: Пузанов Д.В.
A158: 46276 | B158: Г 3500 | C158: 0 | D158: 2 | E158: 3 | F158: 34 | G158: 0 | H158: 68 | I158: 68 | J158: Пузанов Д.В.
A159: 46276 | B159: Г 800 | C159: 64 | D159: 4 | E159: 2 | F159: 23 | G159: 128 | H159: 92 | I159: 220 | J159: Пузанов Д.В.
A160: 46276 | B160: Ми-К | C160: 0 | D160: 6 | E160: 1 | F160: 12 | G160: 0 | H160: 72 | I160: 72 | J160: Пузанов Д.В.
A161: 46276 | B161: Ми-П | C161: 0 | D161: 1 | E161: 1 | F161: 12 | G161: 0 | H161: 12 | I161: 12 | J161: Пузанов Д.В.
H162: ИТОГО: | I162: =SUM(I152:I161) -> 870

Sheet 05Движение
A1: ДВИЖЕНИЕ ТОВАРА
A2: Прибытие / Убытие. Остаток на конец = начало + приход – уход.
A3: Дата | B3: Код | C3: Остаток начало | D3: Прибытие | E3: Убытие | F3: Остаток конец
A4: 46272 | B4: Ak10 | C4: 18 | D4: 0 | E4: 0 | F4: =C4+D4-E4 -> 18
A5: 46272 | B5: Ak15 | C5: 24 | D5: 0 | E5: 0 | F5: =C5+D5-E5 -> 24
A6: 46272 | B6: G1800 | C6: 66 | D6: 3 | E6: 3 | F6: =C6+D6-E6 -> 66
A7: 46272 | B7: G3500 | C7: 3 | D7: 0 | E7: 0 | F7: =C7+D7-E7 -> 3
A8: 46272 | B8: G800 | C8: 39 | D8: 2 | E8: 2 | F8: =C8+D8-E8 -> 39
A9: 46272 | B9: MiK | C9: 17 | D9: 1 | E9: 1 | F9: =C9+D9-E9 -> 17
A10: 46272 | B10: MiP | C10: 0 | D10: 0 | E10: 0 | F10: =C10+D10-E10 -> 0
A11: ПН | B11: Пузанов Д.В. | C11: =SUM(C4:C10) -> 167 | D11: =SUM(D4:D10) -> 6 | E11: =SUM(E4:E10) -> 6 | F11: =SUM(F4:F10) -> 167
A13: 46273 | B13: Ak10 | C13: =F4 -> 18 | D13: 0 | E13: 1 | F13: =C13+D13-E13 -> 17
A14: 46273 | B14: Ak15 | C14: =F5 -> 24 | D14: 0 | E14: 1 | F14: =C14+D14-E14 -> 23
A15: 46273 | B15: G1800 | C15: =F6 -> 66 | D15: 0 | E15: 11 | F15: =C15+D15-E15 -> 55
A16: 46273 | B16: G3500 | C16: =F7 -> 3 | D16: 0 | E16: 0 | F16: =C16+D16-E16 -> 3
A17: 46273 | B17: G800 | C17: =F8 -> 39 | D17: 0 | E17: 3 | F17: =C17+D17-E17 -> 36
A18: 46273 | B18: MiK | C18: =F9 -> 17 | D18: 0 | E18: 0 | F18: =C18+D18-E18 -> 17
A19: 46273 | B19: MiP | C19: =F10 -> 0 | D19: 0 | E19: 0 | F19: =C19+D19-E19 -> 0
A20: ВТ | B20: Завалишин Д.Л. | C20: =SUM(C13:C19) -> 167 | D20: =SUM(D13:D19) -> 0 | E20: =SUM(E13:E19) -> 16 | F20: =SUM(F13:F19) -> 151
A22: 46274 | B22: Ak10 | C22: =F13 -> 17 | D22: 0 | E22: 0 | F22: =C22+D22-E22 -> 17
A23: 46274 | B23: Ak15 | C23: =F14 -> 23 | D23: 0 | E23: 1 | F23: =C23+D23-E23 -> 22
A24: 46274 | B24: G1800 | C24: =F15 -> 55 | D24: 0 | E24: 8 | F24: =C24+D24-E24 -> 47
A25: 46274 | B25: G3500 | C25: =F16 -> 3 | D25: 0 | E25: 0 | F25: =C25+D25-E25 -> 3
A26: 46274 | B26: G800 | C26: =F17 -> 36 | D26: 0 | E26: 5 | F26: =C26+D26-E26 -> 31
A27: 46274 | B27: MiK | C27: =F18 -> 17 | D27: 0 | E27: 1 | F27: =C27+D27-E27 -> 16
A28: 46274 | B28: MiP | C28: =F19 -> 0 | D28: 0 | E28: 0 | F28: =C28+D28-E28 -> 0
A29: СР | B29: Завалишин Д.Л. | C29: =SUM(C22:C28) -> 151 | D29: =SUM(D22:D28) -> 0 | E29: =SUM(E22:E28) -> 15 | F29: =SUM(F22:F28) -> 136
A31: 46275 | B31: Ak10 | C31: =F22 -> 17 | D31: 0 | E31: 0 | F31: =C31+D31-E31 -> 17
A32: 46275 | B32: Ak15 | C32: =F23 -> 22 | D32: 10 | E32: 0 | F32: =C32+D32-E32 -> 32
A33: 46275 | B33: G1800 | C33: =F24 -> 47 | D33: 129 | E33: 10 | F33: =C33+D33-E33 -> 166
A34: 46275 | B34: G3500 | C34: =F25 -> 3 | D34: 2 | E34: 0 | F34: =C34+D34-E34 -> 5
A35: 46275 | B35: G800 | C35: =F26 -> 31 | D35: 0 | E35: 8 | F35: =C35+D35-E35 -> 23
A36: 46275 | B36: MiK | C36: =F27 -> 16 | D36: 10 | E36: 1 | F36: =C36+D36-E36 -> 25
A37: 46275 | B37: MiP | C37: =F28 -> 0 | D37: 27 | E37: 1 | F37: =C37+D37-E37 -> 26
A38: ЧТ | B38: Завалишин Д.Л. | C38: =SUM(C31:C37) -> 136 | D38: =SUM(D31:D37) -> 178 | E38: =SUM(E31:E37) -> 20 | F38: =SUM(F31:F37) -> 294
A40: 46276 | B40: Ak10 | C40: =F31 -> 17 | D40: 0 | E40: 5 | F40: =C40+D40-E40 -> 12
A41: 46276 | B41: Ak15 | C41: =F32 -> 32 | D41: 0 | E41: 2 | F41: =C41+D41-E41 -> 30
A42: 46276 | B42: G1800 | C42: =F33 -> 166 | D42: 0 | E42: 12 | F42: =C42+D42-E42 -> 154
A43: 46276 | B43: G3500 | C43: =F34 -> 5 | D43: 0 | E43: 2 | F43: =C43+D43-E43 -> 3
A44: 46276 | B44: G800 | C44: =F35 -> 23 | D44: 64 | E44: 4 | F44: =C44+D44-E44 -> 83
...

Sheet 06НачисленияДни
A1: НАЧИСЛЕНИЯ ЗА ФУЛФИЛМЕНТ
A2: В сборку входят: брендирование, упаковка и выдача
A3: Дата | B3: Код | C3: Приемка | D3: Отправка | E3: ИТОГО
A4: ='05Движение'!A4 -> 46272 | B4: ='05Движение'!B4 -> Ak10 | C4: =IF('05Движение'!D4>0,'05Движение'!D4*'02Тариф'!$B$3,0) -> 0 | D4: =IF('05Движение'!E4>0,'05Движение'!E4*('02Тариф'!$B$4+'02Тариф'!$B$5+'02Тариф'!$B$6),0) -> 0 | E4: =C4+D4 -> 0
A5: ='05Движение'!A5 -> 46272 | B5: ='05Движение'!B5 -> Ak15 | C5: =IF('05Движение'!D5>0,'05Движение'!D5*'02Тариф'!$B$3,0) -> 0 | D5: =IF('05Движение'!E5>0,'05Движение'!E5*('02Тариф'!$B$4+'02Тариф'!$B$5+'02Тариф'!$B$6),0) -> 0 | E5: =SUM(C5:D5) -> 0
A6: ='05Движение'!A6 -> 46272 | B6: ='05Движение'!B6 -> G1800 | C6: =IF('05Движение'!D6>0,'05Движение'!D6*'02Тариф'!$D$3,0) -> 30 | D6: =IF('05Движение'!E6>0,'05Движение'!E6*('02Тариф'!$D$4+'02Тариф'!$D$5+'02Тариф'!$D$6),0) -> 225 | E6: =SUM(C6:D6) -> 255
A7: ='05Движение'!A7 -> 46272 | B7: ='05Движение'!B7 -> G3500 | C7: =IF('05Движение'!D7>0,'05Движение'!D7*'02Тариф'!$C$3,0) -> 0 | D7: =IF('05Движение'!E7>0,'05Движение'!E7*('02Тариф'!$C$4+'02Тариф'!$C$5+'02Тариф'!$C$6),0) -> 0 | E7: =SUM(C7:D7) -> 0
A8: ='05Движение'!A8 -> 46272 | B8: ='05Движение'!B8 -> G800 | C8: =IF('05Движение'!D8>0,'05Движение'!D8*'02Тариф'!$C$3,0) -> 20 | D8: =IF('05Движение'!E8>0,'05Движение'!E8*('02Тариф'!$C$4+'02Тариф'!$C$5+'02Тариф'!$C$6),0) -> 110 | E8: =SUM(C8:D8) -> 130
A9: ='05Движение'!A9 -> 46272 | B9: ='05Движение'!B9 -> MiK | C9: =IF('05Движение'!D9>0,'05Движение'!D9*'02Тариф'!$B$3,0) -> 10 | D9: =IF('05Движение'!E9>0,'05Движение'!E9*('02Тариф'!$B$5+'02Тариф'!$B$6),0) -> 30 | E9: =SUM(C9:D9) -> 40
A10: ='05Движение'!A10 -> 46272 | B10: ='05Движение'!B10 -> MiP | C10: =IF('05Движение'!D10>0,'05Движение'!D10*'02Тариф'!$B$3,0) -> 0 | D10: =IF('05Движение'!E10>0,'05Движение'!E10*('02Тариф'!$B$5+'02Тариф'!$B$6),0) -> 0 | E10: =SUM(C10:D10) -> 0
A11: ='05Движение'!A11 -> ПН | B11: ='05Движение'!B11 -> Пузанов Д.В. | C11: =SUM(C4:C10) -> 60 | D11: =SUM(D4:D10) -> 365 | E11: =SUM(E4:E10) -> 425
A13: ='05Движение'!A13 -> 46273 | B13: ='05Движение'!B13 -> Ak10 | C13: =IF('05Движение'!D13>0,'05Движение'!D13*'02Тариф'!$B$3,0) -> 0 | D13: =IF('05Движение'!E13>0,'05Движение'!E13*('02Тариф'!$B$4+'02Тариф'!$B$5+'02Тариф'!$B$6),0) -> 40 | E13: =C13+D13 -> 40
A14: ='05Движение'!A14 -> 46273 | B14: ='05Движение'!B14 -> Ak15 | C14: =IF('05Движение'!D14>0,'05Движение'!D14*'02Тариф'!$B$3,0) -> 0 | D14: =IF('05Движение'!E14>0,'05Движение'!E14*('02Тариф'!$B$4+'02Тариф'!$B$5+'02Тариф'!$B$6),0) -> 40 | E14: =SUM(C14:D14) -> 40
A15: ='05Движение'!A15 -> 46273 | B15: ='05Движение'!B15 -> G1800 | C15: =IF('05Движение'!D15>0,'05Движение'!D15*'02Тариф'!$D$3,0) -> 0 | D15: =IF('05Движение'!E15>0,'05Движение'!E15*('02Тариф'!$D$4+'02Тариф'!$D$5+'02Тариф'!$D$6),0) -> 825 | E15: =SUM(C15:D15) -> 825
A16: ='05Движение'!A16 -> 46273 | B16: ='05Движение'!B16 -> G3500 | C16: =IF('05Движение'!D16>0,'05Движение'!D16*'02Тариф'!$C$3,0) -> 0 | D16: =IF('05Движение'!E16>0,'05Движение'!E16*('02Тариф'!$C$4+'02Тариф'!$C$5+'02Тариф'!$C$6),0) -> 0 | E16: =SUM(C16:D16) -> 0
A17: ='05Движение'!A17 -> 46273 | B17: ='05Движение'!B17 -> G800 | C17: =IF('05Движение'!D17>0,'05Движение'!D17*'02Тариф'!$C$3,0) -> 0 | D17: =IF('05Движение'!E17>0,'05Движение'!E17*('02Тариф'!$C$4+'02Тариф'!$C$5+'02Тариф'!$C$6),0) -> 165 | E17: =SUM(C17:D17) -> 165
A18: ='05Движение'!A18 -> 46273 | B18: ='05Движение'!B18 -> MiK | C18: =IF('05Движение'!D18>0,'05Движение'!D18*'02Тариф'!$B$3,0) -> 0 | D18: =IF('05Движение'!E18>0,'05Движение'!E18*('02Тариф'!$B$5+'02Тариф'!$B$6),0) -> 0 | E18: =SUM(C18:D18) -> 0
A19: ='05Движение'!A19 -> 46273 | B19: ='05Движение'!B19 -> MiP | C19: =IF('05Движение'!D19>0,'05Движение'!D19*'02Тариф'!$B$3,0) -> 0 | D19: =IF('05Движение'!E19>0,'05Движение'!E19*('02Тариф'!$B$5+'02Тариф'!$B$6),0) -> 0 | E19: =SUM(C19:D19) -> 0
A20: ='05Движение'!A20 -> ВТ | B20: Завалишин Д.Л. | C20: =SUM(C13:C19) -> 0 | D20: =SUM(D13:D19) -> 1070 | E20: =SUM(E13:E19) -> 1070
A22: ='05Движение'!A22 -> 46274 | B22: ='05Движение'!B22 -> Ak10 | C22: =IF('05Движение'!D22>0,'05Движение'!D22*'02Тариф'!$B$3,0) -> 0 | D22: =IF('05Движение'!E22>0,'05Движение'!E22*('02Тариф'!$B$4+'02Тариф'!$B$5+'02Тариф'!$B$6),0) -> 0 | E22: =C22+D22 -> 0
A23: ='05Движение'!A23 -> 46274 | B23: ='05Движение'!B23 -> Ak15 | C23: =IF('05Движение'!D23>0,'05Движение'!D23*'02Тариф'!$B$3,0) -> 0 | D23: =IF('05Движение'!E23>0,'05Движение'!E23*('02Тариф'!$B$4+'02Тариф'!$B$5+'02Тариф'!$B$6),0) -> 40 | E23: =SUM(C23:D23) -> 40
A24: ='05Движение'!A24 -> 46274 | B24: ='05Движение'!B24 -> G1800 | C24: =IF('05Движение'!D24>0,'05Движение'!D24*'02Тариф'!$D$3,0) -> 0 | D24: =IF('05Движение'!E24>0,'05Движение'!E24*('02Тариф'!$D$4+'02Тариф'!$D$5+'02Тариф'!$D$6),0) -> 600 | E24: =SUM(C24:D24) -> 600
A25: ='05Движение'!A25 -> 46274 | B25: ='05Движение'!B25 -> G3500 | C25: =IF('05Движение'!D25>0,'05Движение'!D25*'02Тариф'!$C$3,0) -> 0 | D25: =IF('05Движение'!E25>0,'05Движение'!E25*('02Тариф'!$C$4+'02Тариф'!$C$5+'02Тариф'!$C$6),0) -> 0 | E25: =SUM(C25:D25) -> 0
A26: ='05Движение'!A26 -> 46274 | B26: ='05Движение'!B26 -> G800 | C26: =IF('05Движение'!D26>0,'05Движение'!D26*'02Тариф'!$C$3,0) -> 0 | D26: =IF('05Движение'!E26>0,'05Движение'!E26*('02Тариф'!$C$4+'02Тариф'!$C$5+'02Тариф'!$C$6),0) -> 275 | E26: =SUM(C26:D26) -> 275
A27: ='05Движение'!A27 -> 46274 | B27: ='05Движение'!B27 -> MiK | C27: =IF('05Движение'!D27>0,'05Движение'!D27*'02Тариф'!$B$3,0) -> 0 | D27: =IF('05Движение'!E27>0,'05Движение'!E27*('02Тариф'!$B$5+'02Тариф'!$B$6),0) -> 30 | E27: =SUM(C27:D27) -> 30
A28: ='05Движение'!A28 -> 46274 | B28: ='05Движение'!B28 -> MiP | C28: =IF('05Движение'!D28>0,'05Движение'!D28*'02Тариф'!$B$3,0) -> 0 | D28: =IF('05Движение'!E28>0,'05Движение'!E28*('02Тариф'!$B$5+'02Тариф'!$B$6),0) -> 0 | E28: =SUM(C28:D28) -> 0
A29: ='05Движение'!A29 -> СР | B29: Завалишин Д.Л. | C29: =SUM(C22:C28) -> 0 | D29: =SUM(D22:D28) -> 945 | E29: =SUM(E22:E28) -> 945
A31: ='05Движение'!A31 -> 46275 | B31: ='05Движение'!B31 -> Ak10 | C31: =IF('05Движение'!D31>0,'05Движение'!D31*'02Тариф'!$B$3,0) -> 0 | D31: =IF('05Движение'!E31>0,'05Движение'!E31*('02Тариф'!$B$4+'02Тариф'!$B$5+'02Тариф'!$B$6),0) -> 0 | E31: =C31+D31 -> 0
A32: ='05Движение'!A32 -> 46275 | B32: ='05Движение'!B32 -> Ak15 | C32: =IF('05Движение'!D32>0,'05Движение'!D32*'02Тариф'!$B$3,0) -> 100 | D32: =IF('05Движение'!E32>0,'05Движение'!E32*('02Тариф'!$B$4+'02Тариф'!$B$5+'02Тариф'!$B$6),0) -> 0 | E32: =SUM(C32:D32) -> 100
A33: ='05Движение'!A33 -> 46275 | B33: ='05Движение'!B33 -> G1800 | C33: =IF('05Движение'!D33>0,'05Движение'!D33*'02Тариф'!$D$3,0) -> 1290 | D33: =IF('05Движение'!E33>0,'05Движение'!E33*('02Тариф'!$D$4+'02Тариф'!$D$5+'02Тариф'!$D$6),0) -> 750 | E33: =SUM(C33:D33) -> 2040
A34: ='05Движение'!A34 -> 46275 | B34: ='05Движение'!B34 -> G3500 | C34: =IF('05Движение'!D34>0,'05Движение'!D34*'02Тариф'!$C$3,0) -> 20 | D34: =IF('05Движение'!E34>0,'05Движение'!E34*('02Тариф'!$C$4+'02Тариф'!$C$5+'02Тариф'!$C$6),0) -> 0 | E34: =SUM(C34:D34) -> 20
A35: ='05Движение'!A35 -> 46275 | B35: ='05Движение'!B35 -> G800 | C35: =IF('05Движение'!D35>0,'05Движение'!D35*'02Тариф'!$C$3,0) -> 0 | D35: =IF('05Движение'!E35>0,'05Движение'!E35*('02Тариф'!$C$4+'02Тариф'!$C$5+'02Тариф'!$C$6),0) -> 440 | E35: =SUM(C35:D35) -> 440
A36: ='05Движение'!A36 -> 46275 | B36: ='05Движение'!B36 -> MiK | C36: =IF('05Движение'!D36>0,'05Движение'!D36*'02Тариф'!$B$3,0) -> 100 | D36: =IF('05Движение'!E36>0,'05Движение'!E36*('02Тариф'!$B$5+'02Тариф'!$B$6),0) -> 30 | E36: =SUM(C36:D36) -> 130
A37: ='05Движение'!A37 -> 46275 | B37: ='05Движение'!B37 -> MiP | C37: =IF('05Движение'!D37>0,'05Движение'!D37*'02Тариф'!$B$3,0) -> 270 | D37: =IF('05Движение'!E37>0,'05Движение'!E37*('02Тариф'!$B$5+'02Тариф'!$B$6),0) -> 30 | E37: =SUM(C37:D37) -> 300
A38: ='05Движение'!A38 -> ЧТ | B38: Завалишин Д.Л. | C38: =SUM(C31:C37) -> 1780 | D38: =SUM(D31:D37) -> 1250 | E38: =SUM(E31:E37) -> 3030
A40: ='05Движение'!A40 -> 46276 | B40: ='05Движение'!B40 -> Ak10 | C40: =IF('05Движение'!D40>0,'05Движение'!D40*'02Тариф'!$B$3,0) -> 0 | D40: =IF('05Движение'!E40>0,'05Движение'!E40*('02Тариф'!$B$4+'02Тариф'!$B$5+'02Тариф'!$B$6),0) -> 200 | E40: =C40+D40 -> 200
A41: ='05Движение'!A41 -> 46276 | B41: ='05Движение'!B41 -> Ak15 | C41: =IF('05Движение'!D41>0,'05Движение'!D41*'02Тариф'!$B$3,0) -> 0 | D41: =IF('05Движение'!E41>0,'05Движение'!E41*('02Тариф'!$B$4+'02Тариф'!$B$5+'02Тариф'!$B$6),0) -> 80 | E41: =SUM(C41:D41) -> 80
A42: ='05Движение'!A42 -> 46276 | B42: ='05Движение'!B42 -> G1800 | C42: =IF('05Движение'!D42>0,'05Движение'!D42*'02Тариф'!$D$3,0) -> 0 | D42: =IF('05Движение'!E42>0,'05Движение'!E42*('02Тариф'!$D$4+'02Тариф'!$D$5+'02Тариф'!$D$6),0) -> 900 | E42: =SUM(C42:D42) -> 900
A43: ='05Движение'!A43 -> 46276 | B43: ='05Движение'!B43 -> G3500 | C43: =IF('05Движение'!D43>0,'05Движение'!D43*'02Тариф'!$C$3,0) -> 0 | D43: =IF('05Движение'!E43>0,'05Движение'!E43*('02Тариф'!$C$4+'02Тариф'!$C$5+'02Тариф'!$C$6),0) -> 110 | E43: =SUM(C43:D43) -> 110
A44: ='05Движение'!A44 -> 46276 | B44: ='05Движение'!B44 -> G800 | C44: =IF('05Движение'!D44>0,'05Движение'!D44*'02Тариф'!$C$3,0) -> 640 | D44: =IF('05Движение'!E44>0,'05Движение'!E44*('02Тариф'!$C$4+'02Тариф'!$C$5+'02Тариф'!$C$6),0) -> 220 | E44: =SUM(C44:D44) -> 860
...

Sheet 07НачисленияАртикул
A1: НАЧИСЛЕНИЯ СЕЛЛЕРУ
A2: Автоматический расчёт. Не вводите данные сюда — только в Журнал.
A3: Дата | B3: Артикул | C3: Приемка | D3: Отправка | E3: Сумма
A4: ='06НачисленияДни'!A4 -> 46272 | B4: ='06НачисленияДни'!B4 -> Ak10 | C4: ='06НачисленияДни'!C4 -> 0 | D4: ='06НачисленияДни'!D4 -> 0 | E4: =C4+D4 -> 0
A5: ='06НачисленияДни'!A13 -> 46273 | B5: ='06НачисленияДни'!B13 -> Ak10 | C5: ='06НачисленияДни'!C13 -> 0 | D5: ='06НачисленияДни'!D13 -> 40 | E5: =C5+D5 -> 40
A6: ='06НачисленияДни'!A22 -> 46274 | B6: ='06НачисленияДни'!B22 -> Ak10 | C6: ='06НачисленияДни'!C22 -> 0 | D6: ='06НачисленияДни'!D22 -> 0 | E6: =SUM(C6:D6) -> 0
A7: ='06НачисленияДни'!A31 -> 46275 | B7: ='06НачисленияДни'!B31 -> Ak10 | C7: ='06НачисленияДни'!C31 -> 0 | D7: ='06НачисленияДни'!D31 -> 0 | E7: =C7+D7 -> 0
A8: ='06НачисленияДни'!A40 -> 46276 | B8: ='06НачисленияДни'!B40 -> Ak10 | C8: ='06НачисленияДни'!C40 -> 0 | D8: ='06НачисленияДни'!D40 -> 200 | E8: =SUM(C8:D8) -> 200
A9: ='06НачисленияДни'!A49 -> 46277 | B9: ='06НачисленияДни'!B49 -> Ak10 | C9: ='06НачисленияДни'!C49 -> 0 | D9: ='06НачисленияДни'!D49 -> 40 | E9: =C9+D9 -> 40
A10: ='06НачисленияДни'!A58 -> 46278 | B10: ='06НачисленияДни'!B58 -> Ak10 | C10: ='06НачисленияДни'!C58 -> 0 | D10: ='06НачисленияДни'!D58 -> 160 | E10: =SUM(C10:D10) -> 160
B11: ИТОГО | C11: =SUM(C4:C10) -> 0 | D11: =SUM(D4:D10) -> 440 | E11: =SUM(E4:E10) -> 440
A13: ='06НачисленияДни'!A5 -> 46272 | B13: ='06НачисленияДни'!B5 -> Ak15 | C13: ='06НачисленияДни'!C5 -> 0 | D13: ='06НачисленияДни'!D5 -> 0 | E13: =C13+D13 -> 0
A14: ='06НачисленияДни'!A14 -> 46273 | B14: ='06НачисленияДни'!B14 -> Ak15 | C14: ='06НачисленияДни'!C14 -> 0 | D14: ='06НачисленияДни'!D14 -> 40 | E14: =C14+D14 -> 40
A15: =A6 -> 46274 | B15: ='06НачисленияДни'!B31 -> Ak10 | C15: ='06НачисленияДни'!C23 -> 0 | D15: ='06НачисленияДни'!D23 -> 40 | E15: =SUM(C15:D15) -> 40
A16: =A7 -> 46275 | B16: ='06НачисленияДни'!B40 -> Ak10 | C16: ='06НачисленияДни'!C32 -> 100 | D16: ='06НачисленияДни'!D32 -> 0 | E16: =C16+D16 -> 100
A17: =A8 -> 46276 | B17: ='06НачисленияДни'!B49 -> Ak10 | C17: ='06НачисленияДни'!C41 -> 0 | D17: ='06НачисленияДни'!D41 -> 80 | E17: =SUM(C17:D17) -> 80
A18: =A9 -> 46277 | B18: ='06НачисленияДни'!B58 -> Ak10 | C18: ='06НачисленияДни'!C50 -> 0 | D18: ='06НачисленияДни'!D50 -> 80 | E18: =C18+D18 -> 80
A19: =A10 -> 46278 | B19: ='06НачисленияДни'!B76 -> Ak10 | C19: ='06НачисленияДни'!C59 -> 0 | D19: ='06НачисленияДни'!D59 -> 80 | E19: =SUM(C19:D19) -> 80
B20: ИТОГО | C20: =SUM(C13:C19) -> 100 | D20: =SUM(D13:D19) -> 320 | E20: =SUM(E13:E19) -> 420
A22: =A13 -> 46272 | B22: ='06НачисленияДни'!B6 -> G1800 | C22: ='06НачисленияДни'!C6 -> 30 | D22: ='06НачисленияДни'!D6 -> 225 | E22: =C22+D22 -> 255
A23: =A14 -> 46273 | B23: =B22 -> G1800 | C23: ='06НачисленияДни'!C15 -> 0 | D23: ='06НачисленияДни'!D15 -> 825 | E23: =C23+D23 -> 825
A24: =A15 -> 46274 | B24: =B22 -> G1800 | C24: ='06НачисленияДни'!C24 -> 0 | D24: ='06НачисленияДни'!D24 -> 600 | E24: =SUM(C24:D24) -> 600
A25: =A16 -> 46275 | B25: =B24 -> G1800 | C25: ='06НачисленияДни'!C33 -> 1290 | D25: ='06НачисленияДни'!D33 -> 750 | E25: =C25+D25 -> 2040
A26: =A17 -> 46276 | B26: =B24 -> G1800 | C26: ='06НачисленияДни'!C42 -> 0 | D26: ='06НачисленияДни'!D42 -> 900 | E26: =SUM(C26:D26) -> 900
A27: =A18 -> 46277 | B27: =B25 -> G1800 | C27: ='06НачисленияДни'!C51 -> 0 | D27: ='06НачисленияДни'!D51 -> 375 | E27: =C27+D27 -> 375
A28: =A19 -> 46278 | B28: =B22 -> G1800 | C28: ='06НачисленияДни'!C60 -> 0 | D28: ='06НачисленияДни'!D60 -> 150 | E28: =SUM(C28:D28) -> 150
B29: ИТОГО | C29: =SUM(C22:C28) -> 1320 | D29: =SUM(D22:D28) -> 3825 | E29: =SUM(E22:E28) -> 5145
A31: =A22 -> 46272 | B31: ='06НачисленияДни'!B7 -> G3500 | C31: ='06НачисленияДни'!C7 -> 0 | D31: ='06НачисленияДни'!D7 -> 0 | E31: =C31+D31 -> 0
A32: =A23 -> 46273 | B32: =B31 -> G3500 | C32: ='06НачисленияДни'!C16 -> 0 | D32: ='06НачисленияДни'!D16 -> 0 | E32: =C32+D32 -> 0
A33: =A24 -> 46274 | B33: =B31 -> G3500 | C33: ='06НачисленияДни'!C25 -> 0 | D33: ='06НачисленияДни'!D25 -> 0 | E33: =SUM(C33:D33) -> 0
A34: =A25 -> 46275 | B34: =B33 -> G3500 | C34: ='06НачисленияДни'!C34 -> 20 | D34: ='06НачисленияДни'!D34 -> 0 | E34: =C34+D34 -> 20
A35: =A26 -> 46276 | B35: =B33 -> G3500 | C35: ='06НачисленияДни'!C43 -> 0 | D35: ='06НачисленияДни'!D43 -> 110 | E35: =SUM(C35:D35) -> 110
A36: =A27 -> 46277 | B36: =B34 -> G3500 | C36: ='06НачисленияДни'!C52 -> 0 | D36: ='06НачисленияДни'!D52 -> 55 | E36: =C36+D36 -> 55
A37: =A28 -> 46278 | B37: =B31 -> G3500 | C37: ='06НачисленияДни'!C61 -> 20 | D37: ='06НачисленияДни'!D61 -> 110 | E37: =SUM(C37:D37) -> 130
B38: ИТОГО | C38: =SUM(C31:C37) -> 40 | D38: =SUM(D31:D37) -> 275 | E38: =SUM(E31:E37) -> 315
A40: =A31 -> 46272 | B40: G800 | C40: ='06НачисленияДни'!C8 -> 20 | D40: ='06НачисленияДни'!D8 -> 110 | E40: =C40+D40 -> 130
A41: =A32 -> 46273 | B41: =B40 -> G800 | C41: ='06НачисленияДни'!C17 -> 0 | D41: ='06НачисленияДни'!D17 -> 165 | E41: =C41+D41 -> 165
A42: =A33 -> 46274 | B42: =B40 -> G800 | C42: ='06НачисленияДни'!C26 -> 0 | D42: ='06НачисленияДни'!D26 -> 275 | E42: =SUM(C42:D42) -> 275
A43: =A34 -> 46275 | B43: =B42 -> G800 | C43: ='06НачисленияДни'!C35 -> 0 | D43: ='06НачисленияДни'!D35 -> 440 | E43: =C43+D43 -> 440
A44: =A35 -> 46276 | B44: =B42 -> G800 | C44: ='06НачисленияДни'!C44 -> 640 | D44: ='06НачисленияДни'!D44 -> 220 | E44: =SUM(C44:D44) -> 860
...

Sheet Счет
A1: НАЧИСЛЕНИЯ ЗА ФУЛФИЛМЕНТ
A2: В сборку входят: брендирование, упаковка и выдача
A3: Дата | B3: Код | C3: Приемка | D3: Отправка | E3: ИТОГО
A4: ='05Движение'!A4 -> 46272 | B4: ='05Движение'!B4 -> Ak10 | C4: =IF('05Движение'!D4>0,'05Движение'!D4*'02Тариф'!$B$3,0) -> 0 | D4: =IF('05Движение'!E4>0,'05Движение'!E4*('02Тариф'!$B$4+'02Тариф'!$B$5+'02Тариф'!$B$6),0) -> 0 | E4: =C4+D4 -> 0
A5: ='05Движение'!A5 -> 46272 | B5: ='05Движение'!B5 -> Ak15 | C5: =IF('05Движение'!D5>0,'05Движение'!D5*'02Тариф'!$B$3,0) -> 0 | D5: =IF('05Движение'!E5>0,'05Движение'!E5*('02Тариф'!$B$4+'02Тариф'!$B$5+'02Тариф'!$B$6),0) -> 0 | E5: =SUM(C5:D5) -> 0
A6: ='05Движение'!A6 -> 46272 | B6: ='05Движение'!B6 -> G1800 | C6: =IF('05Движение'!D6>0,'05Движение'!D6*'02Тариф'!$D$3,0) -> 30 | D6: =IF('05Движение'!E6>0,'05Движение'!E6*('02Тариф'!$D$4+'02Тариф'!$D$5+'02Тариф'!$D$6),0) -> 225 | E6: =SUM(C6:D6) -> 255
A7: ='05Движение'!A7 -> 46272 | B7: ='05Движение'!B7 -> G3500 | C7: =IF('05Движение'!D7>0,'05Движение'!D7*'02Тариф'!$C$3,0) -> 0 | D7: =IF('05Движение'!E7>0,'05Движение'!E7*('02Тариф'!$C$4+'02Тариф'!$C$5+'02Тариф'!$C$6),0) -> 0 | E7: =SUM(C7:D7) -> 0
A8: ='05Движение'!A8 -> 46272 | B8: ='05Движение'!B8 -> G800 | C8: =IF('05Движение'!D8>0,'05Движение'!D8*'02Тариф'!$C$3,0) -> 20 | D8: =IF('05Движение'!E8>0,'05Движение'!E8*('02Тариф'!$C$4+'02Тариф'!$C$5+'02Тариф'!$C$6),0) -> 110 | E8: =SUM(C8:D8) -> 130
A9: ='05Движение'!A9 -> 46272 | B9: ='05Движение'!B9 -> MiK | C9: =IF('05Движение'!D9>0,'05Движение'!D9*'02Тариф'!$B$3,0) -> 10 | D9: =IF('05Движение'!E9>0,'05Движение'!E9*('02Тариф'!$B$5+'02Тариф'!$B$6),0) -> 30 | E9: =SUM(C9:D9) -> 40
A10: ='05Движение'!A10 -> 46272 | B10: ='05Движение'!B10 -> MiP | C10: =IF('05Движение'!D10>0,'05Движение'!D10*'02Тариф'!$B$3,0) -> 0 | D10: =IF('05Движение'!E10>0,'05Движение'!E10*('02Тариф'!$B$5+'02Тариф'!$B$6),0) -> 0 | E10: =SUM(C10:D10) -> 0
A11: ='05Движение'!A11 -> ПН | B11: ='05Движение'!B11 -> Пузанов Д.В. | C11: =SUM(C4:C10) -> 60 | D11: =SUM(D4:D10) -> 365 | E11: =SUM(E4:E10) -> 425
A13: ='05Движение'!A13 -> 46273 | B13: ='05Движение'!B13 -> Ak10 | C13: =IF('05Движение'!D13>0,'05Движение'!D13*'02Тариф'!$B$3,0) -> 0 | D13: =IF('05Движение'!E13>0,'05Движение'!E13*('02Тариф'!$B$4+'02Тариф'!$B$5+'02Тариф'!$B$6),0) -> 40 | E13: =C13+D13 -> 40
A14: ='05Движение'!A14 -> 46273 | B14: ='05Движение'!B14 -> Ak15 | C14: =IF('05Движение'!D14>0,'05Движение'!D14*'02Тариф'!$B$3,0) -> 0 | D14: =IF('05Движение'!E14>0,'05Движение'!E14*('02Тариф'!$B$4+'02Тариф'!$B$5+'02Тариф'!$B$6),0) -> 40 | E14: =SUM(C14:D14) -> 40
A15: ='05Движение'!A15 -> 46273 | B15: ='05Движение'!B15 -> G1800 | C15: =IF('05Движение'!D15>0,'05Движение'!D15*'02Тариф'!$D$3,0) -> 0 | D15: =IF('05Движение'!E15>0,'05Движение'!E15*('02Тариф'!$D$4+'02Тариф'!$D$5+'02Тариф'!$D$6),0) -> 825 | E15: =SUM(C15:D15) -> 825
A16: ='05Движение'!A16 -> 46273 | B16: ='05Движение'!B16 -> G3500 | C16: =IF('05Движение'!D16>0,'05Движение'!D16*'02Тариф'!$C$3,0) -> 0 | D16: =IF('05Движение'!E16>0,'05Движение'!E16*('02Тариф'!$C$4+'02Тариф'!$C$5+'02Тариф'!$C$6),0) -> 0 | E16: =SUM(C16:D16) -> 0
A17: ='05Движение'!A17 -> 46273 | B17: ='05Движение'!B17 -> G800 | C17: =IF('05Движение'!D17>0,'05Движение'!D17*'02Тариф'!$C$3,0) -> 0 | D17: =IF('05Движение'!E17>0,'05Движение'!E17*('02Тариф'!$C$4+'02Тариф'!$C$5+'02Тариф'!$C$6),0) -> 165 | E17: =SUM(C17:D17) -> 165
A18: ='05Движение'!A18 -> 46273 | B18: ='05Движение'!B18 -> MiK | C18: =IF('05Движение'!D18>0,'05Движение'!D18*'02Тариф'!$B$3,0) -> 0 | D18: =IF('05Движение'!E18>0,'05Движение'!E18*('02Тариф'!$B$5+'02Тариф'!$B$6),0) -> 0 | E18: =SUM(C18:D18) -> 0
A19: ='05Движение'!A19 -> 46273 | B19: ='05Движение'!B19 -> MiP | C19: =IF('05Движение'!D19>0,'05Движение'!D19*'02Тариф'!$B$3,0) -> 0 | D19: =IF('05Движение'!E19>0,'05Движение'!E19*('02Тариф'!$B$5+'02Тариф'!$B$6),0) -> 0 | E19: =SUM(C19:D19) -> 0
A20: ='05Движение'!A20 -> ВТ | B20: Завалишин Д.Л. | C20: =SUM(C13:C19) -> 0 | D20: =SUM(D13:D19) -> 1070 | E20: =SUM(E13:E19) -> 1070
A22: ='05Движение'!A22 -> 46274 | B22: ='05Движение'!B22 -> Ak10 | C22: =IF('05Движение'!D22>0,'05Движение'!D22*'02Тариф'!$B$3,0) -> 0 | D22: =IF('05Движение'!E22>0,'05Движение'!E22*('02Тариф'!$B$4+'02Тариф'!$B$5+'02Тариф'!$B$6),0) -> 0 | E22: =C22+D22 -> 0
A23: ='05Движение'!A23 -> 46274 | B23: ='05Движение'!B23 -> Ak15 | C23: =IF('05Движение'!D23>0,'05Движение'!D23*'02Тариф'!$B$3,0) -> 0 | D23: =IF('05Движение'!E23>0,'05Движение'!E23*('02Тариф'!$B$4+'02Тариф'!$B$5+'02Тариф'!$B$6),0) -> 40 | E23: =SUM(C23:D23) -> 40
A24: ='05Движение'!A24 -> 46274 | B24: ='05Движение'!B24 -> G1800 | C24: =IF('05Движение'!D24>0,'05Движение'!D24*'02Тариф'!$D$3,0) -> 0 | D24: =IF('05Движение'!E24>0,'05Движение'!E24*('02Тариф'!$D$4+'02Тариф'!$D$5+'02Тариф'!$D$6),0) -> 600 | E24: =SUM(C24:D24) -> 600
A25: ='05Движение'!A25 -> 46274 | B25: ='05Движение'!B25 -> G3500 | C25: =IF('05Движение'!D25>0,'05Движение'!D25*'02Тариф'!$C$3,0) -> 0 | D25: =IF('05Движение'!E25>0,'05Движение'!E25*('02Тариф'!$C$4+'02Тариф'!$C$5+'02Тариф'!$C$6),0) -> 0 | E25: =SUM(C25:D25) -> 0
A26: ='05Движение'!A26 -> 46274 | B26: ='05Движение'!B26 -> G800 | C26: =IF('05Движение'!D26>0,'05Движение'!D26*'02Тариф'!$C$3,0) -> 0 | D26: =IF('05Движение'!E26>0,'05Движение'!E26*('02Тариф'!$C$4+'02Тариф'!$C$5+'02Тариф'!$C$6),0) -> 275 | E26: =SUM(C26:D26) -> 275
A27: ='05Движение'!A27 -> 46274 | B27: ='05Движение'!B27 -> MiK | C27: =IF('05Движение'!D27>0,'05Движение'!D27*'02Тариф'!$B$3,0) -> 0 | D27: =IF('05Движение'!E27>0,'05Движение'!E27*('02Тариф'!$B$5+'02Тариф'!$B$6),0) -> 30 | E27: =SUM(C27:D27) -> 30
A28: ='05Движение'!A28 -> 46274 | B28: ='05Движение'!B28 -> MiP | C28: =IF('05Движение'!D28>0,'05Движение'!D28*'02Тариф'!$B$3,0) -> 0 | D28: =IF('05Движение'!E28>0,'05Движение'!E28*('02Тариф'!$B$5+'02Тариф'!$B$6),0) -> 0 | E28: =SUM(C28:D28) -> 0
A29: ='05Движение'!A29 -> СР | B29: Завалишин Д.Л. | C29: =SUM(C22:C28) -> 0 | D29: =SUM(D22:D28) -> 945 | E29: =SUM(E22:E28) -> 945
A31: ='05Движение'!A31 -> 46275 | B31: ='05Движение'!B31 -> Ak10 | C31: =IF('05Движение'!D31>0,'05Движение'!D31*'02Тариф'!$B$3,0) -> 0 | D31: =IF('05Движение'!E31>0,'05Движение'!E31*('02Тариф'!$B$4+'02Тариф'!$B$5+'02Тариф'!$B$6),0) -> 0 | E31: =C31+D31 -> 0
A32: ='05Движение'!A32 -> 46275 | B32: ='05Движение'!B32 -> Ak15 | C32: =IF('05Движение'!D32>0,'05Движение'!D32*'02Тариф'!$B$3,0) -> 100 | D32: =IF('05Движение'!E32>0,'05Движение'!E32*('02Тариф'!$B$4+'02Тариф'!$B$5+'02Тариф'!$B$6),0) -> 0 | E32: =SUM(C32:D32) -> 100
A33: ='05Движение'!A33 -> 46275 | B33: ='05Движение'!B33 -> G1800 | C33: =IF('05Движение'!D33>0,'05Движение'!D33*'02Тариф'!$D$3,0) -> 1290 | D33: =IF('05Движение'!E33>0,'05Движение'!E33*('02Тариф'!$D$4+'02Тариф'!$D$5+'02Тариф'!$D$6),0) -> 750 | E33: =SUM(C33:D33) -> 2040
A34: ='05Движение'!A34 -> 46275 | B34: ='05Движение'!B34 -> G3500 | C34: =IF('05Движение'!D34>0,'05Движение'!D34*'02Тариф'!$C$3,0) -> 20 | D34: =IF('05Движение'!E34>0,'05Движение'!E34*('02Тариф'!$C$4+'02Тариф'!$C$5+'02Тариф'!$C$6),0) -> 0 | E34: =SUM(C34:D34) -> 20
A35: ='05Движение'!A35 -> 46275 | B35: ='05Движение'!B35 -> G800 | C35: =IF('05Движение'!D35>0,'05Движение'!D35*'02Тариф'!$C$3,0) -> 0 | D35: =IF('05Движение'!E35>0,'05Движение'!E35*('02Тариф'!$C$4+'02Тариф'!$C$5+'02Тариф'!$C$6),0) -> 440 | E35: =SUM(C35:D35) -> 440
A36: ='05Движение'!A36 -> 46275 | B36: ='05Движение'!B36 -> MiK | C36: =IF('05Движение'!D36>0,'05Движение'!D36*'02Тариф'!$B$3,0) -> 100 | D36: =IF('05Движение'!E36>0,'05Движение'!E36*('02Тариф'!$B$5+'02Тариф'!$B$6),0) -> 30 | E36: =SUM(C36:D36) -> 130
A37: ='05Движение'!A37 -> 46275 | B37: ='05Движение'!B37 -> MiP | C37: =IF('05Движение'!D37>0,'05Движение'!D37*'02Тариф'!$B$3,0) -> 270 | D37: =IF('05Движение'!E37>0,'05Движение'!E37*('02Тариф'!$B$5+'02Тариф'!$B$6),0) -> 30 | E37: =SUM(C37:D37) -> 300
A38: ='05Движение'!A38 -> ЧТ | B38: Завалишин Д.Л. | C38: =SUM(C31:C37) -> 1780 | D38: =SUM(D31:D37) -> 1250 | E38: =SUM(E31:E37) -> 3030
A40: ='05Движение'!A40 -> 46276 | B40: ='05Движение'!B40 -> Ak10 | C40: =IF('05Движение'!D40>0,'05Движение'!D40*'02Тариф'!$B$3,0) -> 0 | D40: =IF('05Движение'!E40>0,'05Движение'!E40*('02Тариф'!$B$4+'02Тариф'!$B$5+'02Тариф'!$B$6),0) -> 200 | E40: =C40+D40 -> 200
A41: ='05Движение'!A41 -> 46276 | B41: ='05Движение'!B41 -> Ak15 | C41: =IF('05Движение'!D41>0,'05Движение'!D41*'02Тариф'!$B$3,0) -> 0 | D41: =IF('05Движение'!E41>0,'05Движение'!E41*('02Тариф'!$B$4+'02Тариф'!$B$5+'02Тариф'!$B$6),0) -> 80 | E41: =SUM(C41:D41) -> 80
A42: ='05Движение'!A42 -> 46276 | B42: ='05Движение'!B42 -> G1800 | C42: =IF('05Движение'!D42>0,'05Движение'!D42*'02Тариф'!$D$3,0) -> 0 | D42: =IF('05Движение'!E42>0,'05Движение'!E42*('02Тариф'!$D$4+'02Тариф'!$D$5+'02Тариф'!$D$6),0) -> 900 | E42: =SUM(C42:D42) -> 900
A43: ='05Движение'!A43 -> 46276 | B43: ='05Движение'!B43 -> G3500 | C43: =IF('05Движение'!D43>0,'05Движение'!D43*'02Тариф'!$C$3,0) -> 0 | D43: =IF('05Движение'!E43>0,'05Движение'!E43*('02Тариф'!$C$4+'02Тариф'!$C$5+'02Тариф'!$C$6),0) -> 110 | E43: =SUM(C43:D43) -> 110
A44: ='05Движение'!A44 -> 46276 | B44: ='05Движение'!B44 -> G800 | C44: =IF('05Движение'!D44>0,'05Движение'!D44*'02Тариф'!$C$3,0) -> 640 | D44: =IF('05Движение'!E44>0,'05Движение'!E44*('02Тариф'!$C$4+'02Тариф'!$C$5+'02Тариф'!$C$6),0) -> 220 | E44: =SUM(C44:D44) -> 860
...
